[2025-03-24T22:19:07.125+0000] {local_task_job_runner.py:123} INFO - ::group::Pre task execution logs
[2025-03-24T22:19:07.162+0000] {taskinstance.py:2614} INFO - Dependencies all met for dep_context=non-requeueable deps ti=<TaskInstance: containers1_dag.php_app1 scheduled__2024-03-02T00:00:00+00:00 [queued]>
[2025-03-24T22:19:07.180+0000] {taskinstance.py:2614} INFO - Dependencies all met for dep_context=requeueable deps ti=<TaskInstance: containers1_dag.php_app1 scheduled__2024-03-02T00:00:00+00:00 [queued]>
[2025-03-24T22:19:07.180+0000] {taskinstance.py:2867} INFO - Starting attempt 1 of 6
[2025-03-24T22:19:07.240+0000] {taskinstance.py:2890} INFO - Executing <Task(BashOperator): php_app1> on 2024-03-02 00:00:00+00:00
[2025-03-24T22:19:07.260+0000] {logging_mixin.py:190} WARNING - /home/***/.local/lib/python3.12/site-packages/***/task/task_runner/standard_task_runner.py:70 DeprecationWarning: This process (pid=4822) is multi-threaded, use of fork() may lead to deadlocks in the child.
[2025-03-24T22:19:07.264+0000] {standard_task_runner.py:72} INFO - Started process 4827 to run task
[2025-03-24T22:19:07.263+0000] {standard_task_runner.py:104} INFO - Running: ['***', 'tasks', 'run', 'containers1_dag', 'php_app1', 'scheduled__2024-03-02T00:00:00+00:00', '--job-id', '112', '--raw', '--subdir', 'DAGS_FOLDER/containers1_dag.py', '--cfg-path', '/tmp/tmp9xtrv5wo']
[2025-03-24T22:19:07.269+0000] {standard_task_runner.py:105} INFO - Job 112: Subtask php_app1
[2025-03-24T22:19:07.409+0000] {task_command.py:467} INFO - Running <TaskInstance: containers1_dag.php_app1 scheduled__2024-03-02T00:00:00+00:00 [running]> on host b9050090f7f5
[2025-03-24T22:19:07.842+0000] {taskinstance.py:3134} INFO - Exporting env vars: AIRFLOW_CTX_DAG_OWNER='andreeppinghaus' AIRFLOW_CTX_DAG_ID='containers1_dag' AIRFLOW_CTX_TASK_ID='php_app1' AIRFLOW_CTX_EXECUTION_DATE='2024-03-02T00:00:00+00:00' AIRFLOW_CTX_TRY_NUMBER='1' AIRFLOW_CTX_DAG_RUN_ID='scheduled__2024-03-02T00:00:00+00:00'
[2025-03-24T22:19:07.843+0000] {taskinstance.py:732} INFO - ::endgroup::
[2025-03-24T22:19:07.903+0000] {subprocess.py:78} INFO - Tmp dir root location: /tmp
[2025-03-24T22:19:07.904+0000] {subprocess.py:88} INFO - Running command: ['/usr/bin/bash', '-c', 'sudo docker run -v $(pwd)/../in:/usr/src/app/in -v $(pwd):/usr/src/app php-app1']
[2025-03-24T22:19:07.974+0000] {subprocess.py:99} INFO - Output:
[2025-03-24T22:19:08.007+0000] {subprocess.py:106} INFO - sudo: a terminal is required to read the password; either use the -S option to read from standard input or configure an askpass helper
[2025-03-24T22:19:08.009+0000] {subprocess.py:106} INFO - sudo: a password is required
[2025-03-24T22:19:08.011+0000] {subprocess.py:110} INFO - Command exited with return code 1
[2025-03-24T22:19:08.035+0000] {taskinstance.py:3313} ERROR - Task failed with exception
Traceback (most recent call last):
  File "/home/airflow/.local/lib/python3.12/site-packages/airflow/models/taskinstance.py", line 768, in _execute_task
    result = _execute_callable(context=context, **execute_callable_kwargs)
             ^^^^^^^^^^^^^^^^^^^^^^^^^^^^^^^^^^^^^^^^^^^^^^^^^^^^^^^^^^^^^
  File "/home/airflow/.local/lib/python3.12/site-packages/airflow/models/taskinstance.py", line 734, in _execute_callable
    return ExecutionCallableRunner(
           ^^^^^^^^^^^^^^^^^^^^^^^^
  File "/home/airflow/.local/lib/python3.12/site-packages/airflow/utils/operator_helpers.py", line 252, in run
    return self.func(*args, **kwargs)
           ^^^^^^^^^^^^^^^^^^^^^^^^^^
  File "/home/airflow/.local/lib/python3.12/site-packages/airflow/models/baseoperator.py", line 424, in wrapper
    return func(self, *args, **kwargs)
           ^^^^^^^^^^^^^^^^^^^^^^^^^^^
  File "/home/airflow/.local/lib/python3.12/site-packages/airflow/operators/bash.py", line 276, in execute
    raise AirflowException(
airflow.exceptions.AirflowException: Bash command failed. The command returned a non-zero exit code 1.
[2025-03-24T22:19:08.051+0000] {taskinstance.py:1226} INFO - Marking task as UP_FOR_RETRY. dag_id=containers1_dag, task_id=php_app1, run_id=scheduled__2024-03-02T00:00:00+00:00, execution_date=20240302T000000, start_date=20250324T221907, end_date=20250324T221908
[2025-03-24T22:19:08.477+0000] {taskinstance.py:341} INFO - ::group::Post task execution logs
[2025-03-24T22:19:08.478+0000] {standard_task_runner.py:124} ERROR - Failed to execute job 112 for task php_app1 (Bash command failed. The command returned a non-zero exit code 1.; 4827)
Traceback (most recent call last):
  File "/home/airflow/.local/lib/python3.12/site-packages/airflow/task/task_runner/standard_task_runner.py", line 117, in _start_by_fork
    ret = args.func(args, dag=self.dag)
          ^^^^^^^^^^^^^^^^^^^^^^^^^^^^^
  File "/home/airflow/.local/lib/python3.12/site-packages/airflow/cli/cli_config.py", line 49, in command
    return func(*args, **kwargs)
           ^^^^^^^^^^^^^^^^^^^^^
  File "/home/airflow/.local/lib/python3.12/site-packages/airflow/utils/cli.py", line 116, in wrapper
    return f(*args, **kwargs)
           ^^^^^^^^^^^^^^^^^^
  File "/home/airflow/.local/lib/python3.12/site-packages/airflow/cli/commands/task_command.py", line 483, in task_run
    task_return_code = _run_task_by_selected_method(args, _dag, ti)
                       ^^^^^^^^^^^^^^^^^^^^^^^^^^^^^^^^^^^^^^^^^^^^
  File "/home/airflow/.local/lib/python3.12/site-packages/airflow/cli/commands/task_command.py", line 256, in _run_task_by_selected_method
    return _run_raw_task(args, ti)
           ^^^^^^^^^^^^^^^^^^^^^^^
  File "/home/airflow/.local/lib/python3.12/site-packages/airflow/cli/commands/task_command.py", line 341, in _run_raw_task
    return ti._run_raw_task(
           ^^^^^^^^^^^^^^^^^
  File "/home/airflow/.local/lib/python3.12/site-packages/airflow/utils/session.py", line 97, in wrapper
    return func(*args, session=session, **kwargs)
           ^^^^^^^^^^^^^^^^^^^^^^^^^^^^^^^^^^^^^^
  File "/home/airflow/.local/lib/python3.12/site-packages/airflow/models/taskinstance.py", line 3006, in _run_raw_task
    return _run_raw_task(
           ^^^^^^^^^^^^^^
  File "/home/airflow/.local/lib/python3.12/site-packages/airflow/models/taskinstance.py", line 274, in _run_raw_task
    TaskInstance._execute_task_with_callbacks(
  File "/home/airflow/.local/lib/python3.12/site-packages/airflow/models/taskinstance.py", line 3161, in _execute_task_with_callbacks
    result = self._execute_task(context, task_orig)
             ^^^^^^^^^^^^^^^^^^^^^^^^^^^^^^^^^^^^^^
  File "/home/airflow/.local/lib/python3.12/site-packages/airflow/models/taskinstance.py", line 3185, in _execute_task
    return _execute_task(self, context, task_orig)
           ^^^^^^^^^^^^^^^^^^^^^^^^^^^^^^^^^^^^^^^
  File "/home/airflow/.local/lib/python3.12/site-packages/airflow/models/taskinstance.py", line 768, in _execute_task
    result = _execute_callable(context=context, **execute_callable_kwargs)
             ^^^^^^^^^^^^^^^^^^^^^^^^^^^^^^^^^^^^^^^^^^^^^^^^^^^^^^^^^^^^^
  File "/home/airflow/.local/lib/python3.12/site-packages/airflow/models/taskinstance.py", line 734, in _execute_callable
    return ExecutionCallableRunner(
           ^^^^^^^^^^^^^^^^^^^^^^^^
  File "/home/airflow/.local/lib/python3.12/site-packages/airflow/utils/operator_helpers.py", line 252, in run
    return self.func(*args, **kwargs)
           ^^^^^^^^^^^^^^^^^^^^^^^^^^
  File "/home/airflow/.local/lib/python3.12/site-packages/airflow/models/baseoperator.py", line 424, in wrapper
    return func(self, *args, **kwargs)
           ^^^^^^^^^^^^^^^^^^^^^^^^^^^
  File "/home/airflow/.local/lib/python3.12/site-packages/airflow/operators/bash.py", line 276, in execute
    raise AirflowException(
airflow.exceptions.AirflowException: Bash command failed. The command returned a non-zero exit code 1.
[2025-03-24T22:19:08.537+0000] {local_task_job_runner.py:266} INFO - Task exited with return code 1
[2025-03-24T22:19:08.625+0000] {taskinstance.py:3901} INFO - 0 downstream tasks scheduled from follow-on schedule check
[2025-03-24T22:19:08.639+0000] {local_task_job_runner.py:245} INFO - ::endgroup::
[2025-03-24T22:24:15.839+0000] {local_task_job_runner.py:123} INFO - ::group::Pre task execution logs
[2025-03-24T22:24:15.944+0000] {taskinstance.py:2614} INFO - Dependencies all met for dep_context=non-requeueable deps ti=<TaskInstance: containers1_dag.php_app1 scheduled__2024-03-02T00:00:00+00:00 [queued]>
[2025-03-24T22:24:16.015+0000] {taskinstance.py:2614} INFO - Dependencies all met for dep_context=requeueable deps ti=<TaskInstance: containers1_dag.php_app1 scheduled__2024-03-02T00:00:00+00:00 [queued]>
[2025-03-24T22:24:16.023+0000] {taskinstance.py:2867} INFO - Starting attempt 1 of 6
[2025-03-24T22:24:16.115+0000] {taskinstance.py:2890} INFO - Executing <Task(BashOperator): php_app1> on 2024-03-02 00:00:00+00:00
[2025-03-24T22:24:16.186+0000] {logging_mixin.py:190} WARNING - /home/***/.local/lib/python3.12/site-packages/***/task/task_runner/standard_task_runner.py:70 DeprecationWarning: This process (pid=5213) is multi-threaded, use of fork() may lead to deadlocks in the child.
[2025-03-24T22:24:16.215+0000] {standard_task_runner.py:72} INFO - Started process 5225 to run task
[2025-03-24T22:24:16.199+0000] {standard_task_runner.py:104} INFO - Running: ['***', 'tasks', 'run', 'containers1_dag', 'php_app1', 'scheduled__2024-03-02T00:00:00+00:00', '--job-id', '146', '--raw', '--subdir', 'DAGS_FOLDER/containers1_dag.py', '--cfg-path', '/tmp/tmp8w7jh296']
[2025-03-24T22:24:16.218+0000] {standard_task_runner.py:105} INFO - Job 146: Subtask php_app1
[2025-03-24T22:24:16.590+0000] {task_command.py:467} INFO - Running <TaskInstance: containers1_dag.php_app1 scheduled__2024-03-02T00:00:00+00:00 [running]> on host b9050090f7f5
[2025-03-24T22:24:17.146+0000] {taskinstance.py:3134} INFO - Exporting env vars: AIRFLOW_CTX_DAG_OWNER='andre' AIRFLOW_CTX_DAG_ID='containers1_dag' AIRFLOW_CTX_TASK_ID='php_app1' AIRFLOW_CTX_EXECUTION_DATE='2024-03-02T00:00:00+00:00' AIRFLOW_CTX_TRY_NUMBER='1' AIRFLOW_CTX_DAG_RUN_ID='scheduled__2024-03-02T00:00:00+00:00'
[2025-03-24T22:24:17.147+0000] {taskinstance.py:732} INFO - ::endgroup::
[2025-03-24T22:24:17.200+0000] {subprocess.py:78} INFO - Tmp dir root location: /tmp
[2025-03-24T22:24:17.201+0000] {subprocess.py:88} INFO - Running command: ['/usr/bin/bash', '-c', 'sudo docker run -v $(pwd)/../in:/usr/src/app/in -v $(pwd):/usr/src/app php-app1']
[2025-03-24T22:24:17.221+0000] {subprocess.py:99} INFO - Output:
[2025-03-24T22:24:17.269+0000] {subprocess.py:106} INFO - sudo: a terminal is required to read the password; either use the -S option to read from standard input or configure an askpass helper
[2025-03-24T22:24:17.271+0000] {subprocess.py:106} INFO - sudo: a password is required
[2025-03-24T22:24:17.275+0000] {subprocess.py:110} INFO - Command exited with return code 1
[2025-03-24T22:24:17.324+0000] {taskinstance.py:3313} ERROR - Task failed with exception
Traceback (most recent call last):
  File "/home/airflow/.local/lib/python3.12/site-packages/airflow/models/taskinstance.py", line 768, in _execute_task
    result = _execute_callable(context=context, **execute_callable_kwargs)
             ^^^^^^^^^^^^^^^^^^^^^^^^^^^^^^^^^^^^^^^^^^^^^^^^^^^^^^^^^^^^^
  File "/home/airflow/.local/lib/python3.12/site-packages/airflow/models/taskinstance.py", line 734, in _execute_callable
    return ExecutionCallableRunner(
           ^^^^^^^^^^^^^^^^^^^^^^^^
  File "/home/airflow/.local/lib/python3.12/site-packages/airflow/utils/operator_helpers.py", line 252, in run
    return self.func(*args, **kwargs)
           ^^^^^^^^^^^^^^^^^^^^^^^^^^
  File "/home/airflow/.local/lib/python3.12/site-packages/airflow/models/baseoperator.py", line 424, in wrapper
    return func(self, *args, **kwargs)
           ^^^^^^^^^^^^^^^^^^^^^^^^^^^
  File "/home/airflow/.local/lib/python3.12/site-packages/airflow/operators/bash.py", line 276, in execute
    raise AirflowException(
airflow.exceptions.AirflowException: Bash command failed. The command returned a non-zero exit code 1.
[2025-03-24T22:24:17.430+0000] {taskinstance.py:1226} INFO - Marking task as UP_FOR_RETRY. dag_id=containers1_dag, task_id=php_app1, run_id=scheduled__2024-03-02T00:00:00+00:00, execution_date=20240302T000000, start_date=20250324T222415, end_date=20250324T222417
[2025-03-24T22:24:17.721+0000] {taskinstance.py:341} INFO - ::group::Post task execution logs
[2025-03-24T22:24:17.725+0000] {standard_task_runner.py:124} ERROR - Failed to execute job 146 for task php_app1 (Bash command failed. The command returned a non-zero exit code 1.; 5225)
Traceback (most recent call last):
  File "/home/airflow/.local/lib/python3.12/site-packages/airflow/task/task_runner/standard_task_runner.py", line 117, in _start_by_fork
    ret = args.func(args, dag=self.dag)
          ^^^^^^^^^^^^^^^^^^^^^^^^^^^^^
  File "/home/airflow/.local/lib/python3.12/site-packages/airflow/cli/cli_config.py", line 49, in command
    return func(*args, **kwargs)
           ^^^^^^^^^^^^^^^^^^^^^
  File "/home/airflow/.local/lib/python3.12/site-packages/airflow/utils/cli.py", line 116, in wrapper
    return f(*args, **kwargs)
           ^^^^^^^^^^^^^^^^^^
  File "/home/airflow/.local/lib/python3.12/site-packages/airflow/cli/commands/task_command.py", line 483, in task_run
    task_return_code = _run_task_by_selected_method(args, _dag, ti)
                       ^^^^^^^^^^^^^^^^^^^^^^^^^^^^^^^^^^^^^^^^^^^^
  File "/home/airflow/.local/lib/python3.12/site-packages/airflow/cli/commands/task_command.py", line 256, in _run_task_by_selected_method
    return _run_raw_task(args, ti)
           ^^^^^^^^^^^^^^^^^^^^^^^
  File "/home/airflow/.local/lib/python3.12/site-packages/airflow/cli/commands/task_command.py", line 341, in _run_raw_task
    return ti._run_raw_task(
           ^^^^^^^^^^^^^^^^^
  File "/home/airflow/.local/lib/python3.12/site-packages/airflow/utils/session.py", line 97, in wrapper
    return func(*args, session=session, **kwargs)
           ^^^^^^^^^^^^^^^^^^^^^^^^^^^^^^^^^^^^^^
  File "/home/airflow/.local/lib/python3.12/site-packages/airflow/models/taskinstance.py", line 3006, in _run_raw_task
    return _run_raw_task(
           ^^^^^^^^^^^^^^
  File "/home/airflow/.local/lib/python3.12/site-packages/airflow/models/taskinstance.py", line 274, in _run_raw_task
    TaskInstance._execute_task_with_callbacks(
  File "/home/airflow/.local/lib/python3.12/site-packages/airflow/models/taskinstance.py", line 3161, in _execute_task_with_callbacks
    result = self._execute_task(context, task_orig)
             ^^^^^^^^^^^^^^^^^^^^^^^^^^^^^^^^^^^^^^
  File "/home/airflow/.local/lib/python3.12/site-packages/airflow/models/taskinstance.py", line 3185, in _execute_task
    return _execute_task(self, context, task_orig)
           ^^^^^^^^^^^^^^^^^^^^^^^^^^^^^^^^^^^^^^^
  File "/home/airflow/.local/lib/python3.12/site-packages/airflow/models/taskinstance.py", line 768, in _execute_task
    result = _execute_callable(context=context, **execute_callable_kwargs)
             ^^^^^^^^^^^^^^^^^^^^^^^^^^^^^^^^^^^^^^^^^^^^^^^^^^^^^^^^^^^^^
  File "/home/airflow/.local/lib/python3.12/site-packages/airflow/models/taskinstance.py", line 734, in _execute_callable
    return ExecutionCallableRunner(
           ^^^^^^^^^^^^^^^^^^^^^^^^
  File "/home/airflow/.local/lib/python3.12/site-packages/airflow/utils/operator_helpers.py", line 252, in run
    return self.func(*args, **kwargs)
           ^^^^^^^^^^^^^^^^^^^^^^^^^^
  File "/home/airflow/.local/lib/python3.12/site-packages/airflow/models/baseoperator.py", line 424, in wrapper
    return func(self, *args, **kwargs)
           ^^^^^^^^^^^^^^^^^^^^^^^^^^^
  File "/home/airflow/.local/lib/python3.12/site-packages/airflow/operators/bash.py", line 276, in execute
    raise AirflowException(
airflow.exceptions.AirflowException: Bash command failed. The command returned a non-zero exit code 1.
[2025-03-24T22:24:17.778+0000] {local_task_job_runner.py:266} INFO - Task exited with return code 1
[2025-03-24T22:24:17.952+0000] {taskinstance.py:3901} INFO - 0 downstream tasks scheduled from follow-on schedule check
[2025-03-24T22:24:17.966+0000] {local_task_job_runner.py:245} INFO - ::endgroup::
[2025-03-24T22:27:19.715+0000] {local_task_job_runner.py:123} INFO - ::group::Pre task execution logs
[2025-03-24T22:27:19.856+0000] {taskinstance.py:2614} INFO - Dependencies all met for dep_context=non-requeueable deps ti=<TaskInstance: containers1_dag.php_app1 scheduled__2024-03-02T00:00:00+00:00 [queued]>
[2025-03-24T22:27:19.907+0000] {taskinstance.py:2614} INFO - Dependencies all met for dep_context=requeueable deps ti=<TaskInstance: containers1_dag.php_app1 scheduled__2024-03-02T00:00:00+00:00 [queued]>
[2025-03-24T22:27:19.907+0000] {taskinstance.py:2867} INFO - Starting attempt 1 of 6
[2025-03-24T22:27:20.039+0000] {taskinstance.py:2890} INFO - Executing <Task(BashOperator): php_app1> on 2024-03-02 00:00:00+00:00
[2025-03-24T22:27:20.055+0000] {logging_mixin.py:190} WARNING - /home/***/.local/lib/python3.12/site-packages/***/task/task_runner/standard_task_runner.py:70 DeprecationWarning: This process (pid=5520) is multi-threaded, use of fork() may lead to deadlocks in the child.
[2025-03-24T22:27:20.057+0000] {standard_task_runner.py:72} INFO - Started process 5538 to run task
[2025-03-24T22:27:20.070+0000] {standard_task_runner.py:104} INFO - Running: ['***', 'tasks', 'run', 'containers1_dag', 'php_app1', 'scheduled__2024-03-02T00:00:00+00:00', '--job-id', '178', '--raw', '--subdir', 'DAGS_FOLDER/containers1_dag.py', '--cfg-path', '/tmp/tmpy2tvgf2s']
[2025-03-24T22:27:20.077+0000] {standard_task_runner.py:105} INFO - Job 178: Subtask php_app1
[2025-03-24T22:27:20.964+0000] {task_command.py:467} INFO - Running <TaskInstance: containers1_dag.php_app1 scheduled__2024-03-02T00:00:00+00:00 [running]> on host b9050090f7f5
[2025-03-24T22:27:22.852+0000] {taskinstance.py:3134} INFO - Exporting env vars: AIRFLOW_CTX_DAG_OWNER='andre' AIRFLOW_CTX_DAG_ID='containers1_dag' AIRFLOW_CTX_TASK_ID='php_app1' AIRFLOW_CTX_EXECUTION_DATE='2024-03-02T00:00:00+00:00' AIRFLOW_CTX_TRY_NUMBER='1' AIRFLOW_CTX_DAG_RUN_ID='scheduled__2024-03-02T00:00:00+00:00'
[2025-03-24T22:27:22.854+0000] {taskinstance.py:732} INFO - ::endgroup::
[2025-03-24T22:27:23.308+0000] {subprocess.py:78} INFO - Tmp dir root location: /tmp
[2025-03-24T22:27:23.309+0000] {subprocess.py:88} INFO - Running command: ['/usr/bin/bash', '-c', 'docker run -v $(pwd)/../in:/usr/src/app/in -v $(pwd):/usr/src/app php-app1']
[2025-03-24T22:27:23.338+0000] {subprocess.py:99} INFO - Output:
[2025-03-24T22:27:23.453+0000] {subprocess.py:106} INFO - docker: Cannot connect to the Docker daemon at unix:///var/run/docker.sock. Is the docker daemon running?.
[2025-03-24T22:27:23.454+0000] {subprocess.py:106} INFO - See 'docker run --help'.
[2025-03-24T22:27:23.488+0000] {subprocess.py:110} INFO - Command exited with return code 125
[2025-03-24T22:27:23.868+0000] {taskinstance.py:3313} ERROR - Task failed with exception
Traceback (most recent call last):
  File "/home/airflow/.local/lib/python3.12/site-packages/airflow/models/taskinstance.py", line 768, in _execute_task
    result = _execute_callable(context=context, **execute_callable_kwargs)
             ^^^^^^^^^^^^^^^^^^^^^^^^^^^^^^^^^^^^^^^^^^^^^^^^^^^^^^^^^^^^^
  File "/home/airflow/.local/lib/python3.12/site-packages/airflow/models/taskinstance.py", line 734, in _execute_callable
    return ExecutionCallableRunner(
           ^^^^^^^^^^^^^^^^^^^^^^^^
  File "/home/airflow/.local/lib/python3.12/site-packages/airflow/utils/operator_helpers.py", line 252, in run
    return self.func(*args, **kwargs)
           ^^^^^^^^^^^^^^^^^^^^^^^^^^
  File "/home/airflow/.local/lib/python3.12/site-packages/airflow/models/baseoperator.py", line 424, in wrapper
    return func(self, *args, **kwargs)
           ^^^^^^^^^^^^^^^^^^^^^^^^^^^
  File "/home/airflow/.local/lib/python3.12/site-packages/airflow/operators/bash.py", line 276, in execute
    raise AirflowException(
airflow.exceptions.AirflowException: Bash command failed. The command returned a non-zero exit code 125.
[2025-03-24T22:27:23.968+0000] {taskinstance.py:1226} INFO - Marking task as UP_FOR_RETRY. dag_id=containers1_dag, task_id=php_app1, run_id=scheduled__2024-03-02T00:00:00+00:00, execution_date=20240302T000000, start_date=20250324T222719, end_date=20250324T222723
[2025-03-24T22:27:24.583+0000] {taskinstance.py:341} INFO - ::group::Post task execution logs
[2025-03-24T22:27:24.588+0000] {standard_task_runner.py:124} ERROR - Failed to execute job 178 for task php_app1 (Bash command failed. The command returned a non-zero exit code 125.; 5538)
Traceback (most recent call last):
  File "/home/airflow/.local/lib/python3.12/site-packages/airflow/task/task_runner/standard_task_runner.py", line 117, in _start_by_fork
    ret = args.func(args, dag=self.dag)
          ^^^^^^^^^^^^^^^^^^^^^^^^^^^^^
  File "/home/airflow/.local/lib/python3.12/site-packages/airflow/cli/cli_config.py", line 49, in command
    return func(*args, **kwargs)
           ^^^^^^^^^^^^^^^^^^^^^
  File "/home/airflow/.local/lib/python3.12/site-packages/airflow/utils/cli.py", line 116, in wrapper
    return f(*args, **kwargs)
           ^^^^^^^^^^^^^^^^^^
  File "/home/airflow/.local/lib/python3.12/site-packages/airflow/cli/commands/task_command.py", line 483, in task_run
    task_return_code = _run_task_by_selected_method(args, _dag, ti)
                       ^^^^^^^^^^^^^^^^^^^^^^^^^^^^^^^^^^^^^^^^^^^^
  File "/home/airflow/.local/lib/python3.12/site-packages/airflow/cli/commands/task_command.py", line 256, in _run_task_by_selected_method
    return _run_raw_task(args, ti)
           ^^^^^^^^^^^^^^^^^^^^^^^
  File "/home/airflow/.local/lib/python3.12/site-packages/airflow/cli/commands/task_command.py", line 341, in _run_raw_task
    return ti._run_raw_task(
           ^^^^^^^^^^^^^^^^^
  File "/home/airflow/.local/lib/python3.12/site-packages/airflow/utils/session.py", line 97, in wrapper
    return func(*args, session=session, **kwargs)
           ^^^^^^^^^^^^^^^^^^^^^^^^^^^^^^^^^^^^^^
  File "/home/airflow/.local/lib/python3.12/site-packages/airflow/models/taskinstance.py", line 3006, in _run_raw_task
    return _run_raw_task(
           ^^^^^^^^^^^^^^
  File "/home/airflow/.local/lib/python3.12/site-packages/airflow/models/taskinstance.py", line 274, in _run_raw_task
    TaskInstance._execute_task_with_callbacks(
  File "/home/airflow/.local/lib/python3.12/site-packages/airflow/models/taskinstance.py", line 3161, in _execute_task_with_callbacks
    result = self._execute_task(context, task_orig)
             ^^^^^^^^^^^^^^^^^^^^^^^^^^^^^^^^^^^^^^
  File "/home/airflow/.local/lib/python3.12/site-packages/airflow/models/taskinstance.py", line 3185, in _execute_task
    return _execute_task(self, context, task_orig)
           ^^^^^^^^^^^^^^^^^^^^^^^^^^^^^^^^^^^^^^^
  File "/home/airflow/.local/lib/python3.12/site-packages/airflow/models/taskinstance.py", line 768, in _execute_task
    result = _execute_callable(context=context, **execute_callable_kwargs)
             ^^^^^^^^^^^^^^^^^^^^^^^^^^^^^^^^^^^^^^^^^^^^^^^^^^^^^^^^^^^^^
  File "/home/airflow/.local/lib/python3.12/site-packages/airflow/models/taskinstance.py", line 734, in _execute_callable
    return ExecutionCallableRunner(
           ^^^^^^^^^^^^^^^^^^^^^^^^
  File "/home/airflow/.local/lib/python3.12/site-packages/airflow/utils/operator_helpers.py", line 252, in run
    return self.func(*args, **kwargs)
           ^^^^^^^^^^^^^^^^^^^^^^^^^^
  File "/home/airflow/.local/lib/python3.12/site-packages/airflow/models/baseoperator.py", line 424, in wrapper
    return func(self, *args, **kwargs)
           ^^^^^^^^^^^^^^^^^^^^^^^^^^^
  File "/home/airflow/.local/lib/python3.12/site-packages/airflow/operators/bash.py", line 276, in execute
    raise AirflowException(
airflow.exceptions.AirflowException: Bash command failed. The command returned a non-zero exit code 125.
[2025-03-24T22:27:24.807+0000] {local_task_job_runner.py:266} INFO - Task exited with return code 1
[2025-03-24T22:27:24.883+0000] {local_task_job_runner.py:245} INFO - ::endgroup::
[2025-03-24T22:27:25.072+0000] {standard_task_runner.py:217} INFO - Process not found (most likely exited), stop collecting metrics
[2025-03-24T23:57:23.610+0000] {local_task_job_runner.py:123} INFO - ::group::Pre task execution logs
[2025-03-24T23:57:23.642+0000] {taskinstance.py:2614} INFO - Dependencies all met for dep_context=non-requeueable deps ti=<TaskInstance: containers1_dag.php_app1 scheduled__2024-03-02T00:00:00+00:00 [queued]>
[2025-03-24T23:57:23.657+0000] {taskinstance.py:2614} INFO - Dependencies all met for dep_context=requeueable deps ti=<TaskInstance: containers1_dag.php_app1 scheduled__2024-03-02T00:00:00+00:00 [queued]>
[2025-03-24T23:57:23.658+0000] {taskinstance.py:2867} INFO - Starting attempt 1 of 6
[2025-03-24T23:57:24.052+0000] {taskinstance.py:2890} INFO - Executing <Task(BashOperator): php_app1> on 2024-03-02 00:00:00+00:00
[2025-03-24T23:57:24.094+0000] {standard_task_runner.py:104} INFO - Running: ['***', 'tasks', 'run', 'containers1_dag', 'php_app1', 'scheduled__2024-03-02T00:00:00+00:00', '--job-id', '6', '--raw', '--subdir', 'DAGS_FOLDER/containers1_dag.py', '--cfg-path', '/tmp/tmp9kvrjpku']
[2025-03-24T23:57:24.101+0000] {logging_mixin.py:190} WARNING - /home/***/.local/lib/python3.12/site-packages/***/task/task_runner/standard_task_runner.py:70 DeprecationWarning: This process (pid=205) is multi-threaded, use of fork() may lead to deadlocks in the child.
[2025-03-24T23:57:24.105+0000] {standard_task_runner.py:72} INFO - Started process 215 to run task
[2025-03-24T23:57:24.103+0000] {standard_task_runner.py:105} INFO - Job 6: Subtask php_app1
[2025-03-24T23:57:24.384+0000] {task_command.py:467} INFO - Running <TaskInstance: containers1_dag.php_app1 scheduled__2024-03-02T00:00:00+00:00 [running]> on host 8e89fdaa3360
[2025-03-24T23:57:25.005+0000] {taskinstance.py:3134} INFO - Exporting env vars: AIRFLOW_CTX_DAG_OWNER='andre' AIRFLOW_CTX_DAG_ID='containers1_dag' AIRFLOW_CTX_TASK_ID='php_app1' AIRFLOW_CTX_EXECUTION_DATE='2024-03-02T00:00:00+00:00' AIRFLOW_CTX_TRY_NUMBER='1' AIRFLOW_CTX_DAG_RUN_ID='scheduled__2024-03-02T00:00:00+00:00'
[2025-03-24T23:57:25.005+0000] {taskinstance.py:732} INFO - ::endgroup::
[2025-03-24T23:57:25.166+0000] {subprocess.py:78} INFO - Tmp dir root location: /tmp
[2025-03-24T23:57:25.167+0000] {subprocess.py:88} INFO - Running command: ['/usr/bin/bash', '-c', 'docker run -v $(pwd)/../in:/usr/src/app/in -v $(pwd):/usr/src/app php-app1']
[2025-03-24T23:57:25.257+0000] {subprocess.py:99} INFO - Output:
[2025-03-24T23:57:25.548+0000] {subprocess.py:106} INFO - docker: Cannot connect to the Docker daemon at unix:///var/run/docker.sock. Is the docker daemon running?.
[2025-03-24T23:57:25.549+0000] {subprocess.py:106} INFO - See 'docker run --help'.
[2025-03-24T23:57:25.563+0000] {subprocess.py:110} INFO - Command exited with return code 125
[2025-03-24T23:57:25.704+0000] {taskinstance.py:3313} ERROR - Task failed with exception
Traceback (most recent call last):
  File "/home/airflow/.local/lib/python3.12/site-packages/airflow/models/taskinstance.py", line 768, in _execute_task
    result = _execute_callable(context=context, **execute_callable_kwargs)
             ^^^^^^^^^^^^^^^^^^^^^^^^^^^^^^^^^^^^^^^^^^^^^^^^^^^^^^^^^^^^^
  File "/home/airflow/.local/lib/python3.12/site-packages/airflow/models/taskinstance.py", line 734, in _execute_callable
    return ExecutionCallableRunner(
           ^^^^^^^^^^^^^^^^^^^^^^^^
  File "/home/airflow/.local/lib/python3.12/site-packages/airflow/utils/operator_helpers.py", line 252, in run
    return self.func(*args, **kwargs)
           ^^^^^^^^^^^^^^^^^^^^^^^^^^
  File "/home/airflow/.local/lib/python3.12/site-packages/airflow/models/baseoperator.py", line 424, in wrapper
    return func(self, *args, **kwargs)
           ^^^^^^^^^^^^^^^^^^^^^^^^^^^
  File "/home/airflow/.local/lib/python3.12/site-packages/airflow/operators/bash.py", line 276, in execute
    raise AirflowException(
airflow.exceptions.AirflowException: Bash command failed. The command returned a non-zero exit code 125.
[2025-03-24T23:57:25.773+0000] {taskinstance.py:1226} INFO - Marking task as UP_FOR_RETRY. dag_id=containers1_dag, task_id=php_app1, run_id=scheduled__2024-03-02T00:00:00+00:00, execution_date=20240302T000000, start_date=20250324T235723, end_date=20250324T235725
[2025-03-24T23:57:26.220+0000] {taskinstance.py:341} INFO - ::group::Post task execution logs
[2025-03-24T23:57:26.233+0000] {standard_task_runner.py:124} ERROR - Failed to execute job 6 for task php_app1 (Bash command failed. The command returned a non-zero exit code 125.; 215)
Traceback (most recent call last):
  File "/home/airflow/.local/lib/python3.12/site-packages/airflow/task/task_runner/standard_task_runner.py", line 117, in _start_by_fork
    ret = args.func(args, dag=self.dag)
          ^^^^^^^^^^^^^^^^^^^^^^^^^^^^^
  File "/home/airflow/.local/lib/python3.12/site-packages/airflow/cli/cli_config.py", line 49, in command
    return func(*args, **kwargs)
           ^^^^^^^^^^^^^^^^^^^^^
  File "/home/airflow/.local/lib/python3.12/site-packages/airflow/utils/cli.py", line 116, in wrapper
    return f(*args, **kwargs)
           ^^^^^^^^^^^^^^^^^^
  File "/home/airflow/.local/lib/python3.12/site-packages/airflow/cli/commands/task_command.py", line 483, in task_run
    task_return_code = _run_task_by_selected_method(args, _dag, ti)
                       ^^^^^^^^^^^^^^^^^^^^^^^^^^^^^^^^^^^^^^^^^^^^
  File "/home/airflow/.local/lib/python3.12/site-packages/airflow/cli/commands/task_command.py", line 256, in _run_task_by_selected_method
    return _run_raw_task(args, ti)
           ^^^^^^^^^^^^^^^^^^^^^^^
  File "/home/airflow/.local/lib/python3.12/site-packages/airflow/cli/commands/task_command.py", line 341, in _run_raw_task
    return ti._run_raw_task(
           ^^^^^^^^^^^^^^^^^
  File "/home/airflow/.local/lib/python3.12/site-packages/airflow/utils/session.py", line 97, in wrapper
    return func(*args, session=session, **kwargs)
           ^^^^^^^^^^^^^^^^^^^^^^^^^^^^^^^^^^^^^^
  File "/home/airflow/.local/lib/python3.12/site-packages/airflow/models/taskinstance.py", line 3006, in _run_raw_task
    return _run_raw_task(
           ^^^^^^^^^^^^^^
  File "/home/airflow/.local/lib/python3.12/site-packages/airflow/models/taskinstance.py", line 274, in _run_raw_task
    TaskInstance._execute_task_with_callbacks(
  File "/home/airflow/.local/lib/python3.12/site-packages/airflow/models/taskinstance.py", line 3161, in _execute_task_with_callbacks
    result = self._execute_task(context, task_orig)
             ^^^^^^^^^^^^^^^^^^^^^^^^^^^^^^^^^^^^^^
  File "/home/airflow/.local/lib/python3.12/site-packages/airflow/models/taskinstance.py", line 3185, in _execute_task
    return _execute_task(self, context, task_orig)
           ^^^^^^^^^^^^^^^^^^^^^^^^^^^^^^^^^^^^^^^
  File "/home/airflow/.local/lib/python3.12/site-packages/airflow/models/taskinstance.py", line 768, in _execute_task
    result = _execute_callable(context=context, **execute_callable_kwargs)
             ^^^^^^^^^^^^^^^^^^^^^^^^^^^^^^^^^^^^^^^^^^^^^^^^^^^^^^^^^^^^^
  File "/home/airflow/.local/lib/python3.12/site-packages/airflow/models/taskinstance.py", line 734, in _execute_callable
    return ExecutionCallableRunner(
           ^^^^^^^^^^^^^^^^^^^^^^^^
  File "/home/airflow/.local/lib/python3.12/site-packages/airflow/utils/operator_helpers.py", line 252, in run
    return self.func(*args, **kwargs)
           ^^^^^^^^^^^^^^^^^^^^^^^^^^
  File "/home/airflow/.local/lib/python3.12/site-packages/airflow/models/baseoperator.py", line 424, in wrapper
    return func(self, *args, **kwargs)
           ^^^^^^^^^^^^^^^^^^^^^^^^^^^
  File "/home/airflow/.local/lib/python3.12/site-packages/airflow/operators/bash.py", line 276, in execute
    raise AirflowException(
airflow.exceptions.AirflowException: Bash command failed. The command returned a non-zero exit code 125.
[2025-03-24T23:57:26.377+0000] {local_task_job_runner.py:266} INFO - Task exited with return code 1
[2025-03-24T23:57:26.797+0000] {taskinstance.py:3901} INFO - 0 downstream tasks scheduled from follow-on schedule check
[2025-03-24T23:57:26.830+0000] {local_task_job_runner.py:245} INFO - ::endgroup::
[2025-03-25T00:18:25.048+0000] {local_task_job_runner.py:123} INFO - ::group::Pre task execution logs
[2025-03-25T00:18:25.239+0000] {taskinstance.py:2614} INFO - Dependencies all met for dep_context=non-requeueable deps ti=<TaskInstance: containers1_dag.php_app1 scheduled__2024-03-02T00:00:00+00:00 [queued]>
[2025-03-25T00:18:25.292+0000] {taskinstance.py:2614} INFO - Dependencies all met for dep_context=requeueable deps ti=<TaskInstance: containers1_dag.php_app1 scheduled__2024-03-02T00:00:00+00:00 [queued]>
[2025-03-25T00:18:25.293+0000] {taskinstance.py:2867} INFO - Starting attempt 1 of 6
[2025-03-25T00:18:25.402+0000] {taskinstance.py:2890} INFO - Executing <Task(DockerOperator): php_app1> on 2024-03-02 00:00:00+00:00
[2025-03-25T00:18:25.424+0000] {logging_mixin.py:190} WARNING - /home/***/.local/lib/python3.12/site-packages/***/task/task_runner/standard_task_runner.py:70 DeprecationWarning: This process (pid=389) is multi-threaded, use of fork() may lead to deadlocks in the child.
[2025-03-25T00:18:25.426+0000] {standard_task_runner.py:72} INFO - Started process 396 to run task
[2025-03-25T00:18:25.441+0000] {standard_task_runner.py:104} INFO - Running: ['***', 'tasks', 'run', 'containers1_dag', 'php_app1', 'scheduled__2024-03-02T00:00:00+00:00', '--job-id', '4', '--raw', '--subdir', 'DAGS_FOLDER/containers1_dag.py', '--cfg-path', '/tmp/tmp3ujumxq0']
[2025-03-25T00:18:25.447+0000] {standard_task_runner.py:105} INFO - Job 4: Subtask php_app1
[2025-03-25T00:18:25.699+0000] {task_command.py:467} INFO - Running <TaskInstance: containers1_dag.php_app1 scheduled__2024-03-02T00:00:00+00:00 [running]> on host 0f77abd8a5ce
[2025-03-25T00:18:26.524+0000] {taskinstance.py:3134} INFO - Exporting env vars: AIRFLOW_CTX_DAG_OWNER='andre' AIRFLOW_CTX_DAG_ID='containers1_dag' AIRFLOW_CTX_TASK_ID='php_app1' AIRFLOW_CTX_EXECUTION_DATE='2024-03-02T00:00:00+00:00' AIRFLOW_CTX_TRY_NUMBER='1' AIRFLOW_CTX_DAG_RUN_ID='scheduled__2024-03-02T00:00:00+00:00'
[2025-03-25T00:18:26.525+0000] {taskinstance.py:732} INFO - ::endgroup::
[2025-03-25T00:18:27.030+0000] {docker.py:157} ERROR - Failed to establish connection to Docker host unix://var/run/docker.sock: Error while fetching server API version: ('Connection aborted.', FileNotFoundError(2, 'No such file or directory'))
[2025-03-25T00:18:27.083+0000] {taskinstance.py:3313} ERROR - Task failed with exception
Traceback (most recent call last):
  File "/home/airflow/.local/lib/python3.12/site-packages/airflow/models/taskinstance.py", line 768, in _execute_task
    result = _execute_callable(context=context, **execute_callable_kwargs)
             ^^^^^^^^^^^^^^^^^^^^^^^^^^^^^^^^^^^^^^^^^^^^^^^^^^^^^^^^^^^^^
  File "/home/airflow/.local/lib/python3.12/site-packages/airflow/models/taskinstance.py", line 734, in _execute_callable
    return ExecutionCallableRunner(
           ^^^^^^^^^^^^^^^^^^^^^^^^
  File "/home/airflow/.local/lib/python3.12/site-packages/airflow/utils/operator_helpers.py", line 252, in run
    return self.func(*args, **kwargs)
           ^^^^^^^^^^^^^^^^^^^^^^^^^^
  File "/home/airflow/.local/lib/python3.12/site-packages/airflow/models/baseoperator.py", line 424, in wrapper
    return func(self, *args, **kwargs)
           ^^^^^^^^^^^^^^^^^^^^^^^^^^^
  File "/home/airflow/.local/lib/python3.12/site-packages/airflow/providers/docker/operators/docker.py", line 467, in execute
    if self.force_pull or not self.cli.images(name=self.image):
                              ^^^^^^^^
  File "/home/airflow/.local/lib/python3.12/site-packages/airflow/providers/docker/operators/docker.py", line 341, in cli
    return self.hook.api_client
           ^^^^^^^^^^^^^^^^^^^^
  File "/usr/local/lib/python3.12/functools.py", line 998, in __get__
    val = self.func(instance)
          ^^^^^^^^^^^^^^^^^^^
  File "/home/airflow/.local/lib/python3.12/site-packages/airflow/providers/docker/hooks/docker.py", line 161, in api_client
    raise AirflowException("Failed to establish connection to any given Docker hosts.")
airflow.exceptions.AirflowException: Failed to establish connection to any given Docker hosts.
[2025-03-25T00:18:27.150+0000] {taskinstance.py:1226} INFO - Marking task as UP_FOR_RETRY. dag_id=containers1_dag, task_id=php_app1, run_id=scheduled__2024-03-02T00:00:00+00:00, execution_date=20240302T000000, start_date=20250325T001825, end_date=20250325T001827
[2025-03-25T00:18:27.404+0000] {taskinstance.py:341} INFO - ::group::Post task execution logs
[2025-03-25T00:18:27.407+0000] {standard_task_runner.py:124} ERROR - Failed to execute job 4 for task php_app1 (Failed to establish connection to any given Docker hosts.; 396)
Traceback (most recent call last):
  File "/home/airflow/.local/lib/python3.12/site-packages/airflow/task/task_runner/standard_task_runner.py", line 117, in _start_by_fork
    ret = args.func(args, dag=self.dag)
          ^^^^^^^^^^^^^^^^^^^^^^^^^^^^^
  File "/home/airflow/.local/lib/python3.12/site-packages/airflow/cli/cli_config.py", line 49, in command
    return func(*args, **kwargs)
           ^^^^^^^^^^^^^^^^^^^^^
  File "/home/airflow/.local/lib/python3.12/site-packages/airflow/utils/cli.py", line 116, in wrapper
    return f(*args, **kwargs)
           ^^^^^^^^^^^^^^^^^^
  File "/home/airflow/.local/lib/python3.12/site-packages/airflow/cli/commands/task_command.py", line 483, in task_run
    task_return_code = _run_task_by_selected_method(args, _dag, ti)
                       ^^^^^^^^^^^^^^^^^^^^^^^^^^^^^^^^^^^^^^^^^^^^
  File "/home/airflow/.local/lib/python3.12/site-packages/airflow/cli/commands/task_command.py", line 256, in _run_task_by_selected_method
    return _run_raw_task(args, ti)
           ^^^^^^^^^^^^^^^^^^^^^^^
  File "/home/airflow/.local/lib/python3.12/site-packages/airflow/cli/commands/task_command.py", line 341, in _run_raw_task
    return ti._run_raw_task(
           ^^^^^^^^^^^^^^^^^
  File "/home/airflow/.local/lib/python3.12/site-packages/airflow/utils/session.py", line 97, in wrapper
    return func(*args, session=session, **kwargs)
           ^^^^^^^^^^^^^^^^^^^^^^^^^^^^^^^^^^^^^^
  File "/home/airflow/.local/lib/python3.12/site-packages/airflow/models/taskinstance.py", line 3006, in _run_raw_task
    return _run_raw_task(
           ^^^^^^^^^^^^^^
  File "/home/airflow/.local/lib/python3.12/site-packages/airflow/models/taskinstance.py", line 274, in _run_raw_task
    TaskInstance._execute_task_with_callbacks(
  File "/home/airflow/.local/lib/python3.12/site-packages/airflow/models/taskinstance.py", line 3161, in _execute_task_with_callbacks
    result = self._execute_task(context, task_orig)
             ^^^^^^^^^^^^^^^^^^^^^^^^^^^^^^^^^^^^^^
  File "/home/airflow/.local/lib/python3.12/site-packages/airflow/models/taskinstance.py", line 3185, in _execute_task
    return _execute_task(self, context, task_orig)
           ^^^^^^^^^^^^^^^^^^^^^^^^^^^^^^^^^^^^^^^
  File "/home/airflow/.local/lib/python3.12/site-packages/airflow/models/taskinstance.py", line 768, in _execute_task
    result = _execute_callable(context=context, **execute_callable_kwargs)
             ^^^^^^^^^^^^^^^^^^^^^^^^^^^^^^^^^^^^^^^^^^^^^^^^^^^^^^^^^^^^^
  File "/home/airflow/.local/lib/python3.12/site-packages/airflow/models/taskinstance.py", line 734, in _execute_callable
    return ExecutionCallableRunner(
           ^^^^^^^^^^^^^^^^^^^^^^^^
  File "/home/airflow/.local/lib/python3.12/site-packages/airflow/utils/operator_helpers.py", line 252, in run
    return self.func(*args, **kwargs)
           ^^^^^^^^^^^^^^^^^^^^^^^^^^
  File "/home/airflow/.local/lib/python3.12/site-packages/airflow/models/baseoperator.py", line 424, in wrapper
    return func(self, *args, **kwargs)
           ^^^^^^^^^^^^^^^^^^^^^^^^^^^
  File "/home/airflow/.local/lib/python3.12/site-packages/airflow/providers/docker/operators/docker.py", line 467, in execute
    if self.force_pull or not self.cli.images(name=self.image):
                              ^^^^^^^^
  File "/home/airflow/.local/lib/python3.12/site-packages/airflow/providers/docker/operators/docker.py", line 341, in cli
    return self.hook.api_client
           ^^^^^^^^^^^^^^^^^^^^
  File "/usr/local/lib/python3.12/functools.py", line 998, in __get__
    val = self.func(instance)
          ^^^^^^^^^^^^^^^^^^^
  File "/home/airflow/.local/lib/python3.12/site-packages/airflow/providers/docker/hooks/docker.py", line 161, in api_client
    raise AirflowException("Failed to establish connection to any given Docker hosts.")
airflow.exceptions.AirflowException: Failed to establish connection to any given Docker hosts.
[2025-03-25T00:18:27.637+0000] {local_task_job_runner.py:266} INFO - Task exited with return code 1
[2025-03-25T00:18:27.756+0000] {local_task_job_runner.py:245} INFO - ::endgroup::
[2025-03-25T00:25:39.358+0000] {local_task_job_runner.py:123} INFO - ::group::Pre task execution logs
[2025-03-25T00:25:39.424+0000] {taskinstance.py:2614} INFO - Dependencies all met for dep_context=non-requeueable deps ti=<TaskInstance: containers1_dag.php_app1 scheduled__2024-03-02T00:00:00+00:00 [queued]>
[2025-03-25T00:25:39.459+0000] {taskinstance.py:2614} INFO - Dependencies all met for dep_context=requeueable deps ti=<TaskInstance: containers1_dag.php_app1 scheduled__2024-03-02T00:00:00+00:00 [queued]>
[2025-03-25T00:25:39.460+0000] {taskinstance.py:2867} INFO - Starting attempt 1 of 6
[2025-03-25T00:25:39.539+0000] {taskinstance.py:2890} INFO - Executing <Task(DockerOperator): php_app1> on 2024-03-02 00:00:00+00:00
[2025-03-25T00:25:39.617+0000] {logging_mixin.py:190} WARNING - /home/***/.local/lib/python3.12/site-packages/***/task/task_runner/standard_task_runner.py:70 DeprecationWarning: This process (pid=200) is multi-threaded, use of fork() may lead to deadlocks in the child.
[2025-03-25T00:25:39.619+0000] {standard_task_runner.py:72} INFO - Started process 208 to run task
[2025-03-25T00:25:39.619+0000] {standard_task_runner.py:104} INFO - Running: ['***', 'tasks', 'run', 'containers1_dag', 'php_app1', 'scheduled__2024-03-02T00:00:00+00:00', '--job-id', '5', '--raw', '--subdir', 'DAGS_FOLDER/containers1_dag.py', '--cfg-path', '/tmp/tmpfhads5yn']
[2025-03-25T00:25:39.639+0000] {standard_task_runner.py:105} INFO - Job 5: Subtask php_app1
[2025-03-25T00:25:39.910+0000] {task_command.py:467} INFO - Running <TaskInstance: containers1_dag.php_app1 scheduled__2024-03-02T00:00:00+00:00 [running]> on host 7e2e363232cf
[2025-03-25T00:25:40.970+0000] {taskinstance.py:3134} INFO - Exporting env vars: AIRFLOW_CTX_DAG_OWNER='andre' AIRFLOW_CTX_DAG_ID='containers1_dag' AIRFLOW_CTX_TASK_ID='php_app1' AIRFLOW_CTX_EXECUTION_DATE='2024-03-02T00:00:00+00:00' AIRFLOW_CTX_TRY_NUMBER='1' AIRFLOW_CTX_DAG_RUN_ID='scheduled__2024-03-02T00:00:00+00:00'
[2025-03-25T00:25:40.971+0000] {taskinstance.py:732} INFO - ::endgroup::
[2025-03-25T00:25:41.096+0000] {docker.py:157} ERROR - Failed to establish connection to Docker host unix://var/run/docker.sock: Error while fetching server API version: ('Connection aborted.', FileNotFoundError(2, 'No such file or directory'))
[2025-03-25T00:25:41.129+0000] {taskinstance.py:3313} ERROR - Task failed with exception
Traceback (most recent call last):
  File "/home/airflow/.local/lib/python3.12/site-packages/airflow/models/taskinstance.py", line 768, in _execute_task
    result = _execute_callable(context=context, **execute_callable_kwargs)
             ^^^^^^^^^^^^^^^^^^^^^^^^^^^^^^^^^^^^^^^^^^^^^^^^^^^^^^^^^^^^^
  File "/home/airflow/.local/lib/python3.12/site-packages/airflow/models/taskinstance.py", line 734, in _execute_callable
    return ExecutionCallableRunner(
           ^^^^^^^^^^^^^^^^^^^^^^^^
  File "/home/airflow/.local/lib/python3.12/site-packages/airflow/utils/operator_helpers.py", line 252, in run
    return self.func(*args, **kwargs)
           ^^^^^^^^^^^^^^^^^^^^^^^^^^
  File "/home/airflow/.local/lib/python3.12/site-packages/airflow/models/baseoperator.py", line 424, in wrapper
    return func(self, *args, **kwargs)
           ^^^^^^^^^^^^^^^^^^^^^^^^^^^
  File "/home/airflow/.local/lib/python3.12/site-packages/airflow/providers/docker/operators/docker.py", line 467, in execute
    if self.force_pull or not self.cli.images(name=self.image):
                              ^^^^^^^^
  File "/home/airflow/.local/lib/python3.12/site-packages/airflow/providers/docker/operators/docker.py", line 341, in cli
    return self.hook.api_client
           ^^^^^^^^^^^^^^^^^^^^
  File "/usr/local/lib/python3.12/functools.py", line 998, in __get__
    val = self.func(instance)
          ^^^^^^^^^^^^^^^^^^^
  File "/home/airflow/.local/lib/python3.12/site-packages/airflow/providers/docker/hooks/docker.py", line 161, in api_client
    raise AirflowException("Failed to establish connection to any given Docker hosts.")
airflow.exceptions.AirflowException: Failed to establish connection to any given Docker hosts.
[2025-03-25T00:25:41.190+0000] {taskinstance.py:1226} INFO - Marking task as UP_FOR_RETRY. dag_id=containers1_dag, task_id=php_app1, run_id=scheduled__2024-03-02T00:00:00+00:00, execution_date=20240302T000000, start_date=20250325T002539, end_date=20250325T002541
[2025-03-25T00:25:41.420+0000] {taskinstance.py:341} INFO - ::group::Post task execution logs
[2025-03-25T00:25:41.421+0000] {standard_task_runner.py:124} ERROR - Failed to execute job 5 for task php_app1 (Failed to establish connection to any given Docker hosts.; 208)
Traceback (most recent call last):
  File "/home/airflow/.local/lib/python3.12/site-packages/airflow/task/task_runner/standard_task_runner.py", line 117, in _start_by_fork
    ret = args.func(args, dag=self.dag)
          ^^^^^^^^^^^^^^^^^^^^^^^^^^^^^
  File "/home/airflow/.local/lib/python3.12/site-packages/airflow/cli/cli_config.py", line 49, in command
    return func(*args, **kwargs)
           ^^^^^^^^^^^^^^^^^^^^^
  File "/home/airflow/.local/lib/python3.12/site-packages/airflow/utils/cli.py", line 116, in wrapper
    return f(*args, **kwargs)
           ^^^^^^^^^^^^^^^^^^
  File "/home/airflow/.local/lib/python3.12/site-packages/airflow/cli/commands/task_command.py", line 483, in task_run
    task_return_code = _run_task_by_selected_method(args, _dag, ti)
                       ^^^^^^^^^^^^^^^^^^^^^^^^^^^^^^^^^^^^^^^^^^^^
  File "/home/airflow/.local/lib/python3.12/site-packages/airflow/cli/commands/task_command.py", line 256, in _run_task_by_selected_method
    return _run_raw_task(args, ti)
           ^^^^^^^^^^^^^^^^^^^^^^^
  File "/home/airflow/.local/lib/python3.12/site-packages/airflow/cli/commands/task_command.py", line 341, in _run_raw_task
    return ti._run_raw_task(
           ^^^^^^^^^^^^^^^^^
  File "/home/airflow/.local/lib/python3.12/site-packages/airflow/utils/session.py", line 97, in wrapper
    return func(*args, session=session, **kwargs)
           ^^^^^^^^^^^^^^^^^^^^^^^^^^^^^^^^^^^^^^
  File "/home/airflow/.local/lib/python3.12/site-packages/airflow/models/taskinstance.py", line 3006, in _run_raw_task
    return _run_raw_task(
           ^^^^^^^^^^^^^^
  File "/home/airflow/.local/lib/python3.12/site-packages/airflow/models/taskinstance.py", line 274, in _run_raw_task
    TaskInstance._execute_task_with_callbacks(
  File "/home/airflow/.local/lib/python3.12/site-packages/airflow/models/taskinstance.py", line 3161, in _execute_task_with_callbacks
    result = self._execute_task(context, task_orig)
             ^^^^^^^^^^^^^^^^^^^^^^^^^^^^^^^^^^^^^^
  File "/home/airflow/.local/lib/python3.12/site-packages/airflow/models/taskinstance.py", line 3185, in _execute_task
    return _execute_task(self, context, task_orig)
           ^^^^^^^^^^^^^^^^^^^^^^^^^^^^^^^^^^^^^^^
  File "/home/airflow/.local/lib/python3.12/site-packages/airflow/models/taskinstance.py", line 768, in _execute_task
    result = _execute_callable(context=context, **execute_callable_kwargs)
             ^^^^^^^^^^^^^^^^^^^^^^^^^^^^^^^^^^^^^^^^^^^^^^^^^^^^^^^^^^^^^
  File "/home/airflow/.local/lib/python3.12/site-packages/airflow/models/taskinstance.py", line 734, in _execute_callable
    return ExecutionCallableRunner(
           ^^^^^^^^^^^^^^^^^^^^^^^^
  File "/home/airflow/.local/lib/python3.12/site-packages/airflow/utils/operator_helpers.py", line 252, in run
    return self.func(*args, **kwargs)
           ^^^^^^^^^^^^^^^^^^^^^^^^^^
  File "/home/airflow/.local/lib/python3.12/site-packages/airflow/models/baseoperator.py", line 424, in wrapper
    return func(self, *args, **kwargs)
           ^^^^^^^^^^^^^^^^^^^^^^^^^^^
  File "/home/airflow/.local/lib/python3.12/site-packages/airflow/providers/docker/operators/docker.py", line 467, in execute
    if self.force_pull or not self.cli.images(name=self.image):
                              ^^^^^^^^
  File "/home/airflow/.local/lib/python3.12/site-packages/airflow/providers/docker/operators/docker.py", line 341, in cli
    return self.hook.api_client
           ^^^^^^^^^^^^^^^^^^^^
  File "/usr/local/lib/python3.12/functools.py", line 998, in __get__
    val = self.func(instance)
          ^^^^^^^^^^^^^^^^^^^
  File "/home/airflow/.local/lib/python3.12/site-packages/airflow/providers/docker/hooks/docker.py", line 161, in api_client
    raise AirflowException("Failed to establish connection to any given Docker hosts.")
airflow.exceptions.AirflowException: Failed to establish connection to any given Docker hosts.
[2025-03-25T00:25:41.566+0000] {local_task_job_runner.py:266} INFO - Task exited with return code 1
[2025-03-25T00:25:41.771+0000] {taskinstance.py:3901} INFO - 0 downstream tasks scheduled from follow-on schedule check
[2025-03-25T00:25:41.794+0000] {local_task_job_runner.py:245} INFO - ::endgroup::
[2025-03-25T12:45:29.550+0000] {local_task_job_runner.py:123} INFO - ::group::Pre task execution logs
[2025-03-25T12:45:29.615+0000] {taskinstance.py:2614} INFO - Dependencies all met for dep_context=non-requeueable deps ti=<TaskInstance: containers1_dag.php_app1 scheduled__2024-03-02T00:00:00+00:00 [queued]>
[2025-03-25T12:45:29.645+0000] {taskinstance.py:2614} INFO - Dependencies all met for dep_context=requeueable deps ti=<TaskInstance: containers1_dag.php_app1 scheduled__2024-03-02T00:00:00+00:00 [queued]>
[2025-03-25T12:45:29.649+0000] {taskinstance.py:2867} INFO - Starting attempt 1 of 6
[2025-03-25T12:45:29.834+0000] {taskinstance.py:2890} INFO - Executing <Task(DockerOperator): php_app1> on 2024-03-02 00:00:00+00:00
[2025-03-25T12:45:29.871+0000] {standard_task_runner.py:104} INFO - Running: ['***', 'tasks', 'run', 'containers1_dag', 'php_app1', 'scheduled__2024-03-02T00:00:00+00:00', '--job-id', '5', '--raw', '--subdir', 'DAGS_FOLDER/containers1_dag.py', '--cfg-path', '/tmp/tmp_bkm4ene']
[2025-03-25T12:45:29.880+0000] {standard_task_runner.py:105} INFO - Job 5: Subtask php_app1
[2025-03-25T12:45:29.884+0000] {logging_mixin.py:190} WARNING - /home/***/.local/lib/python3.12/site-packages/***/task/task_runner/standard_task_runner.py:70 DeprecationWarning: This process (pid=215) is multi-threaded, use of fork() may lead to deadlocks in the child.
[2025-03-25T12:45:29.886+0000] {standard_task_runner.py:72} INFO - Started process 227 to run task
[2025-03-25T12:45:30.123+0000] {task_command.py:467} INFO - Running <TaskInstance: containers1_dag.php_app1 scheduled__2024-03-02T00:00:00+00:00 [running]> on host c83c0958fca4
[2025-03-25T12:45:30.702+0000] {taskinstance.py:3134} INFO - Exporting env vars: AIRFLOW_CTX_DAG_OWNER='andre' AIRFLOW_CTX_DAG_ID='containers1_dag' AIRFLOW_CTX_TASK_ID='php_app1' AIRFLOW_CTX_EXECUTION_DATE='2024-03-02T00:00:00+00:00' AIRFLOW_CTX_TRY_NUMBER='1' AIRFLOW_CTX_DAG_RUN_ID='scheduled__2024-03-02T00:00:00+00:00'
[2025-03-25T12:45:30.704+0000] {taskinstance.py:732} INFO - ::endgroup::
[2025-03-25T12:45:30.934+0000] {docker.py:157} ERROR - Failed to establish connection to Docker host unix://var/run/docker.sock: Error while fetching server API version: ('Connection aborted.', FileNotFoundError(2, 'No such file or directory'))
[2025-03-25T12:45:30.969+0000] {taskinstance.py:3313} ERROR - Task failed with exception
Traceback (most recent call last):
  File "/home/airflow/.local/lib/python3.12/site-packages/airflow/models/taskinstance.py", line 768, in _execute_task
    result = _execute_callable(context=context, **execute_callable_kwargs)
             ^^^^^^^^^^^^^^^^^^^^^^^^^^^^^^^^^^^^^^^^^^^^^^^^^^^^^^^^^^^^^
  File "/home/airflow/.local/lib/python3.12/site-packages/airflow/models/taskinstance.py", line 734, in _execute_callable
    return ExecutionCallableRunner(
           ^^^^^^^^^^^^^^^^^^^^^^^^
  File "/home/airflow/.local/lib/python3.12/site-packages/airflow/utils/operator_helpers.py", line 252, in run
    return self.func(*args, **kwargs)
           ^^^^^^^^^^^^^^^^^^^^^^^^^^
  File "/home/airflow/.local/lib/python3.12/site-packages/airflow/models/baseoperator.py", line 424, in wrapper
    return func(self, *args, **kwargs)
           ^^^^^^^^^^^^^^^^^^^^^^^^^^^
  File "/home/airflow/.local/lib/python3.12/site-packages/airflow/providers/docker/operators/docker.py", line 467, in execute
    if self.force_pull or not self.cli.images(name=self.image):
                              ^^^^^^^^
  File "/home/airflow/.local/lib/python3.12/site-packages/airflow/providers/docker/operators/docker.py", line 341, in cli
    return self.hook.api_client
           ^^^^^^^^^^^^^^^^^^^^
  File "/usr/local/lib/python3.12/functools.py", line 998, in __get__
    val = self.func(instance)
          ^^^^^^^^^^^^^^^^^^^
  File "/home/airflow/.local/lib/python3.12/site-packages/airflow/providers/docker/hooks/docker.py", line 161, in api_client
    raise AirflowException("Failed to establish connection to any given Docker hosts.")
airflow.exceptions.AirflowException: Failed to establish connection to any given Docker hosts.
[2025-03-25T12:45:31.014+0000] {taskinstance.py:1226} INFO - Marking task as UP_FOR_RETRY. dag_id=containers1_dag, task_id=php_app1, run_id=scheduled__2024-03-02T00:00:00+00:00, execution_date=20240302T000000, start_date=20250325T124529, end_date=20250325T124531
[2025-03-25T12:45:31.259+0000] {taskinstance.py:341} INFO - ::group::Post task execution logs
[2025-03-25T12:45:31.260+0000] {standard_task_runner.py:124} ERROR - Failed to execute job 5 for task php_app1 (Failed to establish connection to any given Docker hosts.; 227)
Traceback (most recent call last):
  File "/home/airflow/.local/lib/python3.12/site-packages/airflow/task/task_runner/standard_task_runner.py", line 117, in _start_by_fork
    ret = args.func(args, dag=self.dag)
          ^^^^^^^^^^^^^^^^^^^^^^^^^^^^^
  File "/home/airflow/.local/lib/python3.12/site-packages/airflow/cli/cli_config.py", line 49, in command
    return func(*args, **kwargs)
           ^^^^^^^^^^^^^^^^^^^^^
  File "/home/airflow/.local/lib/python3.12/site-packages/airflow/utils/cli.py", line 116, in wrapper
    return f(*args, **kwargs)
           ^^^^^^^^^^^^^^^^^^
  File "/home/airflow/.local/lib/python3.12/site-packages/airflow/cli/commands/task_command.py", line 483, in task_run
    task_return_code = _run_task_by_selected_method(args, _dag, ti)
                       ^^^^^^^^^^^^^^^^^^^^^^^^^^^^^^^^^^^^^^^^^^^^
  File "/home/airflow/.local/lib/python3.12/site-packages/airflow/cli/commands/task_command.py", line 256, in _run_task_by_selected_method
    return _run_raw_task(args, ti)
           ^^^^^^^^^^^^^^^^^^^^^^^
  File "/home/airflow/.local/lib/python3.12/site-packages/airflow/cli/commands/task_command.py", line 341, in _run_raw_task
    return ti._run_raw_task(
           ^^^^^^^^^^^^^^^^^
  File "/home/airflow/.local/lib/python3.12/site-packages/airflow/utils/session.py", line 97, in wrapper
    return func(*args, session=session, **kwargs)
           ^^^^^^^^^^^^^^^^^^^^^^^^^^^^^^^^^^^^^^
  File "/home/airflow/.local/lib/python3.12/site-packages/airflow/models/taskinstance.py", line 3006, in _run_raw_task
    return _run_raw_task(
           ^^^^^^^^^^^^^^
  File "/home/airflow/.local/lib/python3.12/site-packages/airflow/models/taskinstance.py", line 274, in _run_raw_task
    TaskInstance._execute_task_with_callbacks(
  File "/home/airflow/.local/lib/python3.12/site-packages/airflow/models/taskinstance.py", line 3161, in _execute_task_with_callbacks
    result = self._execute_task(context, task_orig)
             ^^^^^^^^^^^^^^^^^^^^^^^^^^^^^^^^^^^^^^
  File "/home/airflow/.local/lib/python3.12/site-packages/airflow/models/taskinstance.py", line 3185, in _execute_task
    return _execute_task(self, context, task_orig)
           ^^^^^^^^^^^^^^^^^^^^^^^^^^^^^^^^^^^^^^^
  File "/home/airflow/.local/lib/python3.12/site-packages/airflow/models/taskinstance.py", line 768, in _execute_task
    result = _execute_callable(context=context, **execute_callable_kwargs)
             ^^^^^^^^^^^^^^^^^^^^^^^^^^^^^^^^^^^^^^^^^^^^^^^^^^^^^^^^^^^^^
  File "/home/airflow/.local/lib/python3.12/site-packages/airflow/models/taskinstance.py", line 734, in _execute_callable
    return ExecutionCallableRunner(
           ^^^^^^^^^^^^^^^^^^^^^^^^
  File "/home/airflow/.local/lib/python3.12/site-packages/airflow/utils/operator_helpers.py", line 252, in run
    return self.func(*args, **kwargs)
           ^^^^^^^^^^^^^^^^^^^^^^^^^^
  File "/home/airflow/.local/lib/python3.12/site-packages/airflow/models/baseoperator.py", line 424, in wrapper
    return func(self, *args, **kwargs)
           ^^^^^^^^^^^^^^^^^^^^^^^^^^^
  File "/home/airflow/.local/lib/python3.12/site-packages/airflow/providers/docker/operators/docker.py", line 467, in execute
    if self.force_pull or not self.cli.images(name=self.image):
                              ^^^^^^^^
  File "/home/airflow/.local/lib/python3.12/site-packages/airflow/providers/docker/operators/docker.py", line 341, in cli
    return self.hook.api_client
           ^^^^^^^^^^^^^^^^^^^^
  File "/usr/local/lib/python3.12/functools.py", line 998, in __get__
    val = self.func(instance)
          ^^^^^^^^^^^^^^^^^^^
  File "/home/airflow/.local/lib/python3.12/site-packages/airflow/providers/docker/hooks/docker.py", line 161, in api_client
    raise AirflowException("Failed to establish connection to any given Docker hosts.")
airflow.exceptions.AirflowException: Failed to establish connection to any given Docker hosts.
[2025-03-25T12:45:31.311+0000] {local_task_job_runner.py:266} INFO - Task exited with return code 1
[2025-03-25T12:45:31.513+0000] {taskinstance.py:3901} INFO - 0 downstream tasks scheduled from follow-on schedule check
[2025-03-25T12:45:31.556+0000] {local_task_job_runner.py:245} INFO - ::endgroup::
[2025-03-26T11:52:44.759+0000] {local_task_job_runner.py:123} INFO - ::group::Pre task execution logs
[2025-03-26T11:52:44.857+0000] {taskinstance.py:2614} INFO - Dependencies all met for dep_context=non-requeueable deps ti=<TaskInstance: containers1_dag.php_app1 scheduled__2024-03-02T00:00:00+00:00 [queued]>
[2025-03-26T11:52:44.916+0000] {taskinstance.py:2614} INFO - Dependencies all met for dep_context=requeueable deps ti=<TaskInstance: containers1_dag.php_app1 scheduled__2024-03-02T00:00:00+00:00 [queued]>
[2025-03-26T11:52:44.924+0000] {taskinstance.py:2867} INFO - Starting attempt 1 of 6
[2025-03-26T11:52:45.116+0000] {taskinstance.py:2890} INFO - Executing <Task(DockerOperator): php_app1> on 2024-03-02 00:00:00+00:00
[2025-03-26T11:52:45.157+0000] {standard_task_runner.py:104} INFO - Running: ['***', 'tasks', 'run', 'containers1_dag', 'php_app1', 'scheduled__2024-03-02T00:00:00+00:00', '--job-id', '5', '--raw', '--subdir', 'DAGS_FOLDER/containers1_dag.py', '--cfg-path', '/tmp/tmpaf69rz1o']
[2025-03-26T11:52:45.172+0000] {standard_task_runner.py:105} INFO - Job 5: Subtask php_app1
[2025-03-26T11:52:45.188+0000] {logging_mixin.py:190} WARNING - /home/***/.local/lib/python3.12/site-packages/***/task/task_runner/standard_task_runner.py:70 DeprecationWarning: This process (pid=216) is multi-threaded, use of fork() may lead to deadlocks in the child.
[2025-03-26T11:52:45.189+0000] {standard_task_runner.py:72} INFO - Started process 228 to run task
[2025-03-26T11:52:45.496+0000] {task_command.py:467} INFO - Running <TaskInstance: containers1_dag.php_app1 scheduled__2024-03-02T00:00:00+00:00 [running]> on host c0a4d7e9da1a
[2025-03-26T11:52:46.299+0000] {taskinstance.py:3134} INFO - Exporting env vars: AIRFLOW_CTX_DAG_OWNER='andre' AIRFLOW_CTX_DAG_ID='containers1_dag' AIRFLOW_CTX_TASK_ID='php_app1' AIRFLOW_CTX_EXECUTION_DATE='2024-03-02T00:00:00+00:00' AIRFLOW_CTX_TRY_NUMBER='1' AIRFLOW_CTX_DAG_RUN_ID='scheduled__2024-03-02T00:00:00+00:00'
[2025-03-26T11:52:46.301+0000] {taskinstance.py:732} INFO - ::endgroup::
[2025-03-26T11:52:46.356+0000] {docker.py:157} ERROR - Failed to establish connection to Docker host unix://var/run/docker.sock: Error while fetching server API version: ('Connection aborted.', FileNotFoundError(2, 'No such file or directory'))
[2025-03-26T11:52:46.384+0000] {taskinstance.py:3313} ERROR - Task failed with exception
Traceback (most recent call last):
  File "/home/airflow/.local/lib/python3.12/site-packages/airflow/models/taskinstance.py", line 768, in _execute_task
    result = _execute_callable(context=context, **execute_callable_kwargs)
             ^^^^^^^^^^^^^^^^^^^^^^^^^^^^^^^^^^^^^^^^^^^^^^^^^^^^^^^^^^^^^
  File "/home/airflow/.local/lib/python3.12/site-packages/airflow/models/taskinstance.py", line 734, in _execute_callable
    return ExecutionCallableRunner(
           ^^^^^^^^^^^^^^^^^^^^^^^^
  File "/home/airflow/.local/lib/python3.12/site-packages/airflow/utils/operator_helpers.py", line 252, in run
    return self.func(*args, **kwargs)
           ^^^^^^^^^^^^^^^^^^^^^^^^^^
  File "/home/airflow/.local/lib/python3.12/site-packages/airflow/models/baseoperator.py", line 424, in wrapper
    return func(self, *args, **kwargs)
           ^^^^^^^^^^^^^^^^^^^^^^^^^^^
  File "/home/airflow/.local/lib/python3.12/site-packages/airflow/providers/docker/operators/docker.py", line 467, in execute
    if self.force_pull or not self.cli.images(name=self.image):
                              ^^^^^^^^
  File "/home/airflow/.local/lib/python3.12/site-packages/airflow/providers/docker/operators/docker.py", line 341, in cli
    return self.hook.api_client
           ^^^^^^^^^^^^^^^^^^^^
  File "/usr/local/lib/python3.12/functools.py", line 998, in __get__
    val = self.func(instance)
          ^^^^^^^^^^^^^^^^^^^
  File "/home/airflow/.local/lib/python3.12/site-packages/airflow/providers/docker/hooks/docker.py", line 161, in api_client
    raise AirflowException("Failed to establish connection to any given Docker hosts.")
airflow.exceptions.AirflowException: Failed to establish connection to any given Docker hosts.
[2025-03-26T11:52:46.406+0000] {taskinstance.py:1226} INFO - Marking task as UP_FOR_RETRY. dag_id=containers1_dag, task_id=php_app1, run_id=scheduled__2024-03-02T00:00:00+00:00, execution_date=20240302T000000, start_date=20250326T115244, end_date=20250326T115246
[2025-03-26T11:52:46.841+0000] {taskinstance.py:341} INFO - ::group::Post task execution logs
[2025-03-26T11:52:46.873+0000] {standard_task_runner.py:124} ERROR - Failed to execute job 5 for task php_app1 (Failed to establish connection to any given Docker hosts.; 228)
Traceback (most recent call last):
  File "/home/airflow/.local/lib/python3.12/site-packages/airflow/task/task_runner/standard_task_runner.py", line 117, in _start_by_fork
    ret = args.func(args, dag=self.dag)
          ^^^^^^^^^^^^^^^^^^^^^^^^^^^^^
  File "/home/airflow/.local/lib/python3.12/site-packages/airflow/cli/cli_config.py", line 49, in command
    return func(*args, **kwargs)
           ^^^^^^^^^^^^^^^^^^^^^
  File "/home/airflow/.local/lib/python3.12/site-packages/airflow/utils/cli.py", line 116, in wrapper
    return f(*args, **kwargs)
           ^^^^^^^^^^^^^^^^^^
  File "/home/airflow/.local/lib/python3.12/site-packages/airflow/cli/commands/task_command.py", line 483, in task_run
    task_return_code = _run_task_by_selected_method(args, _dag, ti)
                       ^^^^^^^^^^^^^^^^^^^^^^^^^^^^^^^^^^^^^^^^^^^^
  File "/home/airflow/.local/lib/python3.12/site-packages/airflow/cli/commands/task_command.py", line 256, in _run_task_by_selected_method
    return _run_raw_task(args, ti)
           ^^^^^^^^^^^^^^^^^^^^^^^
  File "/home/airflow/.local/lib/python3.12/site-packages/airflow/cli/commands/task_command.py", line 341, in _run_raw_task
    return ti._run_raw_task(
           ^^^^^^^^^^^^^^^^^
  File "/home/airflow/.local/lib/python3.12/site-packages/airflow/utils/session.py", line 97, in wrapper
    return func(*args, session=session, **kwargs)
           ^^^^^^^^^^^^^^^^^^^^^^^^^^^^^^^^^^^^^^
  File "/home/airflow/.local/lib/python3.12/site-packages/airflow/models/taskinstance.py", line 3006, in _run_raw_task
    return _run_raw_task(
           ^^^^^^^^^^^^^^
  File "/home/airflow/.local/lib/python3.12/site-packages/airflow/models/taskinstance.py", line 274, in _run_raw_task
    TaskInstance._execute_task_with_callbacks(
  File "/home/airflow/.local/lib/python3.12/site-packages/airflow/models/taskinstance.py", line 3161, in _execute_task_with_callbacks
    result = self._execute_task(context, task_orig)
             ^^^^^^^^^^^^^^^^^^^^^^^^^^^^^^^^^^^^^^
  File "/home/airflow/.local/lib/python3.12/site-packages/airflow/models/taskinstance.py", line 3185, in _execute_task
    return _execute_task(self, context, task_orig)
           ^^^^^^^^^^^^^^^^^^^^^^^^^^^^^^^^^^^^^^^
  File "/home/airflow/.local/lib/python3.12/site-packages/airflow/models/taskinstance.py", line 768, in _execute_task
    result = _execute_callable(context=context, **execute_callable_kwargs)
             ^^^^^^^^^^^^^^^^^^^^^^^^^^^^^^^^^^^^^^^^^^^^^^^^^^^^^^^^^^^^^
  File "/home/airflow/.local/lib/python3.12/site-packages/airflow/models/taskinstance.py", line 734, in _execute_callable
    return ExecutionCallableRunner(
           ^^^^^^^^^^^^^^^^^^^^^^^^
  File "/home/airflow/.local/lib/python3.12/site-packages/airflow/utils/operator_helpers.py", line 252, in run
    return self.func(*args, **kwargs)
           ^^^^^^^^^^^^^^^^^^^^^^^^^^
  File "/home/airflow/.local/lib/python3.12/site-packages/airflow/models/baseoperator.py", line 424, in wrapper
    return func(self, *args, **kwargs)
           ^^^^^^^^^^^^^^^^^^^^^^^^^^^
  File "/home/airflow/.local/lib/python3.12/site-packages/airflow/providers/docker/operators/docker.py", line 467, in execute
    if self.force_pull or not self.cli.images(name=self.image):
                              ^^^^^^^^
  File "/home/airflow/.local/lib/python3.12/site-packages/airflow/providers/docker/operators/docker.py", line 341, in cli
    return self.hook.api_client
           ^^^^^^^^^^^^^^^^^^^^
  File "/usr/local/lib/python3.12/functools.py", line 998, in __get__
    val = self.func(instance)
          ^^^^^^^^^^^^^^^^^^^
  File "/home/airflow/.local/lib/python3.12/site-packages/airflow/providers/docker/hooks/docker.py", line 161, in api_client
    raise AirflowException("Failed to establish connection to any given Docker hosts.")
airflow.exceptions.AirflowException: Failed to establish connection to any given Docker hosts.
[2025-03-26T11:52:47.103+0000] {local_task_job_runner.py:266} INFO - Task exited with return code 1
[2025-03-26T11:52:47.553+0000] {taskinstance.py:3901} INFO - 0 downstream tasks scheduled from follow-on schedule check
[2025-03-26T11:52:47.699+0000] {local_task_job_runner.py:245} INFO - ::endgroup::
[2025-03-26T13:18:05.974+0000] {local_task_job_runner.py:123} INFO - ::group::Pre task execution logs
[2025-03-26T13:18:06.051+0000] {taskinstance.py:2614} INFO - Dependencies all met for dep_context=non-requeueable deps ti=<TaskInstance: containers1_dag.php_app1 scheduled__2024-03-02T00:00:00+00:00 [queued]>
[2025-03-26T13:18:06.146+0000] {taskinstance.py:2614} INFO - Dependencies all met for dep_context=requeueable deps ti=<TaskInstance: containers1_dag.php_app1 scheduled__2024-03-02T00:00:00+00:00 [queued]>
[2025-03-26T13:18:06.147+0000] {taskinstance.py:2867} INFO - Starting attempt 1 of 6
[2025-03-26T13:18:06.421+0000] {taskinstance.py:2890} INFO - Executing <Task(DockerOperator): php_app1> on 2024-03-02 00:00:00+00:00
[2025-03-26T13:18:06.487+0000] {standard_task_runner.py:104} INFO - Running: ['***', 'tasks', 'run', 'containers1_dag', 'php_app1', 'scheduled__2024-03-02T00:00:00+00:00', '--job-id', '6', '--raw', '--subdir', 'DAGS_FOLDER/containers1_dag.py', '--cfg-path', '/tmp/tmp0yvop6ag']
[2025-03-26T13:18:06.500+0000] {standard_task_runner.py:105} INFO - Job 6: Subtask php_app1
[2025-03-26T13:18:06.537+0000] {logging_mixin.py:190} WARNING - /home/***/.local/lib/python3.12/site-packages/***/task/task_runner/standard_task_runner.py:70 DeprecationWarning: This process (pid=1241) is multi-threaded, use of fork() may lead to deadlocks in the child.
[2025-03-26T13:18:06.539+0000] {standard_task_runner.py:72} INFO - Started process 1255 to run task
[2025-03-26T13:18:06.995+0000] {task_command.py:467} INFO - Running <TaskInstance: containers1_dag.php_app1 scheduled__2024-03-02T00:00:00+00:00 [running]> on host f731374053d7
[2025-03-26T13:18:07.842+0000] {taskinstance.py:3134} INFO - Exporting env vars: AIRFLOW_CTX_DAG_OWNER='andre' AIRFLOW_CTX_DAG_ID='containers1_dag' AIRFLOW_CTX_TASK_ID='php_app1' AIRFLOW_CTX_EXECUTION_DATE='2024-03-02T00:00:00+00:00' AIRFLOW_CTX_TRY_NUMBER='1' AIRFLOW_CTX_DAG_RUN_ID='scheduled__2024-03-02T00:00:00+00:00'
[2025-03-26T13:18:07.843+0000] {taskinstance.py:732} INFO - ::endgroup::
[2025-03-26T13:18:08.001+0000] {docker.py:157} ERROR - Failed to establish connection to Docker host unix://var/run/docker.sock: Error while fetching server API version: ('Connection aborted.', PermissionError(13, 'Permission denied'))
[2025-03-26T13:18:08.041+0000] {taskinstance.py:3313} ERROR - Task failed with exception
Traceback (most recent call last):
  File "/home/airflow/.local/lib/python3.12/site-packages/airflow/models/taskinstance.py", line 768, in _execute_task
    result = _execute_callable(context=context, **execute_callable_kwargs)
             ^^^^^^^^^^^^^^^^^^^^^^^^^^^^^^^^^^^^^^^^^^^^^^^^^^^^^^^^^^^^^
  File "/home/airflow/.local/lib/python3.12/site-packages/airflow/models/taskinstance.py", line 734, in _execute_callable
    return ExecutionCallableRunner(
           ^^^^^^^^^^^^^^^^^^^^^^^^
  File "/home/airflow/.local/lib/python3.12/site-packages/airflow/utils/operator_helpers.py", line 252, in run
    return self.func(*args, **kwargs)
           ^^^^^^^^^^^^^^^^^^^^^^^^^^
  File "/home/airflow/.local/lib/python3.12/site-packages/airflow/models/baseoperator.py", line 424, in wrapper
    return func(self, *args, **kwargs)
           ^^^^^^^^^^^^^^^^^^^^^^^^^^^
  File "/home/airflow/.local/lib/python3.12/site-packages/airflow/providers/docker/operators/docker.py", line 467, in execute
    if self.force_pull or not self.cli.images(name=self.image):
                              ^^^^^^^^
  File "/home/airflow/.local/lib/python3.12/site-packages/airflow/providers/docker/operators/docker.py", line 341, in cli
    return self.hook.api_client
           ^^^^^^^^^^^^^^^^^^^^
  File "/usr/local/lib/python3.12/functools.py", line 998, in __get__
    val = self.func(instance)
          ^^^^^^^^^^^^^^^^^^^
  File "/home/airflow/.local/lib/python3.12/site-packages/airflow/providers/docker/hooks/docker.py", line 161, in api_client
    raise AirflowException("Failed to establish connection to any given Docker hosts.")
airflow.exceptions.AirflowException: Failed to establish connection to any given Docker hosts.
[2025-03-26T13:18:08.067+0000] {taskinstance.py:1226} INFO - Marking task as UP_FOR_RETRY. dag_id=containers1_dag, task_id=php_app1, run_id=scheduled__2024-03-02T00:00:00+00:00, execution_date=20240302T000000, start_date=20250326T131806, end_date=20250326T131808
[2025-03-26T13:18:08.261+0000] {taskinstance.py:341} INFO - ::group::Post task execution logs
[2025-03-26T13:18:08.262+0000] {standard_task_runner.py:124} ERROR - Failed to execute job 6 for task php_app1 (Failed to establish connection to any given Docker hosts.; 1255)
Traceback (most recent call last):
  File "/home/airflow/.local/lib/python3.12/site-packages/airflow/task/task_runner/standard_task_runner.py", line 117, in _start_by_fork
    ret = args.func(args, dag=self.dag)
          ^^^^^^^^^^^^^^^^^^^^^^^^^^^^^
  File "/home/airflow/.local/lib/python3.12/site-packages/airflow/cli/cli_config.py", line 49, in command
    return func(*args, **kwargs)
           ^^^^^^^^^^^^^^^^^^^^^
  File "/home/airflow/.local/lib/python3.12/site-packages/airflow/utils/cli.py", line 116, in wrapper
    return f(*args, **kwargs)
           ^^^^^^^^^^^^^^^^^^
  File "/home/airflow/.local/lib/python3.12/site-packages/airflow/cli/commands/task_command.py", line 483, in task_run
    task_return_code = _run_task_by_selected_method(args, _dag, ti)
                       ^^^^^^^^^^^^^^^^^^^^^^^^^^^^^^^^^^^^^^^^^^^^
  File "/home/airflow/.local/lib/python3.12/site-packages/airflow/cli/commands/task_command.py", line 256, in _run_task_by_selected_method
    return _run_raw_task(args, ti)
           ^^^^^^^^^^^^^^^^^^^^^^^
  File "/home/airflow/.local/lib/python3.12/site-packages/airflow/cli/commands/task_command.py", line 341, in _run_raw_task
    return ti._run_raw_task(
           ^^^^^^^^^^^^^^^^^
  File "/home/airflow/.local/lib/python3.12/site-packages/airflow/utils/session.py", line 97, in wrapper
    return func(*args, session=session, **kwargs)
           ^^^^^^^^^^^^^^^^^^^^^^^^^^^^^^^^^^^^^^
  File "/home/airflow/.local/lib/python3.12/site-packages/airflow/models/taskinstance.py", line 3006, in _run_raw_task
    return _run_raw_task(
           ^^^^^^^^^^^^^^
  File "/home/airflow/.local/lib/python3.12/site-packages/airflow/models/taskinstance.py", line 274, in _run_raw_task
    TaskInstance._execute_task_with_callbacks(
  File "/home/airflow/.local/lib/python3.12/site-packages/airflow/models/taskinstance.py", line 3161, in _execute_task_with_callbacks
    result = self._execute_task(context, task_orig)
             ^^^^^^^^^^^^^^^^^^^^^^^^^^^^^^^^^^^^^^
  File "/home/airflow/.local/lib/python3.12/site-packages/airflow/models/taskinstance.py", line 3185, in _execute_task
    return _execute_task(self, context, task_orig)
           ^^^^^^^^^^^^^^^^^^^^^^^^^^^^^^^^^^^^^^^
  File "/home/airflow/.local/lib/python3.12/site-packages/airflow/models/taskinstance.py", line 768, in _execute_task
    result = _execute_callable(context=context, **execute_callable_kwargs)
             ^^^^^^^^^^^^^^^^^^^^^^^^^^^^^^^^^^^^^^^^^^^^^^^^^^^^^^^^^^^^^
  File "/home/airflow/.local/lib/python3.12/site-packages/airflow/models/taskinstance.py", line 734, in _execute_callable
    return ExecutionCallableRunner(
           ^^^^^^^^^^^^^^^^^^^^^^^^
  File "/home/airflow/.local/lib/python3.12/site-packages/airflow/utils/operator_helpers.py", line 252, in run
    return self.func(*args, **kwargs)
           ^^^^^^^^^^^^^^^^^^^^^^^^^^
  File "/home/airflow/.local/lib/python3.12/site-packages/airflow/models/baseoperator.py", line 424, in wrapper
    return func(self, *args, **kwargs)
           ^^^^^^^^^^^^^^^^^^^^^^^^^^^
  File "/home/airflow/.local/lib/python3.12/site-packages/airflow/providers/docker/operators/docker.py", line 467, in execute
    if self.force_pull or not self.cli.images(name=self.image):
                              ^^^^^^^^
  File "/home/airflow/.local/lib/python3.12/site-packages/airflow/providers/docker/operators/docker.py", line 341, in cli
    return self.hook.api_client
           ^^^^^^^^^^^^^^^^^^^^
  File "/usr/local/lib/python3.12/functools.py", line 998, in __get__
    val = self.func(instance)
          ^^^^^^^^^^^^^^^^^^^
  File "/home/airflow/.local/lib/python3.12/site-packages/airflow/providers/docker/hooks/docker.py", line 161, in api_client
    raise AirflowException("Failed to establish connection to any given Docker hosts.")
airflow.exceptions.AirflowException: Failed to establish connection to any given Docker hosts.
[2025-03-26T13:18:08.302+0000] {local_task_job_runner.py:266} INFO - Task exited with return code 1
[2025-03-26T13:18:08.655+0000] {taskinstance.py:3901} INFO - 0 downstream tasks scheduled from follow-on schedule check
[2025-03-26T13:18:08.703+0000] {local_task_job_runner.py:245} INFO - ::endgroup::
[2025-03-26T13:38:18.780+0000] {local_task_job_runner.py:123} INFO - ::group::Pre task execution logs
[2025-03-26T13:38:18.930+0000] {taskinstance.py:2614} INFO - Dependencies all met for dep_context=non-requeueable deps ti=<TaskInstance: containers1_dag.php_app1 scheduled__2024-03-02T00:00:00+00:00 [queued]>
[2025-03-26T13:38:18.995+0000] {taskinstance.py:2614} INFO - Dependencies all met for dep_context=requeueable deps ti=<TaskInstance: containers1_dag.php_app1 scheduled__2024-03-02T00:00:00+00:00 [queued]>
[2025-03-26T13:38:18.997+0000] {taskinstance.py:2867} INFO - Starting attempt 1 of 6
[2025-03-26T13:38:19.098+0000] {taskinstance.py:2890} INFO - Executing <Task(DockerOperator): php_app1> on 2024-03-02 00:00:00+00:00
[2025-03-26T13:38:19.145+0000] {logging_mixin.py:190} WARNING - /home/***/.local/lib/python3.12/site-packages/***/task/task_runner/standard_task_runner.py:70 DeprecationWarning: This process (pid=247) is multi-threaded, use of fork() may lead to deadlocks in the child.
[2025-03-26T13:38:19.149+0000] {standard_task_runner.py:72} INFO - Started process 259 to run task
[2025-03-26T13:38:19.139+0000] {standard_task_runner.py:104} INFO - Running: ['***', 'tasks', 'run', 'containers1_dag', 'php_app1', 'scheduled__2024-03-02T00:00:00+00:00', '--job-id', '5', '--raw', '--subdir', 'DAGS_FOLDER/containers1_dag.py', '--cfg-path', '/tmp/tmpbih2sr2q']
[2025-03-26T13:38:19.150+0000] {standard_task_runner.py:105} INFO - Job 5: Subtask php_app1
[2025-03-26T13:38:19.520+0000] {task_command.py:467} INFO - Running <TaskInstance: containers1_dag.php_app1 scheduled__2024-03-02T00:00:00+00:00 [running]> on host 3d581a580455
[2025-03-26T13:38:19.971+0000] {taskinstance.py:3134} INFO - Exporting env vars: AIRFLOW_CTX_DAG_OWNER='andre' AIRFLOW_CTX_DAG_ID='containers1_dag' AIRFLOW_CTX_TASK_ID='php_app1' AIRFLOW_CTX_EXECUTION_DATE='2024-03-02T00:00:00+00:00' AIRFLOW_CTX_TRY_NUMBER='1' AIRFLOW_CTX_DAG_RUN_ID='scheduled__2024-03-02T00:00:00+00:00'
[2025-03-26T13:38:20.003+0000] {taskinstance.py:732} INFO - ::endgroup::
[2025-03-26T13:38:20.235+0000] {docker.py:345} INFO - Starting docker container from image php-app1
[2025-03-26T13:38:20.344+0000] {docker.py:353} WARNING - Using remote engine or docker-in-docker and mounting temporary volume from host is not supported. Falling back to `mount_tmp_dir=False` mode. You can set `mount_tmp_dir` parameter to False to disable mounting and remove the warning
[2025-03-26T13:38:22.420+0000] {docker.py:69} INFO - array(7) {
[2025-03-26T13:38:22.472+0000] {docker.py:69} INFO -   [0]=>
[2025-03-26T13:38:22.474+0000] {docker.py:69} INFO -   object(stdClass)#2 (3) {
[2025-03-26T13:38:22.494+0000] {docker.py:69} INFO -     ["contador"]=>
[2025-03-26T13:38:22.494+0000] {docker.py:69} INFO -     int(0)
[2025-03-26T13:38:22.495+0000] {docker.py:69} INFO -     ["container"]=>
[2025-03-26T13:38:22.504+0000] {docker.py:69} INFO -     string(8) "php-app1"
[2025-03-26T13:38:22.505+0000] {docker.py:69} INFO -     ["timestamp"]=>
[2025-03-26T13:38:22.508+0000] {docker.py:69} INFO -     int(1742852307)
[2025-03-26T13:38:22.509+0000] {docker.py:69} INFO -   }
[2025-03-26T13:38:22.525+0000] {docker.py:69} INFO -   [1]=>
[2025-03-26T13:38:22.526+0000] {docker.py:69} INFO -   object(stdClass)#3 (3) {
[2025-03-26T13:38:22.526+0000] {docker.py:69} INFO -     ["contador"]=>
[2025-03-26T13:38:22.527+0000] {docker.py:69} INFO -     int(1)
[2025-03-26T13:38:22.559+0000] {docker.py:69} INFO -     ["container"]=>
[2025-03-26T13:38:22.560+0000] {docker.py:69} INFO -     string(8) "php-app2"
[2025-03-26T13:38:22.564+0000] {docker.py:69} INFO -     ["timestamp"]=>
[2025-03-26T13:38:22.565+0000] {docker.py:69} INFO -     int(1742852309)
[2025-03-26T13:38:22.565+0000] {docker.py:69} INFO -   }
[2025-03-26T13:38:22.565+0000] {docker.py:69} INFO -   [2]=>
[2025-03-26T13:38:22.566+0000] {docker.py:69} INFO -   object(stdClass)#4 (3) {
[2025-03-26T13:38:22.589+0000] {docker.py:69} INFO -     ["contador"]=>
[2025-03-26T13:38:22.590+0000] {docker.py:69} INFO -     int(1)
[2025-03-26T13:38:22.590+0000] {docker.py:69} INFO -     ["container"]=>
[2025-03-26T13:38:22.591+0000] {docker.py:69} INFO -     string(8) "php-app1"
[2025-03-26T13:38:22.591+0000] {docker.py:69} INFO -     ["timestamp"]=>
[2025-03-26T13:38:22.592+0000] {docker.py:69} INFO -     int(1742852311)
[2025-03-26T13:38:22.623+0000] {docker.py:69} INFO -   }
[2025-03-26T13:38:22.624+0000] {docker.py:69} INFO -   [3]=>
[2025-03-26T13:38:22.624+0000] {docker.py:69} INFO -   object(stdClass)#5 (3) {
[2025-03-26T13:38:22.625+0000] {docker.py:69} INFO -     ["contador"]=>
[2025-03-26T13:38:22.635+0000] {docker.py:69} INFO -     int(1)
[2025-03-26T13:38:22.647+0000] {docker.py:69} INFO -     ["container
[2025-03-26T13:38:22.648+0000] {docker.py:69} INFO - "]=>
[2025-03-26T13:38:22.658+0000] {docker.py:69} INFO -     string(8) "php-app2"
[2025-03-26T13:38:22.658+0000] {docker.py:69} INFO -     ["timestamp"]=>
[2025-03-26T13:38:22.659+0000] {docker.py:69} INFO -     int(1742852314)
[2025-03-26T13:38:22.669+0000] {docker.py:69} INFO -   }
[2025-03-26T13:38:22.670+0000] {docker.py:69} INFO -   [4]=>
[2025-03-26T13:38:22.670+0000] {docker.py:69} INFO -   object(stdClass)#6 (3) {
[2025-03-26T13:38:22.671+0000] {docker.py:69} INFO -     ["contador"]=>
[2025-03-26T13:38:22.671+0000] {docker.py:69} INFO -     int(1)
[2025-03-26T13:38:22.671+0000] {docker.py:69} INFO -     ["container"]=>
[2025-03-26T13:38:22.682+0000] {docker.py:69} INFO -     string(8) "php-app2"
[2025-03-26T13:38:22.683+0000] {docker.py:69} INFO -     ["timestamp"]=>
[2025-03-26T13:38:22.683+0000] {docker.py:69} INFO -     int(1742996301)
[2025-03-26T13:38:22.683+0000] {docker.py:69} INFO -   }
[2025-03-26T13:38:22.684+0000] {docker.py:69} INFO -   [5]=>
[2025-03-26T13:38:22.684+0000] {docker.py:69} INFO -   object(stdClass)#7 (3) {
[2025-03-26T13:38:22.685+0000] {docker.py:69} INFO -     ["contador"]=>
[2025-03-26T13:38:22.694+0000] {docker.py:69} INFO -     int(1)
[2025-03-26T13:38:22.695+0000] {docker.py:69} INFO -     ["container"]=>
[2025-03-26T13:38:22.695+0000] {docker.py:69} INFO -     string(8) "php-app1"
[2025-03-26T13:38:22.695+0000] {docker.py:69} INFO -     ["timestamp"]=>
[2025-03-26T13:38:22.696+0000] {docker.py:69} INFO -     int(1742996302)
[2025-03-26T13:38:22.696+0000] {docker.py:69} INFO -   }
[2025-03-26T13:38:22.697+0000] {docker.py:69} INFO -   [6]=>
[2025-03-26T13:38:22.699+0000] {docker.py:69} INFO -   array(3) {
[2025-03-26T13:38:22.700+0000] {docker.py:69} INFO -     ["contador"]=>
[2025-03-26T13:38:22.700+0000] {docker.py:69} INFO -     int(1)
[2025-03-26T13:38:22.701+0000] {docker.py:69} INFO -     ["container"]=>
[2025-03-26T13:38:22.701+0000] {docker.py:69} INFO -     string(8) "php-app1"
[2025-03-26T13:38:22.701+0000] {docker.py:69} INFO -     ["timestamp"]=>
[2025-03-26T13:38:22.702+0000] {docker.py:69} INFO -     int(1742996302)
[2025-03-26T13:38:22.705+0000] {docker.py:69} INFO -   }
[2025-03-26T13:38:22.705+0000] {docker.py:69} INFO - }
[2025-03-26T13:38:23.979+0000] {taskinstance.py:341} INFO - ::group::Post task execution logs
[2025-03-26T13:38:23.980+0000] {taskinstance.py:353} INFO - Marking task as SUCCESS. dag_id=containers1_dag, task_id=php_app1, run_id=scheduled__2024-03-02T00:00:00+00:00, execution_date=20240302T000000, start_date=20250326T133818, end_date=20250326T133823
[2025-03-26T13:38:24.543+0000] {local_task_job_runner.py:266} INFO - Task exited with return code 0
[2025-03-26T13:38:24.951+0000] {taskinstance.py:3901} INFO - 0 downstream tasks scheduled from follow-on schedule check
[2025-03-26T13:38:25.218+0000] {local_task_job_runner.py:245} INFO - ::endgroup::
