[2025-03-24T22:19:24.720+0000] {local_task_job_runner.py:123} INFO - ::group::Pre task execution logs
[2025-03-24T22:19:24.773+0000] {taskinstance.py:2614} INFO - Dependencies all met for dep_context=non-requeueable deps ti=<TaskInstance: containers1_dag.php_app2 scheduled__2024-03-04T00:00:00+00:00 [queued]>
[2025-03-24T22:19:24.798+0000] {taskinstance.py:2614} INFO - Dependencies all met for dep_context=requeueable deps ti=<TaskInstance: containers1_dag.php_app2 scheduled__2024-03-04T00:00:00+00:00 [queued]>
[2025-03-24T22:19:24.799+0000] {taskinstance.py:2867} INFO - Starting attempt 1 of 6
[2025-03-24T22:19:24.869+0000] {taskinstance.py:2890} INFO - Executing <Task(BashOperator): php_app2> on 2024-03-04 00:00:00+00:00
[2025-03-24T22:19:24.903+0000] {logging_mixin.py:190} WARNING - /home/***/.local/lib/python3.12/site-packages/***/task/task_runner/standard_task_runner.py:70 DeprecationWarning: This process (pid=4948) is multi-threaded, use of fork() may lead to deadlocks in the child.
[2025-03-24T22:19:24.906+0000] {standard_task_runner.py:72} INFO - Started process 4969 to run task
[2025-03-24T22:19:24.909+0000] {standard_task_runner.py:104} INFO - Running: ['***', 'tasks', 'run', 'containers1_dag', 'php_app2', 'scheduled__2024-03-04T00:00:00+00:00', '--job-id', '133', '--raw', '--subdir', 'DAGS_FOLDER/containers1_dag.py', '--cfg-path', '/tmp/tmp34pa5jn1']
[2025-03-24T22:19:24.912+0000] {standard_task_runner.py:105} INFO - Job 133: Subtask php_app2
[2025-03-24T22:19:25.405+0000] {task_command.py:467} INFO - Running <TaskInstance: containers1_dag.php_app2 scheduled__2024-03-04T00:00:00+00:00 [running]> on host b9050090f7f5
[2025-03-24T22:19:25.977+0000] {taskinstance.py:3134} INFO - Exporting env vars: AIRFLOW_CTX_DAG_OWNER='andreeppinghaus' AIRFLOW_CTX_DAG_ID='containers1_dag' AIRFLOW_CTX_TASK_ID='php_app2' AIRFLOW_CTX_EXECUTION_DATE='2024-03-04T00:00:00+00:00' AIRFLOW_CTX_TRY_NUMBER='1' AIRFLOW_CTX_DAG_RUN_ID='scheduled__2024-03-04T00:00:00+00:00'
[2025-03-24T22:19:25.978+0000] {taskinstance.py:732} INFO - ::endgroup::
[2025-03-24T22:19:26.049+0000] {subprocess.py:78} INFO - Tmp dir root location: /tmp
[2025-03-24T22:19:26.050+0000] {subprocess.py:88} INFO - Running command: ['/usr/bin/bash', '-c', 'sudo docker run -v $(pwd)/../in:/usr/src/app/in -v $(pwd):/usr/src/app php-app2']
[2025-03-24T22:19:26.145+0000] {subprocess.py:99} INFO - Output:
[2025-03-24T22:19:26.282+0000] {subprocess.py:106} INFO - sudo: a terminal is required to read the password; either use the -S option to read from standard input or configure an askpass helper
[2025-03-24T22:19:26.304+0000] {subprocess.py:106} INFO - sudo: a password is required
[2025-03-24T22:19:26.305+0000] {subprocess.py:110} INFO - Command exited with return code 1
[2025-03-24T22:19:26.509+0000] {taskinstance.py:3313} ERROR - Task failed with exception
Traceback (most recent call last):
  File "/home/airflow/.local/lib/python3.12/site-packages/airflow/models/taskinstance.py", line 768, in _execute_task
    result = _execute_callable(context=context, **execute_callable_kwargs)
             ^^^^^^^^^^^^^^^^^^^^^^^^^^^^^^^^^^^^^^^^^^^^^^^^^^^^^^^^^^^^^
  File "/home/airflow/.local/lib/python3.12/site-packages/airflow/models/taskinstance.py", line 734, in _execute_callable
    return ExecutionCallableRunner(
           ^^^^^^^^^^^^^^^^^^^^^^^^
  File "/home/airflow/.local/lib/python3.12/site-packages/airflow/utils/operator_helpers.py", line 252, in run
    return self.func(*args, **kwargs)
           ^^^^^^^^^^^^^^^^^^^^^^^^^^
  File "/home/airflow/.local/lib/python3.12/site-packages/airflow/models/baseoperator.py", line 424, in wrapper
    return func(self, *args, **kwargs)
           ^^^^^^^^^^^^^^^^^^^^^^^^^^^
  File "/home/airflow/.local/lib/python3.12/site-packages/airflow/operators/bash.py", line 276, in execute
    raise AirflowException(
airflow.exceptions.AirflowException: Bash command failed. The command returned a non-zero exit code 1.
[2025-03-24T22:19:26.652+0000] {taskinstance.py:1226} INFO - Marking task as UP_FOR_RETRY. dag_id=containers1_dag, task_id=php_app2, run_id=scheduled__2024-03-04T00:00:00+00:00, execution_date=20240304T000000, start_date=20250324T221924, end_date=20250324T221926
[2025-03-24T22:19:27.356+0000] {taskinstance.py:341} INFO - ::group::Post task execution logs
[2025-03-24T22:19:27.359+0000] {standard_task_runner.py:124} ERROR - Failed to execute job 133 for task php_app2 (Bash command failed. The command returned a non-zero exit code 1.; 4969)
Traceback (most recent call last):
  File "/home/airflow/.local/lib/python3.12/site-packages/airflow/task/task_runner/standard_task_runner.py", line 117, in _start_by_fork
    ret = args.func(args, dag=self.dag)
          ^^^^^^^^^^^^^^^^^^^^^^^^^^^^^
  File "/home/airflow/.local/lib/python3.12/site-packages/airflow/cli/cli_config.py", line 49, in command
    return func(*args, **kwargs)
           ^^^^^^^^^^^^^^^^^^^^^
  File "/home/airflow/.local/lib/python3.12/site-packages/airflow/utils/cli.py", line 116, in wrapper
    return f(*args, **kwargs)
           ^^^^^^^^^^^^^^^^^^
  File "/home/airflow/.local/lib/python3.12/site-packages/airflow/cli/commands/task_command.py", line 483, in task_run
    task_return_code = _run_task_by_selected_method(args, _dag, ti)
                       ^^^^^^^^^^^^^^^^^^^^^^^^^^^^^^^^^^^^^^^^^^^^
  File "/home/airflow/.local/lib/python3.12/site-packages/airflow/cli/commands/task_command.py", line 256, in _run_task_by_selected_method
    return _run_raw_task(args, ti)
           ^^^^^^^^^^^^^^^^^^^^^^^
  File "/home/airflow/.local/lib/python3.12/site-packages/airflow/cli/commands/task_command.py", line 341, in _run_raw_task
    return ti._run_raw_task(
           ^^^^^^^^^^^^^^^^^
  File "/home/airflow/.local/lib/python3.12/site-packages/airflow/utils/session.py", line 97, in wrapper
    return func(*args, session=session, **kwargs)
           ^^^^^^^^^^^^^^^^^^^^^^^^^^^^^^^^^^^^^^
  File "/home/airflow/.local/lib/python3.12/site-packages/airflow/models/taskinstance.py", line 3006, in _run_raw_task
    return _run_raw_task(
           ^^^^^^^^^^^^^^
  File "/home/airflow/.local/lib/python3.12/site-packages/airflow/models/taskinstance.py", line 274, in _run_raw_task
    TaskInstance._execute_task_with_callbacks(
  File "/home/airflow/.local/lib/python3.12/site-packages/airflow/models/taskinstance.py", line 3161, in _execute_task_with_callbacks
    result = self._execute_task(context, task_orig)
             ^^^^^^^^^^^^^^^^^^^^^^^^^^^^^^^^^^^^^^
  File "/home/airflow/.local/lib/python3.12/site-packages/airflow/models/taskinstance.py", line 3185, in _execute_task
    return _execute_task(self, context, task_orig)
           ^^^^^^^^^^^^^^^^^^^^^^^^^^^^^^^^^^^^^^^
  File "/home/airflow/.local/lib/python3.12/site-packages/airflow/models/taskinstance.py", line 768, in _execute_task
    result = _execute_callable(context=context, **execute_callable_kwargs)
             ^^^^^^^^^^^^^^^^^^^^^^^^^^^^^^^^^^^^^^^^^^^^^^^^^^^^^^^^^^^^^
  File "/home/airflow/.local/lib/python3.12/site-packages/airflow/models/taskinstance.py", line 734, in _execute_callable
    return ExecutionCallableRunner(
           ^^^^^^^^^^^^^^^^^^^^^^^^
  File "/home/airflow/.local/lib/python3.12/site-packages/airflow/utils/operator_helpers.py", line 252, in run
    return self.func(*args, **kwargs)
           ^^^^^^^^^^^^^^^^^^^^^^^^^^
  File "/home/airflow/.local/lib/python3.12/site-packages/airflow/models/baseoperator.py", line 424, in wrapper
    return func(self, *args, **kwargs)
           ^^^^^^^^^^^^^^^^^^^^^^^^^^^
  File "/home/airflow/.local/lib/python3.12/site-packages/airflow/operators/bash.py", line 276, in execute
    raise AirflowException(
airflow.exceptions.AirflowException: Bash command failed. The command returned a non-zero exit code 1.
[2025-03-24T22:19:27.519+0000] {local_task_job_runner.py:266} INFO - Task exited with return code 1
[2025-03-24T22:19:27.814+0000] {taskinstance.py:3901} INFO - 0 downstream tasks scheduled from follow-on schedule check
[2025-03-24T22:19:27.837+0000] {local_task_job_runner.py:245} INFO - ::endgroup::
[2025-03-24T22:24:16.558+0000] {local_task_job_runner.py:123} INFO - ::group::Pre task execution logs
[2025-03-24T22:24:16.735+0000] {taskinstance.py:2614} INFO - Dependencies all met for dep_context=non-requeueable deps ti=<TaskInstance: containers1_dag.php_app2 scheduled__2024-03-04T00:00:00+00:00 [queued]>
[2025-03-24T22:24:16.755+0000] {taskinstance.py:2614} INFO - Dependencies all met for dep_context=requeueable deps ti=<TaskInstance: containers1_dag.php_app2 scheduled__2024-03-04T00:00:00+00:00 [queued]>
[2025-03-24T22:24:16.757+0000] {taskinstance.py:2867} INFO - Starting attempt 1 of 6
[2025-03-24T22:24:16.853+0000] {taskinstance.py:2890} INFO - Executing <Task(BashOperator): php_app2> on 2024-03-04 00:00:00+00:00
[2025-03-24T22:24:16.878+0000] {logging_mixin.py:190} WARNING - /home/***/.local/lib/python3.12/site-packages/***/task/task_runner/standard_task_runner.py:70 DeprecationWarning: This process (pid=5222) is multi-threaded, use of fork() may lead to deadlocks in the child.
[2025-03-24T22:24:16.880+0000] {standard_task_runner.py:72} INFO - Started process 5238 to run task
[2025-03-24T22:24:16.913+0000] {standard_task_runner.py:104} INFO - Running: ['***', 'tasks', 'run', 'containers1_dag', 'php_app2', 'scheduled__2024-03-04T00:00:00+00:00', '--job-id', '149', '--raw', '--subdir', 'DAGS_FOLDER/containers1_dag.py', '--cfg-path', '/tmp/tmp50keczek']
[2025-03-24T22:24:16.946+0000] {standard_task_runner.py:105} INFO - Job 149: Subtask php_app2
[2025-03-24T22:24:17.332+0000] {task_command.py:467} INFO - Running <TaskInstance: containers1_dag.php_app2 scheduled__2024-03-04T00:00:00+00:00 [running]> on host b9050090f7f5
[2025-03-24T22:24:18.129+0000] {taskinstance.py:3134} INFO - Exporting env vars: AIRFLOW_CTX_DAG_OWNER='andre' AIRFLOW_CTX_DAG_ID='containers1_dag' AIRFLOW_CTX_TASK_ID='php_app2' AIRFLOW_CTX_EXECUTION_DATE='2024-03-04T00:00:00+00:00' AIRFLOW_CTX_TRY_NUMBER='1' AIRFLOW_CTX_DAG_RUN_ID='scheduled__2024-03-04T00:00:00+00:00'
[2025-03-24T22:24:18.131+0000] {taskinstance.py:732} INFO - ::endgroup::
[2025-03-24T22:24:18.216+0000] {subprocess.py:78} INFO - Tmp dir root location: /tmp
[2025-03-24T22:24:18.221+0000] {subprocess.py:88} INFO - Running command: ['/usr/bin/bash', '-c', 'sudo docker run -v $(pwd)/../in:/usr/src/app/in -v $(pwd):/usr/src/app php-app2']
[2025-03-24T22:24:18.350+0000] {subprocess.py:99} INFO - Output:
[2025-03-24T22:24:18.453+0000] {subprocess.py:106} INFO - sudo: a terminal is required to read the password; either use the -S option to read from standard input or configure an askpass helper
[2025-03-24T22:24:18.454+0000] {subprocess.py:106} INFO - sudo: a password is required
[2025-03-24T22:24:18.456+0000] {subprocess.py:110} INFO - Command exited with return code 1
[2025-03-24T22:24:18.660+0000] {taskinstance.py:3313} ERROR - Task failed with exception
Traceback (most recent call last):
  File "/home/airflow/.local/lib/python3.12/site-packages/airflow/models/taskinstance.py", line 768, in _execute_task
    result = _execute_callable(context=context, **execute_callable_kwargs)
             ^^^^^^^^^^^^^^^^^^^^^^^^^^^^^^^^^^^^^^^^^^^^^^^^^^^^^^^^^^^^^
  File "/home/airflow/.local/lib/python3.12/site-packages/airflow/models/taskinstance.py", line 734, in _execute_callable
    return ExecutionCallableRunner(
           ^^^^^^^^^^^^^^^^^^^^^^^^
  File "/home/airflow/.local/lib/python3.12/site-packages/airflow/utils/operator_helpers.py", line 252, in run
    return self.func(*args, **kwargs)
           ^^^^^^^^^^^^^^^^^^^^^^^^^^
  File "/home/airflow/.local/lib/python3.12/site-packages/airflow/models/baseoperator.py", line 424, in wrapper
    return func(self, *args, **kwargs)
           ^^^^^^^^^^^^^^^^^^^^^^^^^^^
  File "/home/airflow/.local/lib/python3.12/site-packages/airflow/operators/bash.py", line 276, in execute
    raise AirflowException(
airflow.exceptions.AirflowException: Bash command failed. The command returned a non-zero exit code 1.
[2025-03-24T22:24:18.705+0000] {taskinstance.py:1226} INFO - Marking task as UP_FOR_RETRY. dag_id=containers1_dag, task_id=php_app2, run_id=scheduled__2024-03-04T00:00:00+00:00, execution_date=20240304T000000, start_date=20250324T222416, end_date=20250324T222418
[2025-03-24T22:24:19.043+0000] {taskinstance.py:341} INFO - ::group::Post task execution logs
[2025-03-24T22:24:19.054+0000] {standard_task_runner.py:124} ERROR - Failed to execute job 149 for task php_app2 (Bash command failed. The command returned a non-zero exit code 1.; 5238)
Traceback (most recent call last):
  File "/home/airflow/.local/lib/python3.12/site-packages/airflow/task/task_runner/standard_task_runner.py", line 117, in _start_by_fork
    ret = args.func(args, dag=self.dag)
          ^^^^^^^^^^^^^^^^^^^^^^^^^^^^^
  File "/home/airflow/.local/lib/python3.12/site-packages/airflow/cli/cli_config.py", line 49, in command
    return func(*args, **kwargs)
           ^^^^^^^^^^^^^^^^^^^^^
  File "/home/airflow/.local/lib/python3.12/site-packages/airflow/utils/cli.py", line 116, in wrapper
    return f(*args, **kwargs)
           ^^^^^^^^^^^^^^^^^^
  File "/home/airflow/.local/lib/python3.12/site-packages/airflow/cli/commands/task_command.py", line 483, in task_run
    task_return_code = _run_task_by_selected_method(args, _dag, ti)
                       ^^^^^^^^^^^^^^^^^^^^^^^^^^^^^^^^^^^^^^^^^^^^
  File "/home/airflow/.local/lib/python3.12/site-packages/airflow/cli/commands/task_command.py", line 256, in _run_task_by_selected_method
    return _run_raw_task(args, ti)
           ^^^^^^^^^^^^^^^^^^^^^^^
  File "/home/airflow/.local/lib/python3.12/site-packages/airflow/cli/commands/task_command.py", line 341, in _run_raw_task
    return ti._run_raw_task(
           ^^^^^^^^^^^^^^^^^
  File "/home/airflow/.local/lib/python3.12/site-packages/airflow/utils/session.py", line 97, in wrapper
    return func(*args, session=session, **kwargs)
           ^^^^^^^^^^^^^^^^^^^^^^^^^^^^^^^^^^^^^^
  File "/home/airflow/.local/lib/python3.12/site-packages/airflow/models/taskinstance.py", line 3006, in _run_raw_task
    return _run_raw_task(
           ^^^^^^^^^^^^^^
  File "/home/airflow/.local/lib/python3.12/site-packages/airflow/models/taskinstance.py", line 274, in _run_raw_task
    TaskInstance._execute_task_with_callbacks(
  File "/home/airflow/.local/lib/python3.12/site-packages/airflow/models/taskinstance.py", line 3161, in _execute_task_with_callbacks
    result = self._execute_task(context, task_orig)
             ^^^^^^^^^^^^^^^^^^^^^^^^^^^^^^^^^^^^^^
  File "/home/airflow/.local/lib/python3.12/site-packages/airflow/models/taskinstance.py", line 3185, in _execute_task
    return _execute_task(self, context, task_orig)
           ^^^^^^^^^^^^^^^^^^^^^^^^^^^^^^^^^^^^^^^
  File "/home/airflow/.local/lib/python3.12/site-packages/airflow/models/taskinstance.py", line 768, in _execute_task
    result = _execute_callable(context=context, **execute_callable_kwargs)
             ^^^^^^^^^^^^^^^^^^^^^^^^^^^^^^^^^^^^^^^^^^^^^^^^^^^^^^^^^^^^^
  File "/home/airflow/.local/lib/python3.12/site-packages/airflow/models/taskinstance.py", line 734, in _execute_callable
    return ExecutionCallableRunner(
           ^^^^^^^^^^^^^^^^^^^^^^^^
  File "/home/airflow/.local/lib/python3.12/site-packages/airflow/utils/operator_helpers.py", line 252, in run
    return self.func(*args, **kwargs)
           ^^^^^^^^^^^^^^^^^^^^^^^^^^
  File "/home/airflow/.local/lib/python3.12/site-packages/airflow/models/baseoperator.py", line 424, in wrapper
    return func(self, *args, **kwargs)
           ^^^^^^^^^^^^^^^^^^^^^^^^^^^
  File "/home/airflow/.local/lib/python3.12/site-packages/airflow/operators/bash.py", line 276, in execute
    raise AirflowException(
airflow.exceptions.AirflowException: Bash command failed. The command returned a non-zero exit code 1.
[2025-03-24T22:24:19.154+0000] {local_task_job_runner.py:266} INFO - Task exited with return code 1
[2025-03-24T22:24:19.466+0000] {taskinstance.py:3901} INFO - 0 downstream tasks scheduled from follow-on schedule check
[2025-03-24T22:24:19.500+0000] {local_task_job_runner.py:245} INFO - ::endgroup::
[2025-03-24T22:27:20.504+0000] {local_task_job_runner.py:123} INFO - ::group::Pre task execution logs
[2025-03-24T22:27:20.567+0000] {taskinstance.py:2614} INFO - Dependencies all met for dep_context=non-requeueable deps ti=<TaskInstance: containers1_dag.php_app2 scheduled__2024-03-04T00:00:00+00:00 [queued]>
[2025-03-24T22:27:20.590+0000] {taskinstance.py:2614} INFO - Dependencies all met for dep_context=requeueable deps ti=<TaskInstance: containers1_dag.php_app2 scheduled__2024-03-04T00:00:00+00:00 [queued]>
[2025-03-24T22:27:20.593+0000] {taskinstance.py:2867} INFO - Starting attempt 1 of 6
[2025-03-24T22:27:20.638+0000] {taskinstance.py:2890} INFO - Executing <Task(BashOperator): php_app2> on 2024-03-04 00:00:00+00:00
[2025-03-24T22:27:20.665+0000] {logging_mixin.py:190} WARNING - /home/***/.local/lib/python3.12/site-packages/***/task/task_runner/standard_task_runner.py:70 DeprecationWarning: This process (pid=5530) is multi-threaded, use of fork() may lead to deadlocks in the child.
[2025-03-24T22:27:20.675+0000] {standard_task_runner.py:72} INFO - Started process 5544 to run task
[2025-03-24T22:27:20.667+0000] {standard_task_runner.py:104} INFO - Running: ['***', 'tasks', 'run', 'containers1_dag', 'php_app2', 'scheduled__2024-03-04T00:00:00+00:00', '--job-id', '181', '--raw', '--subdir', 'DAGS_FOLDER/containers1_dag.py', '--cfg-path', '/tmp/tmp4y85ng8i']
[2025-03-24T22:27:20.679+0000] {standard_task_runner.py:105} INFO - Job 181: Subtask php_app2
[2025-03-24T22:27:21.147+0000] {task_command.py:467} INFO - Running <TaskInstance: containers1_dag.php_app2 scheduled__2024-03-04T00:00:00+00:00 [running]> on host b9050090f7f5
[2025-03-24T22:27:22.165+0000] {taskinstance.py:3134} INFO - Exporting env vars: AIRFLOW_CTX_DAG_OWNER='andre' AIRFLOW_CTX_DAG_ID='containers1_dag' AIRFLOW_CTX_TASK_ID='php_app2' AIRFLOW_CTX_EXECUTION_DATE='2024-03-04T00:00:00+00:00' AIRFLOW_CTX_TRY_NUMBER='1' AIRFLOW_CTX_DAG_RUN_ID='scheduled__2024-03-04T00:00:00+00:00'
[2025-03-24T22:27:22.184+0000] {taskinstance.py:732} INFO - ::endgroup::
[2025-03-24T22:27:22.572+0000] {subprocess.py:78} INFO - Tmp dir root location: /tmp
[2025-03-24T22:27:22.580+0000] {subprocess.py:88} INFO - Running command: ['/usr/bin/bash', '-c', 'docker run -v $(pwd)/../in:/usr/src/app/in -v $(pwd):/usr/src/app php-app2']
[2025-03-24T22:27:22.680+0000] {subprocess.py:99} INFO - Output:
[2025-03-24T22:27:23.190+0000] {subprocess.py:106} INFO - docker: Cannot connect to the Docker daemon at unix:///var/run/docker.sock. Is the docker daemon running?.
[2025-03-24T22:27:23.193+0000] {subprocess.py:106} INFO - See 'docker run --help'.
[2025-03-24T22:27:23.194+0000] {subprocess.py:110} INFO - Command exited with return code 125
[2025-03-24T22:27:23.291+0000] {taskinstance.py:3313} ERROR - Task failed with exception
Traceback (most recent call last):
  File "/home/airflow/.local/lib/python3.12/site-packages/airflow/models/taskinstance.py", line 768, in _execute_task
    result = _execute_callable(context=context, **execute_callable_kwargs)
             ^^^^^^^^^^^^^^^^^^^^^^^^^^^^^^^^^^^^^^^^^^^^^^^^^^^^^^^^^^^^^
  File "/home/airflow/.local/lib/python3.12/site-packages/airflow/models/taskinstance.py", line 734, in _execute_callable
    return ExecutionCallableRunner(
           ^^^^^^^^^^^^^^^^^^^^^^^^
  File "/home/airflow/.local/lib/python3.12/site-packages/airflow/utils/operator_helpers.py", line 252, in run
    return self.func(*args, **kwargs)
           ^^^^^^^^^^^^^^^^^^^^^^^^^^
  File "/home/airflow/.local/lib/python3.12/site-packages/airflow/models/baseoperator.py", line 424, in wrapper
    return func(self, *args, **kwargs)
           ^^^^^^^^^^^^^^^^^^^^^^^^^^^
  File "/home/airflow/.local/lib/python3.12/site-packages/airflow/operators/bash.py", line 276, in execute
    raise AirflowException(
airflow.exceptions.AirflowException: Bash command failed. The command returned a non-zero exit code 125.
[2025-03-24T22:27:23.346+0000] {taskinstance.py:1226} INFO - Marking task as UP_FOR_RETRY. dag_id=containers1_dag, task_id=php_app2, run_id=scheduled__2024-03-04T00:00:00+00:00, execution_date=20240304T000000, start_date=20250324T222720, end_date=20250324T222723
[2025-03-24T22:27:23.639+0000] {taskinstance.py:341} INFO - ::group::Post task execution logs
[2025-03-24T22:27:23.640+0000] {standard_task_runner.py:124} ERROR - Failed to execute job 181 for task php_app2 (Bash command failed. The command returned a non-zero exit code 125.; 5544)
Traceback (most recent call last):
  File "/home/airflow/.local/lib/python3.12/site-packages/airflow/task/task_runner/standard_task_runner.py", line 117, in _start_by_fork
    ret = args.func(args, dag=self.dag)
          ^^^^^^^^^^^^^^^^^^^^^^^^^^^^^
  File "/home/airflow/.local/lib/python3.12/site-packages/airflow/cli/cli_config.py", line 49, in command
    return func(*args, **kwargs)
           ^^^^^^^^^^^^^^^^^^^^^
  File "/home/airflow/.local/lib/python3.12/site-packages/airflow/utils/cli.py", line 116, in wrapper
    return f(*args, **kwargs)
           ^^^^^^^^^^^^^^^^^^
  File "/home/airflow/.local/lib/python3.12/site-packages/airflow/cli/commands/task_command.py", line 483, in task_run
    task_return_code = _run_task_by_selected_method(args, _dag, ti)
                       ^^^^^^^^^^^^^^^^^^^^^^^^^^^^^^^^^^^^^^^^^^^^
  File "/home/airflow/.local/lib/python3.12/site-packages/airflow/cli/commands/task_command.py", line 256, in _run_task_by_selected_method
    return _run_raw_task(args, ti)
           ^^^^^^^^^^^^^^^^^^^^^^^
  File "/home/airflow/.local/lib/python3.12/site-packages/airflow/cli/commands/task_command.py", line 341, in _run_raw_task
    return ti._run_raw_task(
           ^^^^^^^^^^^^^^^^^
  File "/home/airflow/.local/lib/python3.12/site-packages/airflow/utils/session.py", line 97, in wrapper
    return func(*args, session=session, **kwargs)
           ^^^^^^^^^^^^^^^^^^^^^^^^^^^^^^^^^^^^^^
  File "/home/airflow/.local/lib/python3.12/site-packages/airflow/models/taskinstance.py", line 3006, in _run_raw_task
    return _run_raw_task(
           ^^^^^^^^^^^^^^
  File "/home/airflow/.local/lib/python3.12/site-packages/airflow/models/taskinstance.py", line 274, in _run_raw_task
    TaskInstance._execute_task_with_callbacks(
  File "/home/airflow/.local/lib/python3.12/site-packages/airflow/models/taskinstance.py", line 3161, in _execute_task_with_callbacks
    result = self._execute_task(context, task_orig)
             ^^^^^^^^^^^^^^^^^^^^^^^^^^^^^^^^^^^^^^
  File "/home/airflow/.local/lib/python3.12/site-packages/airflow/models/taskinstance.py", line 3185, in _execute_task
    return _execute_task(self, context, task_orig)
           ^^^^^^^^^^^^^^^^^^^^^^^^^^^^^^^^^^^^^^^
  File "/home/airflow/.local/lib/python3.12/site-packages/airflow/models/taskinstance.py", line 768, in _execute_task
    result = _execute_callable(context=context, **execute_callable_kwargs)
             ^^^^^^^^^^^^^^^^^^^^^^^^^^^^^^^^^^^^^^^^^^^^^^^^^^^^^^^^^^^^^
  File "/home/airflow/.local/lib/python3.12/site-packages/airflow/models/taskinstance.py", line 734, in _execute_callable
    return ExecutionCallableRunner(
           ^^^^^^^^^^^^^^^^^^^^^^^^
  File "/home/airflow/.local/lib/python3.12/site-packages/airflow/utils/operator_helpers.py", line 252, in run
    return self.func(*args, **kwargs)
           ^^^^^^^^^^^^^^^^^^^^^^^^^^
  File "/home/airflow/.local/lib/python3.12/site-packages/airflow/models/baseoperator.py", line 424, in wrapper
    return func(self, *args, **kwargs)
           ^^^^^^^^^^^^^^^^^^^^^^^^^^^
  File "/home/airflow/.local/lib/python3.12/site-packages/airflow/operators/bash.py", line 276, in execute
    raise AirflowException(
airflow.exceptions.AirflowException: Bash command failed. The command returned a non-zero exit code 125.
[2025-03-24T22:27:23.723+0000] {local_task_job_runner.py:266} INFO - Task exited with return code 1
[2025-03-24T22:27:24.040+0000] {taskinstance.py:3901} INFO - 0 downstream tasks scheduled from follow-on schedule check
[2025-03-24T22:27:24.130+0000] {local_task_job_runner.py:245} INFO - ::endgroup::
[2025-03-24T23:57:24.898+0000] {local_task_job_runner.py:123} INFO - ::group::Pre task execution logs
[2025-03-24T23:57:24.997+0000] {taskinstance.py:2614} INFO - Dependencies all met for dep_context=non-requeueable deps ti=<TaskInstance: containers1_dag.php_app2 scheduled__2024-03-04T00:00:00+00:00 [queued]>
[2025-03-24T23:57:25.056+0000] {taskinstance.py:2614} INFO - Dependencies all met for dep_context=requeueable deps ti=<TaskInstance: containers1_dag.php_app2 scheduled__2024-03-04T00:00:00+00:00 [queued]>
[2025-03-24T23:57:25.059+0000] {taskinstance.py:2867} INFO - Starting attempt 1 of 6
[2025-03-24T23:57:25.387+0000] {taskinstance.py:2890} INFO - Executing <Task(BashOperator): php_app2> on 2024-03-04 00:00:00+00:00
[2025-03-24T23:57:25.460+0000] {standard_task_runner.py:104} INFO - Running: ['***', 'tasks', 'run', 'containers1_dag', 'php_app2', 'scheduled__2024-03-04T00:00:00+00:00', '--job-id', '10', '--raw', '--subdir', 'DAGS_FOLDER/containers1_dag.py', '--cfg-path', '/tmp/tmpdcvsfxyy']
[2025-03-24T23:57:25.472+0000] {standard_task_runner.py:105} INFO - Job 10: Subtask php_app2
[2025-03-24T23:57:25.550+0000] {logging_mixin.py:190} WARNING - /home/***/.local/lib/python3.12/site-packages/***/task/task_runner/standard_task_runner.py:70 DeprecationWarning: This process (pid=218) is multi-threaded, use of fork() may lead to deadlocks in the child.
[2025-03-24T23:57:25.561+0000] {standard_task_runner.py:72} INFO - Started process 259 to run task
[2025-03-24T23:57:25.704+0000] {task_command.py:467} INFO - Running <TaskInstance: containers1_dag.php_app2 scheduled__2024-03-04T00:00:00+00:00 [running]> on host 8e89fdaa3360
[2025-03-24T23:57:27.132+0000] {taskinstance.py:3134} INFO - Exporting env vars: AIRFLOW_CTX_DAG_OWNER='andre' AIRFLOW_CTX_DAG_ID='containers1_dag' AIRFLOW_CTX_TASK_ID='php_app2' AIRFLOW_CTX_EXECUTION_DATE='2024-03-04T00:00:00+00:00' AIRFLOW_CTX_TRY_NUMBER='1' AIRFLOW_CTX_DAG_RUN_ID='scheduled__2024-03-04T00:00:00+00:00'
[2025-03-24T23:57:27.133+0000] {taskinstance.py:732} INFO - ::endgroup::
[2025-03-24T23:57:27.187+0000] {subprocess.py:78} INFO - Tmp dir root location: /tmp
[2025-03-24T23:57:27.189+0000] {subprocess.py:88} INFO - Running command: ['/usr/bin/bash', '-c', 'docker run -v $(pwd)/../in:/usr/src/app/in -v $(pwd):/usr/src/app php-app2']
[2025-03-24T23:57:27.274+0000] {subprocess.py:99} INFO - Output:
[2025-03-24T23:57:27.348+0000] {subprocess.py:106} INFO - docker: Cannot connect to the Docker daemon at unix:///var/run/docker.sock. Is the docker daemon running?.
[2025-03-24T23:57:27.350+0000] {subprocess.py:106} INFO - See 'docker run --help'.
[2025-03-24T23:57:27.354+0000] {subprocess.py:110} INFO - Command exited with return code 125
[2025-03-24T23:57:27.433+0000] {taskinstance.py:3313} ERROR - Task failed with exception
Traceback (most recent call last):
  File "/home/airflow/.local/lib/python3.12/site-packages/airflow/models/taskinstance.py", line 768, in _execute_task
    result = _execute_callable(context=context, **execute_callable_kwargs)
             ^^^^^^^^^^^^^^^^^^^^^^^^^^^^^^^^^^^^^^^^^^^^^^^^^^^^^^^^^^^^^
  File "/home/airflow/.local/lib/python3.12/site-packages/airflow/models/taskinstance.py", line 734, in _execute_callable
    return ExecutionCallableRunner(
           ^^^^^^^^^^^^^^^^^^^^^^^^
  File "/home/airflow/.local/lib/python3.12/site-packages/airflow/utils/operator_helpers.py", line 252, in run
    return self.func(*args, **kwargs)
           ^^^^^^^^^^^^^^^^^^^^^^^^^^
  File "/home/airflow/.local/lib/python3.12/site-packages/airflow/models/baseoperator.py", line 424, in wrapper
    return func(self, *args, **kwargs)
           ^^^^^^^^^^^^^^^^^^^^^^^^^^^
  File "/home/airflow/.local/lib/python3.12/site-packages/airflow/operators/bash.py", line 276, in execute
    raise AirflowException(
airflow.exceptions.AirflowException: Bash command failed. The command returned a non-zero exit code 125.
[2025-03-24T23:57:27.685+0000] {taskinstance.py:1226} INFO - Marking task as UP_FOR_RETRY. dag_id=containers1_dag, task_id=php_app2, run_id=scheduled__2024-03-04T00:00:00+00:00, execution_date=20240304T000000, start_date=20250324T235725, end_date=20250324T235727
[2025-03-24T23:57:28.002+0000] {taskinstance.py:341} INFO - ::group::Post task execution logs
[2025-03-24T23:57:28.027+0000] {standard_task_runner.py:124} ERROR - Failed to execute job 10 for task php_app2 (Bash command failed. The command returned a non-zero exit code 125.; 259)
Traceback (most recent call last):
  File "/home/airflow/.local/lib/python3.12/site-packages/airflow/task/task_runner/standard_task_runner.py", line 117, in _start_by_fork
    ret = args.func(args, dag=self.dag)
          ^^^^^^^^^^^^^^^^^^^^^^^^^^^^^
  File "/home/airflow/.local/lib/python3.12/site-packages/airflow/cli/cli_config.py", line 49, in command
    return func(*args, **kwargs)
           ^^^^^^^^^^^^^^^^^^^^^
  File "/home/airflow/.local/lib/python3.12/site-packages/airflow/utils/cli.py", line 116, in wrapper
    return f(*args, **kwargs)
           ^^^^^^^^^^^^^^^^^^
  File "/home/airflow/.local/lib/python3.12/site-packages/airflow/cli/commands/task_command.py", line 483, in task_run
    task_return_code = _run_task_by_selected_method(args, _dag, ti)
                       ^^^^^^^^^^^^^^^^^^^^^^^^^^^^^^^^^^^^^^^^^^^^
  File "/home/airflow/.local/lib/python3.12/site-packages/airflow/cli/commands/task_command.py", line 256, in _run_task_by_selected_method
    return _run_raw_task(args, ti)
           ^^^^^^^^^^^^^^^^^^^^^^^
  File "/home/airflow/.local/lib/python3.12/site-packages/airflow/cli/commands/task_command.py", line 341, in _run_raw_task
    return ti._run_raw_task(
           ^^^^^^^^^^^^^^^^^
  File "/home/airflow/.local/lib/python3.12/site-packages/airflow/utils/session.py", line 97, in wrapper
    return func(*args, session=session, **kwargs)
           ^^^^^^^^^^^^^^^^^^^^^^^^^^^^^^^^^^^^^^
  File "/home/airflow/.local/lib/python3.12/site-packages/airflow/models/taskinstance.py", line 3006, in _run_raw_task
    return _run_raw_task(
           ^^^^^^^^^^^^^^
  File "/home/airflow/.local/lib/python3.12/site-packages/airflow/models/taskinstance.py", line 274, in _run_raw_task
    TaskInstance._execute_task_with_callbacks(
  File "/home/airflow/.local/lib/python3.12/site-packages/airflow/models/taskinstance.py", line 3161, in _execute_task_with_callbacks
    result = self._execute_task(context, task_orig)
             ^^^^^^^^^^^^^^^^^^^^^^^^^^^^^^^^^^^^^^
  File "/home/airflow/.local/lib/python3.12/site-packages/airflow/models/taskinstance.py", line 3185, in _execute_task
    return _execute_task(self, context, task_orig)
           ^^^^^^^^^^^^^^^^^^^^^^^^^^^^^^^^^^^^^^^
  File "/home/airflow/.local/lib/python3.12/site-packages/airflow/models/taskinstance.py", line 768, in _execute_task
    result = _execute_callable(context=context, **execute_callable_kwargs)
             ^^^^^^^^^^^^^^^^^^^^^^^^^^^^^^^^^^^^^^^^^^^^^^^^^^^^^^^^^^^^^
  File "/home/airflow/.local/lib/python3.12/site-packages/airflow/models/taskinstance.py", line 734, in _execute_callable
    return ExecutionCallableRunner(
           ^^^^^^^^^^^^^^^^^^^^^^^^
  File "/home/airflow/.local/lib/python3.12/site-packages/airflow/utils/operator_helpers.py", line 252, in run
    return self.func(*args, **kwargs)
           ^^^^^^^^^^^^^^^^^^^^^^^^^^
  File "/home/airflow/.local/lib/python3.12/site-packages/airflow/models/baseoperator.py", line 424, in wrapper
    return func(self, *args, **kwargs)
           ^^^^^^^^^^^^^^^^^^^^^^^^^^^
  File "/home/airflow/.local/lib/python3.12/site-packages/airflow/operators/bash.py", line 276, in execute
    raise AirflowException(
airflow.exceptions.AirflowException: Bash command failed. The command returned a non-zero exit code 125.
[2025-03-24T23:57:28.136+0000] {local_task_job_runner.py:266} INFO - Task exited with return code 1
[2025-03-24T23:57:28.261+0000] {taskinstance.py:3901} INFO - 0 downstream tasks scheduled from follow-on schedule check
[2025-03-24T23:57:28.277+0000] {local_task_job_runner.py:245} INFO - ::endgroup::
[2025-03-25T00:18:26.480+0000] {local_task_job_runner.py:123} INFO - ::group::Pre task execution logs
[2025-03-25T00:18:26.650+0000] {taskinstance.py:2614} INFO - Dependencies all met for dep_context=non-requeueable deps ti=<TaskInstance: containers1_dag.php_app2 scheduled__2024-03-04T00:00:00+00:00 [queued]>
[2025-03-25T00:18:26.775+0000] {taskinstance.py:2614} INFO - Dependencies all met for dep_context=requeueable deps ti=<TaskInstance: containers1_dag.php_app2 scheduled__2024-03-04T00:00:00+00:00 [queued]>
[2025-03-25T00:18:26.775+0000] {taskinstance.py:2867} INFO - Starting attempt 1 of 6
[2025-03-25T00:18:27.042+0000] {taskinstance.py:2890} INFO - Executing <Task(DockerOperator): php_app2> on 2024-03-04 00:00:00+00:00
[2025-03-25T00:18:27.099+0000] {standard_task_runner.py:104} INFO - Running: ['***', 'tasks', 'run', 'containers1_dag', 'php_app2', 'scheduled__2024-03-04T00:00:00+00:00', '--job-id', '9', '--raw', '--subdir', 'DAGS_FOLDER/containers1_dag.py', '--cfg-path', '/tmp/tmpoto6my3k']
[2025-03-25T00:18:27.111+0000] {standard_task_runner.py:105} INFO - Job 9: Subtask php_app2
[2025-03-25T00:18:27.136+0000] {logging_mixin.py:190} WARNING - /home/***/.local/lib/python3.12/site-packages/***/task/task_runner/standard_task_runner.py:70 DeprecationWarning: This process (pid=394) is multi-threaded, use of fork() may lead to deadlocks in the child.
[2025-03-25T00:18:27.137+0000] {standard_task_runner.py:72} INFO - Started process 411 to run task
[2025-03-25T00:18:27.492+0000] {task_command.py:467} INFO - Running <TaskInstance: containers1_dag.php_app2 scheduled__2024-03-04T00:00:00+00:00 [running]> on host 0f77abd8a5ce
[2025-03-25T00:18:28.342+0000] {taskinstance.py:3134} INFO - Exporting env vars: AIRFLOW_CTX_DAG_OWNER='andre' AIRFLOW_CTX_DAG_ID='containers1_dag' AIRFLOW_CTX_TASK_ID='php_app2' AIRFLOW_CTX_EXECUTION_DATE='2024-03-04T00:00:00+00:00' AIRFLOW_CTX_TRY_NUMBER='1' AIRFLOW_CTX_DAG_RUN_ID='scheduled__2024-03-04T00:00:00+00:00'
[2025-03-25T00:18:28.343+0000] {taskinstance.py:732} INFO - ::endgroup::
[2025-03-25T00:18:28.528+0000] {docker.py:157} ERROR - Failed to establish connection to Docker host unix://var/run/docker.sock: Error while fetching server API version: ('Connection aborted.', FileNotFoundError(2, 'No such file or directory'))
[2025-03-25T00:18:28.589+0000] {taskinstance.py:3313} ERROR - Task failed with exception
Traceback (most recent call last):
  File "/home/airflow/.local/lib/python3.12/site-packages/airflow/models/taskinstance.py", line 768, in _execute_task
    result = _execute_callable(context=context, **execute_callable_kwargs)
             ^^^^^^^^^^^^^^^^^^^^^^^^^^^^^^^^^^^^^^^^^^^^^^^^^^^^^^^^^^^^^
  File "/home/airflow/.local/lib/python3.12/site-packages/airflow/models/taskinstance.py", line 734, in _execute_callable
    return ExecutionCallableRunner(
           ^^^^^^^^^^^^^^^^^^^^^^^^
  File "/home/airflow/.local/lib/python3.12/site-packages/airflow/utils/operator_helpers.py", line 252, in run
    return self.func(*args, **kwargs)
           ^^^^^^^^^^^^^^^^^^^^^^^^^^
  File "/home/airflow/.local/lib/python3.12/site-packages/airflow/models/baseoperator.py", line 424, in wrapper
    return func(self, *args, **kwargs)
           ^^^^^^^^^^^^^^^^^^^^^^^^^^^
  File "/home/airflow/.local/lib/python3.12/site-packages/airflow/providers/docker/operators/docker.py", line 467, in execute
    if self.force_pull or not self.cli.images(name=self.image):
                              ^^^^^^^^
  File "/home/airflow/.local/lib/python3.12/site-packages/airflow/providers/docker/operators/docker.py", line 341, in cli
    return self.hook.api_client
           ^^^^^^^^^^^^^^^^^^^^
  File "/usr/local/lib/python3.12/functools.py", line 998, in __get__
    val = self.func(instance)
          ^^^^^^^^^^^^^^^^^^^
  File "/home/airflow/.local/lib/python3.12/site-packages/airflow/providers/docker/hooks/docker.py", line 161, in api_client
    raise AirflowException("Failed to establish connection to any given Docker hosts.")
airflow.exceptions.AirflowException: Failed to establish connection to any given Docker hosts.
[2025-03-25T00:18:28.683+0000] {taskinstance.py:1226} INFO - Marking task as UP_FOR_RETRY. dag_id=containers1_dag, task_id=php_app2, run_id=scheduled__2024-03-04T00:00:00+00:00, execution_date=20240304T000000, start_date=20250325T001826, end_date=20250325T001828
[2025-03-25T00:18:28.967+0000] {taskinstance.py:341} INFO - ::group::Post task execution logs
[2025-03-25T00:18:28.970+0000] {standard_task_runner.py:124} ERROR - Failed to execute job 9 for task php_app2 (Failed to establish connection to any given Docker hosts.; 411)
Traceback (most recent call last):
  File "/home/airflow/.local/lib/python3.12/site-packages/airflow/task/task_runner/standard_task_runner.py", line 117, in _start_by_fork
    ret = args.func(args, dag=self.dag)
          ^^^^^^^^^^^^^^^^^^^^^^^^^^^^^
  File "/home/airflow/.local/lib/python3.12/site-packages/airflow/cli/cli_config.py", line 49, in command
    return func(*args, **kwargs)
           ^^^^^^^^^^^^^^^^^^^^^
  File "/home/airflow/.local/lib/python3.12/site-packages/airflow/utils/cli.py", line 116, in wrapper
    return f(*args, **kwargs)
           ^^^^^^^^^^^^^^^^^^
  File "/home/airflow/.local/lib/python3.12/site-packages/airflow/cli/commands/task_command.py", line 483, in task_run
    task_return_code = _run_task_by_selected_method(args, _dag, ti)
                       ^^^^^^^^^^^^^^^^^^^^^^^^^^^^^^^^^^^^^^^^^^^^
  File "/home/airflow/.local/lib/python3.12/site-packages/airflow/cli/commands/task_command.py", line 256, in _run_task_by_selected_method
    return _run_raw_task(args, ti)
           ^^^^^^^^^^^^^^^^^^^^^^^
  File "/home/airflow/.local/lib/python3.12/site-packages/airflow/cli/commands/task_command.py", line 341, in _run_raw_task
    return ti._run_raw_task(
           ^^^^^^^^^^^^^^^^^
  File "/home/airflow/.local/lib/python3.12/site-packages/airflow/utils/session.py", line 97, in wrapper
    return func(*args, session=session, **kwargs)
           ^^^^^^^^^^^^^^^^^^^^^^^^^^^^^^^^^^^^^^
  File "/home/airflow/.local/lib/python3.12/site-packages/airflow/models/taskinstance.py", line 3006, in _run_raw_task
    return _run_raw_task(
           ^^^^^^^^^^^^^^
  File "/home/airflow/.local/lib/python3.12/site-packages/airflow/models/taskinstance.py", line 274, in _run_raw_task
    TaskInstance._execute_task_with_callbacks(
  File "/home/airflow/.local/lib/python3.12/site-packages/airflow/models/taskinstance.py", line 3161, in _execute_task_with_callbacks
    result = self._execute_task(context, task_orig)
             ^^^^^^^^^^^^^^^^^^^^^^^^^^^^^^^^^^^^^^
  File "/home/airflow/.local/lib/python3.12/site-packages/airflow/models/taskinstance.py", line 3185, in _execute_task
    return _execute_task(self, context, task_orig)
           ^^^^^^^^^^^^^^^^^^^^^^^^^^^^^^^^^^^^^^^
  File "/home/airflow/.local/lib/python3.12/site-packages/airflow/models/taskinstance.py", line 768, in _execute_task
    result = _execute_callable(context=context, **execute_callable_kwargs)
             ^^^^^^^^^^^^^^^^^^^^^^^^^^^^^^^^^^^^^^^^^^^^^^^^^^^^^^^^^^^^^
  File "/home/airflow/.local/lib/python3.12/site-packages/airflow/models/taskinstance.py", line 734, in _execute_callable
    return ExecutionCallableRunner(
           ^^^^^^^^^^^^^^^^^^^^^^^^
  File "/home/airflow/.local/lib/python3.12/site-packages/airflow/utils/operator_helpers.py", line 252, in run
    return self.func(*args, **kwargs)
           ^^^^^^^^^^^^^^^^^^^^^^^^^^
  File "/home/airflow/.local/lib/python3.12/site-packages/airflow/models/baseoperator.py", line 424, in wrapper
    return func(self, *args, **kwargs)
           ^^^^^^^^^^^^^^^^^^^^^^^^^^^
  File "/home/airflow/.local/lib/python3.12/site-packages/airflow/providers/docker/operators/docker.py", line 467, in execute
    if self.force_pull or not self.cli.images(name=self.image):
                              ^^^^^^^^
  File "/home/airflow/.local/lib/python3.12/site-packages/airflow/providers/docker/operators/docker.py", line 341, in cli
    return self.hook.api_client
           ^^^^^^^^^^^^^^^^^^^^
  File "/usr/local/lib/python3.12/functools.py", line 998, in __get__
    val = self.func(instance)
          ^^^^^^^^^^^^^^^^^^^
  File "/home/airflow/.local/lib/python3.12/site-packages/airflow/providers/docker/hooks/docker.py", line 161, in api_client
    raise AirflowException("Failed to establish connection to any given Docker hosts.")
airflow.exceptions.AirflowException: Failed to establish connection to any given Docker hosts.
[2025-03-25T00:18:29.057+0000] {local_task_job_runner.py:266} INFO - Task exited with return code 1
[2025-03-25T00:18:29.169+0000] {taskinstance.py:3901} INFO - 0 downstream tasks scheduled from follow-on schedule check
[2025-03-25T00:18:29.175+0000] {local_task_job_runner.py:245} INFO - ::endgroup::
[2025-03-25T00:25:40.777+0000] {local_task_job_runner.py:123} INFO - ::group::Pre task execution logs
[2025-03-25T00:25:41.094+0000] {taskinstance.py:2614} INFO - Dependencies all met for dep_context=non-requeueable deps ti=<TaskInstance: containers1_dag.php_app2 scheduled__2024-03-04T00:00:00+00:00 [queued]>
[2025-03-25T00:25:41.307+0000] {taskinstance.py:2614} INFO - Dependencies all met for dep_context=requeueable deps ti=<TaskInstance: containers1_dag.php_app2 scheduled__2024-03-04T00:00:00+00:00 [queued]>
[2025-03-25T00:25:41.308+0000] {taskinstance.py:2867} INFO - Starting attempt 1 of 6
[2025-03-25T00:25:41.572+0000] {taskinstance.py:2890} INFO - Executing <Task(DockerOperator): php_app2> on 2024-03-04 00:00:00+00:00
[2025-03-25T00:25:41.714+0000] {standard_task_runner.py:104} INFO - Running: ['***', 'tasks', 'run', 'containers1_dag', 'php_app2', 'scheduled__2024-03-04T00:00:00+00:00', '--job-id', '10', '--raw', '--subdir', 'DAGS_FOLDER/containers1_dag.py', '--cfg-path', '/tmp/tmph599foxr']
[2025-03-25T00:25:41.756+0000] {standard_task_runner.py:105} INFO - Job 10: Subtask php_app2
[2025-03-25T00:25:41.800+0000] {logging_mixin.py:190} WARNING - /home/***/.local/lib/python3.12/site-packages/***/task/task_runner/standard_task_runner.py:70 DeprecationWarning: This process (pid=204) is multi-threaded, use of fork() may lead to deadlocks in the child.
[2025-03-25T00:25:41.801+0000] {standard_task_runner.py:72} INFO - Started process 230 to run task
[2025-03-25T00:25:42.663+0000] {task_command.py:467} INFO - Running <TaskInstance: containers1_dag.php_app2 scheduled__2024-03-04T00:00:00+00:00 [running]> on host 7e2e363232cf
[2025-03-25T00:25:44.245+0000] {taskinstance.py:3134} INFO - Exporting env vars: AIRFLOW_CTX_DAG_OWNER='andre' AIRFLOW_CTX_DAG_ID='containers1_dag' AIRFLOW_CTX_TASK_ID='php_app2' AIRFLOW_CTX_EXECUTION_DATE='2024-03-04T00:00:00+00:00' AIRFLOW_CTX_TRY_NUMBER='1' AIRFLOW_CTX_DAG_RUN_ID='scheduled__2024-03-04T00:00:00+00:00'
[2025-03-25T00:25:44.250+0000] {taskinstance.py:732} INFO - ::endgroup::
[2025-03-25T00:25:44.441+0000] {docker.py:157} ERROR - Failed to establish connection to Docker host unix://var/run/docker.sock: Error while fetching server API version: ('Connection aborted.', FileNotFoundError(2, 'No such file or directory'))
[2025-03-25T00:25:44.554+0000] {taskinstance.py:3313} ERROR - Task failed with exception
Traceback (most recent call last):
  File "/home/airflow/.local/lib/python3.12/site-packages/airflow/models/taskinstance.py", line 768, in _execute_task
    result = _execute_callable(context=context, **execute_callable_kwargs)
             ^^^^^^^^^^^^^^^^^^^^^^^^^^^^^^^^^^^^^^^^^^^^^^^^^^^^^^^^^^^^^
  File "/home/airflow/.local/lib/python3.12/site-packages/airflow/models/taskinstance.py", line 734, in _execute_callable
    return ExecutionCallableRunner(
           ^^^^^^^^^^^^^^^^^^^^^^^^
  File "/home/airflow/.local/lib/python3.12/site-packages/airflow/utils/operator_helpers.py", line 252, in run
    return self.func(*args, **kwargs)
           ^^^^^^^^^^^^^^^^^^^^^^^^^^
  File "/home/airflow/.local/lib/python3.12/site-packages/airflow/models/baseoperator.py", line 424, in wrapper
    return func(self, *args, **kwargs)
           ^^^^^^^^^^^^^^^^^^^^^^^^^^^
  File "/home/airflow/.local/lib/python3.12/site-packages/airflow/providers/docker/operators/docker.py", line 467, in execute
    if self.force_pull or not self.cli.images(name=self.image):
                              ^^^^^^^^
  File "/home/airflow/.local/lib/python3.12/site-packages/airflow/providers/docker/operators/docker.py", line 341, in cli
    return self.hook.api_client
           ^^^^^^^^^^^^^^^^^^^^
  File "/usr/local/lib/python3.12/functools.py", line 998, in __get__
    val = self.func(instance)
          ^^^^^^^^^^^^^^^^^^^
  File "/home/airflow/.local/lib/python3.12/site-packages/airflow/providers/docker/hooks/docker.py", line 161, in api_client
    raise AirflowException("Failed to establish connection to any given Docker hosts.")
airflow.exceptions.AirflowException: Failed to establish connection to any given Docker hosts.
[2025-03-25T00:25:44.660+0000] {taskinstance.py:1226} INFO - Marking task as UP_FOR_RETRY. dag_id=containers1_dag, task_id=php_app2, run_id=scheduled__2024-03-04T00:00:00+00:00, execution_date=20240304T000000, start_date=20250325T002541, end_date=20250325T002544
[2025-03-25T00:25:44.938+0000] {taskinstance.py:341} INFO - ::group::Post task execution logs
[2025-03-25T00:25:44.951+0000] {standard_task_runner.py:124} ERROR - Failed to execute job 10 for task php_app2 (Failed to establish connection to any given Docker hosts.; 230)
Traceback (most recent call last):
  File "/home/airflow/.local/lib/python3.12/site-packages/airflow/task/task_runner/standard_task_runner.py", line 117, in _start_by_fork
    ret = args.func(args, dag=self.dag)
          ^^^^^^^^^^^^^^^^^^^^^^^^^^^^^
  File "/home/airflow/.local/lib/python3.12/site-packages/airflow/cli/cli_config.py", line 49, in command
    return func(*args, **kwargs)
           ^^^^^^^^^^^^^^^^^^^^^
  File "/home/airflow/.local/lib/python3.12/site-packages/airflow/utils/cli.py", line 116, in wrapper
    return f(*args, **kwargs)
           ^^^^^^^^^^^^^^^^^^
  File "/home/airflow/.local/lib/python3.12/site-packages/airflow/cli/commands/task_command.py", line 483, in task_run
    task_return_code = _run_task_by_selected_method(args, _dag, ti)
                       ^^^^^^^^^^^^^^^^^^^^^^^^^^^^^^^^^^^^^^^^^^^^
  File "/home/airflow/.local/lib/python3.12/site-packages/airflow/cli/commands/task_command.py", line 256, in _run_task_by_selected_method
    return _run_raw_task(args, ti)
           ^^^^^^^^^^^^^^^^^^^^^^^
  File "/home/airflow/.local/lib/python3.12/site-packages/airflow/cli/commands/task_command.py", line 341, in _run_raw_task
    return ti._run_raw_task(
           ^^^^^^^^^^^^^^^^^
  File "/home/airflow/.local/lib/python3.12/site-packages/airflow/utils/session.py", line 97, in wrapper
    return func(*args, session=session, **kwargs)
           ^^^^^^^^^^^^^^^^^^^^^^^^^^^^^^^^^^^^^^
  File "/home/airflow/.local/lib/python3.12/site-packages/airflow/models/taskinstance.py", line 3006, in _run_raw_task
    return _run_raw_task(
           ^^^^^^^^^^^^^^
  File "/home/airflow/.local/lib/python3.12/site-packages/airflow/models/taskinstance.py", line 274, in _run_raw_task
    TaskInstance._execute_task_with_callbacks(
  File "/home/airflow/.local/lib/python3.12/site-packages/airflow/models/taskinstance.py", line 3161, in _execute_task_with_callbacks
    result = self._execute_task(context, task_orig)
             ^^^^^^^^^^^^^^^^^^^^^^^^^^^^^^^^^^^^^^
  File "/home/airflow/.local/lib/python3.12/site-packages/airflow/models/taskinstance.py", line 3185, in _execute_task
    return _execute_task(self, context, task_orig)
           ^^^^^^^^^^^^^^^^^^^^^^^^^^^^^^^^^^^^^^^
  File "/home/airflow/.local/lib/python3.12/site-packages/airflow/models/taskinstance.py", line 768, in _execute_task
    result = _execute_callable(context=context, **execute_callable_kwargs)
             ^^^^^^^^^^^^^^^^^^^^^^^^^^^^^^^^^^^^^^^^^^^^^^^^^^^^^^^^^^^^^
  File "/home/airflow/.local/lib/python3.12/site-packages/airflow/models/taskinstance.py", line 734, in _execute_callable
    return ExecutionCallableRunner(
           ^^^^^^^^^^^^^^^^^^^^^^^^
  File "/home/airflow/.local/lib/python3.12/site-packages/airflow/utils/operator_helpers.py", line 252, in run
    return self.func(*args, **kwargs)
           ^^^^^^^^^^^^^^^^^^^^^^^^^^
  File "/home/airflow/.local/lib/python3.12/site-packages/airflow/models/baseoperator.py", line 424, in wrapper
    return func(self, *args, **kwargs)
           ^^^^^^^^^^^^^^^^^^^^^^^^^^^
  File "/home/airflow/.local/lib/python3.12/site-packages/airflow/providers/docker/operators/docker.py", line 467, in execute
    if self.force_pull or not self.cli.images(name=self.image):
                              ^^^^^^^^
  File "/home/airflow/.local/lib/python3.12/site-packages/airflow/providers/docker/operators/docker.py", line 341, in cli
    return self.hook.api_client
           ^^^^^^^^^^^^^^^^^^^^
  File "/usr/local/lib/python3.12/functools.py", line 998, in __get__
    val = self.func(instance)
          ^^^^^^^^^^^^^^^^^^^
  File "/home/airflow/.local/lib/python3.12/site-packages/airflow/providers/docker/hooks/docker.py", line 161, in api_client
    raise AirflowException("Failed to establish connection to any given Docker hosts.")
airflow.exceptions.AirflowException: Failed to establish connection to any given Docker hosts.
[2025-03-25T00:25:45.098+0000] {local_task_job_runner.py:266} INFO - Task exited with return code 1
[2025-03-25T00:25:45.284+0000] {taskinstance.py:3901} INFO - 0 downstream tasks scheduled from follow-on schedule check
[2025-03-25T00:25:45.292+0000] {local_task_job_runner.py:245} INFO - ::endgroup::
[2025-03-25T12:45:30.089+0000] {local_task_job_runner.py:123} INFO - ::group::Pre task execution logs
[2025-03-25T12:45:30.183+0000] {taskinstance.py:2614} INFO - Dependencies all met for dep_context=non-requeueable deps ti=<TaskInstance: containers1_dag.php_app2 scheduled__2024-03-04T00:00:00+00:00 [queued]>
[2025-03-25T12:45:30.262+0000] {taskinstance.py:2614} INFO - Dependencies all met for dep_context=requeueable deps ti=<TaskInstance: containers1_dag.php_app2 scheduled__2024-03-04T00:00:00+00:00 [queued]>
[2025-03-25T12:45:30.281+0000] {taskinstance.py:2867} INFO - Starting attempt 1 of 6
[2025-03-25T12:45:30.539+0000] {taskinstance.py:2890} INFO - Executing <Task(DockerOperator): php_app2> on 2024-03-04 00:00:00+00:00
[2025-03-25T12:45:30.653+0000] {standard_task_runner.py:104} INFO - Running: ['***', 'tasks', 'run', 'containers1_dag', 'php_app2', 'scheduled__2024-03-04T00:00:00+00:00', '--job-id', '8', '--raw', '--subdir', 'DAGS_FOLDER/containers1_dag.py', '--cfg-path', '/tmp/tmpoepjvvnn']
[2025-03-25T12:45:30.698+0000] {standard_task_runner.py:105} INFO - Job 8: Subtask php_app2
[2025-03-25T12:45:30.702+0000] {logging_mixin.py:190} WARNING - /home/***/.local/lib/python3.12/site-packages/***/task/task_runner/standard_task_runner.py:70 DeprecationWarning: This process (pid=219) is multi-threaded, use of fork() may lead to deadlocks in the child.
[2025-03-25T12:45:30.703+0000] {standard_task_runner.py:72} INFO - Started process 244 to run task
[2025-03-25T12:45:31.073+0000] {task_command.py:467} INFO - Running <TaskInstance: containers1_dag.php_app2 scheduled__2024-03-04T00:00:00+00:00 [running]> on host c83c0958fca4
[2025-03-25T12:45:31.598+0000] {taskinstance.py:3134} INFO - Exporting env vars: AIRFLOW_CTX_DAG_OWNER='andre' AIRFLOW_CTX_DAG_ID='containers1_dag' AIRFLOW_CTX_TASK_ID='php_app2' AIRFLOW_CTX_EXECUTION_DATE='2024-03-04T00:00:00+00:00' AIRFLOW_CTX_TRY_NUMBER='1' AIRFLOW_CTX_DAG_RUN_ID='scheduled__2024-03-04T00:00:00+00:00'
[2025-03-25T12:45:31.599+0000] {taskinstance.py:732} INFO - ::endgroup::
[2025-03-25T12:45:31.716+0000] {docker.py:157} ERROR - Failed to establish connection to Docker host unix://var/run/docker.sock: Error while fetching server API version: ('Connection aborted.', FileNotFoundError(2, 'No such file or directory'))
[2025-03-25T12:45:31.760+0000] {taskinstance.py:3313} ERROR - Task failed with exception
Traceback (most recent call last):
  File "/home/airflow/.local/lib/python3.12/site-packages/airflow/models/taskinstance.py", line 768, in _execute_task
    result = _execute_callable(context=context, **execute_callable_kwargs)
             ^^^^^^^^^^^^^^^^^^^^^^^^^^^^^^^^^^^^^^^^^^^^^^^^^^^^^^^^^^^^^
  File "/home/airflow/.local/lib/python3.12/site-packages/airflow/models/taskinstance.py", line 734, in _execute_callable
    return ExecutionCallableRunner(
           ^^^^^^^^^^^^^^^^^^^^^^^^
  File "/home/airflow/.local/lib/python3.12/site-packages/airflow/utils/operator_helpers.py", line 252, in run
    return self.func(*args, **kwargs)
           ^^^^^^^^^^^^^^^^^^^^^^^^^^
  File "/home/airflow/.local/lib/python3.12/site-packages/airflow/models/baseoperator.py", line 424, in wrapper
    return func(self, *args, **kwargs)
           ^^^^^^^^^^^^^^^^^^^^^^^^^^^
  File "/home/airflow/.local/lib/python3.12/site-packages/airflow/providers/docker/operators/docker.py", line 467, in execute
    if self.force_pull or not self.cli.images(name=self.image):
                              ^^^^^^^^
  File "/home/airflow/.local/lib/python3.12/site-packages/airflow/providers/docker/operators/docker.py", line 341, in cli
    return self.hook.api_client
           ^^^^^^^^^^^^^^^^^^^^
  File "/usr/local/lib/python3.12/functools.py", line 998, in __get__
    val = self.func(instance)
          ^^^^^^^^^^^^^^^^^^^
  File "/home/airflow/.local/lib/python3.12/site-packages/airflow/providers/docker/hooks/docker.py", line 161, in api_client
    raise AirflowException("Failed to establish connection to any given Docker hosts.")
airflow.exceptions.AirflowException: Failed to establish connection to any given Docker hosts.
[2025-03-25T12:45:31.809+0000] {taskinstance.py:1226} INFO - Marking task as UP_FOR_RETRY. dag_id=containers1_dag, task_id=php_app2, run_id=scheduled__2024-03-04T00:00:00+00:00, execution_date=20240304T000000, start_date=20250325T124530, end_date=20250325T124531
[2025-03-25T12:45:31.974+0000] {taskinstance.py:341} INFO - ::group::Post task execution logs
[2025-03-25T12:45:31.975+0000] {standard_task_runner.py:124} ERROR - Failed to execute job 8 for task php_app2 (Failed to establish connection to any given Docker hosts.; 244)
Traceback (most recent call last):
  File "/home/airflow/.local/lib/python3.12/site-packages/airflow/task/task_runner/standard_task_runner.py", line 117, in _start_by_fork
    ret = args.func(args, dag=self.dag)
          ^^^^^^^^^^^^^^^^^^^^^^^^^^^^^
  File "/home/airflow/.local/lib/python3.12/site-packages/airflow/cli/cli_config.py", line 49, in command
    return func(*args, **kwargs)
           ^^^^^^^^^^^^^^^^^^^^^
  File "/home/airflow/.local/lib/python3.12/site-packages/airflow/utils/cli.py", line 116, in wrapper
    return f(*args, **kwargs)
           ^^^^^^^^^^^^^^^^^^
  File "/home/airflow/.local/lib/python3.12/site-packages/airflow/cli/commands/task_command.py", line 483, in task_run
    task_return_code = _run_task_by_selected_method(args, _dag, ti)
                       ^^^^^^^^^^^^^^^^^^^^^^^^^^^^^^^^^^^^^^^^^^^^
  File "/home/airflow/.local/lib/python3.12/site-packages/airflow/cli/commands/task_command.py", line 256, in _run_task_by_selected_method
    return _run_raw_task(args, ti)
           ^^^^^^^^^^^^^^^^^^^^^^^
  File "/home/airflow/.local/lib/python3.12/site-packages/airflow/cli/commands/task_command.py", line 341, in _run_raw_task
    return ti._run_raw_task(
           ^^^^^^^^^^^^^^^^^
  File "/home/airflow/.local/lib/python3.12/site-packages/airflow/utils/session.py", line 97, in wrapper
    return func(*args, session=session, **kwargs)
           ^^^^^^^^^^^^^^^^^^^^^^^^^^^^^^^^^^^^^^
  File "/home/airflow/.local/lib/python3.12/site-packages/airflow/models/taskinstance.py", line 3006, in _run_raw_task
    return _run_raw_task(
           ^^^^^^^^^^^^^^
  File "/home/airflow/.local/lib/python3.12/site-packages/airflow/models/taskinstance.py", line 274, in _run_raw_task
    TaskInstance._execute_task_with_callbacks(
  File "/home/airflow/.local/lib/python3.12/site-packages/airflow/models/taskinstance.py", line 3161, in _execute_task_with_callbacks
    result = self._execute_task(context, task_orig)
             ^^^^^^^^^^^^^^^^^^^^^^^^^^^^^^^^^^^^^^
  File "/home/airflow/.local/lib/python3.12/site-packages/airflow/models/taskinstance.py", line 3185, in _execute_task
    return _execute_task(self, context, task_orig)
           ^^^^^^^^^^^^^^^^^^^^^^^^^^^^^^^^^^^^^^^
  File "/home/airflow/.local/lib/python3.12/site-packages/airflow/models/taskinstance.py", line 768, in _execute_task
    result = _execute_callable(context=context, **execute_callable_kwargs)
             ^^^^^^^^^^^^^^^^^^^^^^^^^^^^^^^^^^^^^^^^^^^^^^^^^^^^^^^^^^^^^
  File "/home/airflow/.local/lib/python3.12/site-packages/airflow/models/taskinstance.py", line 734, in _execute_callable
    return ExecutionCallableRunner(
           ^^^^^^^^^^^^^^^^^^^^^^^^
  File "/home/airflow/.local/lib/python3.12/site-packages/airflow/utils/operator_helpers.py", line 252, in run
    return self.func(*args, **kwargs)
           ^^^^^^^^^^^^^^^^^^^^^^^^^^
  File "/home/airflow/.local/lib/python3.12/site-packages/airflow/models/baseoperator.py", line 424, in wrapper
    return func(self, *args, **kwargs)
           ^^^^^^^^^^^^^^^^^^^^^^^^^^^
  File "/home/airflow/.local/lib/python3.12/site-packages/airflow/providers/docker/operators/docker.py", line 467, in execute
    if self.force_pull or not self.cli.images(name=self.image):
                              ^^^^^^^^
  File "/home/airflow/.local/lib/python3.12/site-packages/airflow/providers/docker/operators/docker.py", line 341, in cli
    return self.hook.api_client
           ^^^^^^^^^^^^^^^^^^^^
  File "/usr/local/lib/python3.12/functools.py", line 998, in __get__
    val = self.func(instance)
          ^^^^^^^^^^^^^^^^^^^
  File "/home/airflow/.local/lib/python3.12/site-packages/airflow/providers/docker/hooks/docker.py", line 161, in api_client
    raise AirflowException("Failed to establish connection to any given Docker hosts.")
airflow.exceptions.AirflowException: Failed to establish connection to any given Docker hosts.
[2025-03-25T12:45:32.141+0000] {local_task_job_runner.py:266} INFO - Task exited with return code 1
[2025-03-25T12:45:32.425+0000] {taskinstance.py:3901} INFO - 0 downstream tasks scheduled from follow-on schedule check
[2025-03-25T12:45:32.444+0000] {local_task_job_runner.py:245} INFO - ::endgroup::
[2025-03-26T11:52:45.634+0000] {local_task_job_runner.py:123} INFO - ::group::Pre task execution logs
[2025-03-26T11:52:45.706+0000] {taskinstance.py:2614} INFO - Dependencies all met for dep_context=non-requeueable deps ti=<TaskInstance: containers1_dag.php_app2 scheduled__2024-03-04T00:00:00+00:00 [queued]>
[2025-03-26T11:52:45.828+0000] {taskinstance.py:2614} INFO - Dependencies all met for dep_context=requeueable deps ti=<TaskInstance: containers1_dag.php_app2 scheduled__2024-03-04T00:00:00+00:00 [queued]>
[2025-03-26T11:52:45.829+0000] {taskinstance.py:2867} INFO - Starting attempt 1 of 6
[2025-03-26T11:52:45.957+0000] {taskinstance.py:2890} INFO - Executing <Task(DockerOperator): php_app2> on 2024-03-04 00:00:00+00:00
[2025-03-26T11:52:46.007+0000] {standard_task_runner.py:104} INFO - Running: ['***', 'tasks', 'run', 'containers1_dag', 'php_app2', 'scheduled__2024-03-04T00:00:00+00:00', '--job-id', '8', '--raw', '--subdir', 'DAGS_FOLDER/containers1_dag.py', '--cfg-path', '/tmp/tmpq8ako6g6']
[2025-03-26T11:52:46.017+0000] {standard_task_runner.py:105} INFO - Job 8: Subtask php_app2
[2025-03-26T11:52:46.031+0000] {logging_mixin.py:190} WARNING - /home/***/.local/lib/python3.12/site-packages/***/task/task_runner/standard_task_runner.py:70 DeprecationWarning: This process (pid=220) is multi-threaded, use of fork() may lead to deadlocks in the child.
[2025-03-26T11:52:46.035+0000] {standard_task_runner.py:72} INFO - Started process 236 to run task
[2025-03-26T11:52:46.193+0000] {task_command.py:467} INFO - Running <TaskInstance: containers1_dag.php_app2 scheduled__2024-03-04T00:00:00+00:00 [running]> on host c0a4d7e9da1a
[2025-03-26T11:52:47.261+0000] {taskinstance.py:3134} INFO - Exporting env vars: AIRFLOW_CTX_DAG_OWNER='andre' AIRFLOW_CTX_DAG_ID='containers1_dag' AIRFLOW_CTX_TASK_ID='php_app2' AIRFLOW_CTX_EXECUTION_DATE='2024-03-04T00:00:00+00:00' AIRFLOW_CTX_TRY_NUMBER='1' AIRFLOW_CTX_DAG_RUN_ID='scheduled__2024-03-04T00:00:00+00:00'
[2025-03-26T11:52:47.262+0000] {taskinstance.py:732} INFO - ::endgroup::
[2025-03-26T11:52:47.746+0000] {docker.py:157} ERROR - Failed to establish connection to Docker host unix://var/run/docker.sock: Error while fetching server API version: ('Connection aborted.', FileNotFoundError(2, 'No such file or directory'))
[2025-03-26T11:52:48.008+0000] {taskinstance.py:3313} ERROR - Task failed with exception
Traceback (most recent call last):
  File "/home/airflow/.local/lib/python3.12/site-packages/airflow/models/taskinstance.py", line 768, in _execute_task
    result = _execute_callable(context=context, **execute_callable_kwargs)
             ^^^^^^^^^^^^^^^^^^^^^^^^^^^^^^^^^^^^^^^^^^^^^^^^^^^^^^^^^^^^^
  File "/home/airflow/.local/lib/python3.12/site-packages/airflow/models/taskinstance.py", line 734, in _execute_callable
    return ExecutionCallableRunner(
           ^^^^^^^^^^^^^^^^^^^^^^^^
  File "/home/airflow/.local/lib/python3.12/site-packages/airflow/utils/operator_helpers.py", line 252, in run
    return self.func(*args, **kwargs)
           ^^^^^^^^^^^^^^^^^^^^^^^^^^
  File "/home/airflow/.local/lib/python3.12/site-packages/airflow/models/baseoperator.py", line 424, in wrapper
    return func(self, *args, **kwargs)
           ^^^^^^^^^^^^^^^^^^^^^^^^^^^
  File "/home/airflow/.local/lib/python3.12/site-packages/airflow/providers/docker/operators/docker.py", line 467, in execute
    if self.force_pull or not self.cli.images(name=self.image):
                              ^^^^^^^^
  File "/home/airflow/.local/lib/python3.12/site-packages/airflow/providers/docker/operators/docker.py", line 341, in cli
    return self.hook.api_client
           ^^^^^^^^^^^^^^^^^^^^
  File "/usr/local/lib/python3.12/functools.py", line 998, in __get__
    val = self.func(instance)
          ^^^^^^^^^^^^^^^^^^^
  File "/home/airflow/.local/lib/python3.12/site-packages/airflow/providers/docker/hooks/docker.py", line 161, in api_client
    raise AirflowException("Failed to establish connection to any given Docker hosts.")
airflow.exceptions.AirflowException: Failed to establish connection to any given Docker hosts.
[2025-03-26T11:52:48.067+0000] {taskinstance.py:1226} INFO - Marking task as UP_FOR_RETRY. dag_id=containers1_dag, task_id=php_app2, run_id=scheduled__2024-03-04T00:00:00+00:00, execution_date=20240304T000000, start_date=20250326T115245, end_date=20250326T115248
[2025-03-26T11:52:48.335+0000] {taskinstance.py:341} INFO - ::group::Post task execution logs
[2025-03-26T11:52:48.336+0000] {standard_task_runner.py:124} ERROR - Failed to execute job 8 for task php_app2 (Failed to establish connection to any given Docker hosts.; 236)
Traceback (most recent call last):
  File "/home/airflow/.local/lib/python3.12/site-packages/airflow/task/task_runner/standard_task_runner.py", line 117, in _start_by_fork
    ret = args.func(args, dag=self.dag)
          ^^^^^^^^^^^^^^^^^^^^^^^^^^^^^
  File "/home/airflow/.local/lib/python3.12/site-packages/airflow/cli/cli_config.py", line 49, in command
    return func(*args, **kwargs)
           ^^^^^^^^^^^^^^^^^^^^^
  File "/home/airflow/.local/lib/python3.12/site-packages/airflow/utils/cli.py", line 116, in wrapper
    return f(*args, **kwargs)
           ^^^^^^^^^^^^^^^^^^
  File "/home/airflow/.local/lib/python3.12/site-packages/airflow/cli/commands/task_command.py", line 483, in task_run
    task_return_code = _run_task_by_selected_method(args, _dag, ti)
                       ^^^^^^^^^^^^^^^^^^^^^^^^^^^^^^^^^^^^^^^^^^^^
  File "/home/airflow/.local/lib/python3.12/site-packages/airflow/cli/commands/task_command.py", line 256, in _run_task_by_selected_method
    return _run_raw_task(args, ti)
           ^^^^^^^^^^^^^^^^^^^^^^^
  File "/home/airflow/.local/lib/python3.12/site-packages/airflow/cli/commands/task_command.py", line 341, in _run_raw_task
    return ti._run_raw_task(
           ^^^^^^^^^^^^^^^^^
  File "/home/airflow/.local/lib/python3.12/site-packages/airflow/utils/session.py", line 97, in wrapper
    return func(*args, session=session, **kwargs)
           ^^^^^^^^^^^^^^^^^^^^^^^^^^^^^^^^^^^^^^
  File "/home/airflow/.local/lib/python3.12/site-packages/airflow/models/taskinstance.py", line 3006, in _run_raw_task
    return _run_raw_task(
           ^^^^^^^^^^^^^^
  File "/home/airflow/.local/lib/python3.12/site-packages/airflow/models/taskinstance.py", line 274, in _run_raw_task
    TaskInstance._execute_task_with_callbacks(
  File "/home/airflow/.local/lib/python3.12/site-packages/airflow/models/taskinstance.py", line 3161, in _execute_task_with_callbacks
    result = self._execute_task(context, task_orig)
             ^^^^^^^^^^^^^^^^^^^^^^^^^^^^^^^^^^^^^^
  File "/home/airflow/.local/lib/python3.12/site-packages/airflow/models/taskinstance.py", line 3185, in _execute_task
    return _execute_task(self, context, task_orig)
           ^^^^^^^^^^^^^^^^^^^^^^^^^^^^^^^^^^^^^^^
  File "/home/airflow/.local/lib/python3.12/site-packages/airflow/models/taskinstance.py", line 768, in _execute_task
    result = _execute_callable(context=context, **execute_callable_kwargs)
             ^^^^^^^^^^^^^^^^^^^^^^^^^^^^^^^^^^^^^^^^^^^^^^^^^^^^^^^^^^^^^
  File "/home/airflow/.local/lib/python3.12/site-packages/airflow/models/taskinstance.py", line 734, in _execute_callable
    return ExecutionCallableRunner(
           ^^^^^^^^^^^^^^^^^^^^^^^^
  File "/home/airflow/.local/lib/python3.12/site-packages/airflow/utils/operator_helpers.py", line 252, in run
    return self.func(*args, **kwargs)
           ^^^^^^^^^^^^^^^^^^^^^^^^^^
  File "/home/airflow/.local/lib/python3.12/site-packages/airflow/models/baseoperator.py", line 424, in wrapper
    return func(self, *args, **kwargs)
           ^^^^^^^^^^^^^^^^^^^^^^^^^^^
  File "/home/airflow/.local/lib/python3.12/site-packages/airflow/providers/docker/operators/docker.py", line 467, in execute
    if self.force_pull or not self.cli.images(name=self.image):
                              ^^^^^^^^
  File "/home/airflow/.local/lib/python3.12/site-packages/airflow/providers/docker/operators/docker.py", line 341, in cli
    return self.hook.api_client
           ^^^^^^^^^^^^^^^^^^^^
  File "/usr/local/lib/python3.12/functools.py", line 998, in __get__
    val = self.func(instance)
          ^^^^^^^^^^^^^^^^^^^
  File "/home/airflow/.local/lib/python3.12/site-packages/airflow/providers/docker/hooks/docker.py", line 161, in api_client
    raise AirflowException("Failed to establish connection to any given Docker hosts.")
airflow.exceptions.AirflowException: Failed to establish connection to any given Docker hosts.
[2025-03-26T11:52:48.416+0000] {local_task_job_runner.py:266} INFO - Task exited with return code 1
[2025-03-26T11:52:48.661+0000] {taskinstance.py:3901} INFO - 0 downstream tasks scheduled from follow-on schedule check
[2025-03-26T11:52:48.715+0000] {local_task_job_runner.py:245} INFO - ::endgroup::
[2025-03-26T13:18:06.900+0000] {local_task_job_runner.py:123} INFO - ::group::Pre task execution logs
[2025-03-26T13:18:06.969+0000] {taskinstance.py:2614} INFO - Dependencies all met for dep_context=non-requeueable deps ti=<TaskInstance: containers1_dag.php_app2 scheduled__2024-03-04T00:00:00+00:00 [queued]>
[2025-03-26T13:18:06.997+0000] {taskinstance.py:2614} INFO - Dependencies all met for dep_context=requeueable deps ti=<TaskInstance: containers1_dag.php_app2 scheduled__2024-03-04T00:00:00+00:00 [queued]>
[2025-03-26T13:18:06.998+0000] {taskinstance.py:2867} INFO - Starting attempt 1 of 6
[2025-03-26T13:18:07.190+0000] {taskinstance.py:2890} INFO - Executing <Task(DockerOperator): php_app2> on 2024-03-04 00:00:00+00:00
[2025-03-26T13:18:07.246+0000] {logging_mixin.py:190} WARNING - /home/***/.local/lib/python3.12/site-packages/***/task/task_runner/standard_task_runner.py:70 DeprecationWarning: This process (pid=1245) is multi-threaded, use of fork() may lead to deadlocks in the child.
[2025-03-26T13:18:07.247+0000] {standard_task_runner.py:72} INFO - Started process 1263 to run task
[2025-03-26T13:18:07.232+0000] {standard_task_runner.py:104} INFO - Running: ['***', 'tasks', 'run', 'containers1_dag', 'php_app2', 'scheduled__2024-03-04T00:00:00+00:00', '--job-id', '9', '--raw', '--subdir', 'DAGS_FOLDER/containers1_dag.py', '--cfg-path', '/tmp/tmpzknje1ei']
[2025-03-26T13:18:07.251+0000] {standard_task_runner.py:105} INFO - Job 9: Subtask php_app2
[2025-03-26T13:18:07.758+0000] {task_command.py:467} INFO - Running <TaskInstance: containers1_dag.php_app2 scheduled__2024-03-04T00:00:00+00:00 [running]> on host f731374053d7
[2025-03-26T13:18:08.696+0000] {taskinstance.py:3134} INFO - Exporting env vars: AIRFLOW_CTX_DAG_OWNER='andre' AIRFLOW_CTX_DAG_ID='containers1_dag' AIRFLOW_CTX_TASK_ID='php_app2' AIRFLOW_CTX_EXECUTION_DATE='2024-03-04T00:00:00+00:00' AIRFLOW_CTX_TRY_NUMBER='1' AIRFLOW_CTX_DAG_RUN_ID='scheduled__2024-03-04T00:00:00+00:00'
[2025-03-26T13:18:08.697+0000] {taskinstance.py:732} INFO - ::endgroup::
[2025-03-26T13:18:08.806+0000] {docker.py:157} ERROR - Failed to establish connection to Docker host unix://var/run/docker.sock: Error while fetching server API version: ('Connection aborted.', PermissionError(13, 'Permission denied'))
[2025-03-26T13:18:08.949+0000] {taskinstance.py:3313} ERROR - Task failed with exception
Traceback (most recent call last):
  File "/home/airflow/.local/lib/python3.12/site-packages/airflow/models/taskinstance.py", line 768, in _execute_task
    result = _execute_callable(context=context, **execute_callable_kwargs)
             ^^^^^^^^^^^^^^^^^^^^^^^^^^^^^^^^^^^^^^^^^^^^^^^^^^^^^^^^^^^^^
  File "/home/airflow/.local/lib/python3.12/site-packages/airflow/models/taskinstance.py", line 734, in _execute_callable
    return ExecutionCallableRunner(
           ^^^^^^^^^^^^^^^^^^^^^^^^
  File "/home/airflow/.local/lib/python3.12/site-packages/airflow/utils/operator_helpers.py", line 252, in run
    return self.func(*args, **kwargs)
           ^^^^^^^^^^^^^^^^^^^^^^^^^^
  File "/home/airflow/.local/lib/python3.12/site-packages/airflow/models/baseoperator.py", line 424, in wrapper
    return func(self, *args, **kwargs)
           ^^^^^^^^^^^^^^^^^^^^^^^^^^^
  File "/home/airflow/.local/lib/python3.12/site-packages/airflow/providers/docker/operators/docker.py", line 467, in execute
    if self.force_pull or not self.cli.images(name=self.image):
                              ^^^^^^^^
  File "/home/airflow/.local/lib/python3.12/site-packages/airflow/providers/docker/operators/docker.py", line 341, in cli
    return self.hook.api_client
           ^^^^^^^^^^^^^^^^^^^^
  File "/usr/local/lib/python3.12/functools.py", line 998, in __get__
    val = self.func(instance)
          ^^^^^^^^^^^^^^^^^^^
  File "/home/airflow/.local/lib/python3.12/site-packages/airflow/providers/docker/hooks/docker.py", line 161, in api_client
    raise AirflowException("Failed to establish connection to any given Docker hosts.")
airflow.exceptions.AirflowException: Failed to establish connection to any given Docker hosts.
[2025-03-26T13:18:09.029+0000] {taskinstance.py:1226} INFO - Marking task as UP_FOR_RETRY. dag_id=containers1_dag, task_id=php_app2, run_id=scheduled__2024-03-04T00:00:00+00:00, execution_date=20240304T000000, start_date=20250326T131806, end_date=20250326T131809
[2025-03-26T13:18:09.269+0000] {taskinstance.py:341} INFO - ::group::Post task execution logs
[2025-03-26T13:18:09.270+0000] {standard_task_runner.py:124} ERROR - Failed to execute job 9 for task php_app2 (Failed to establish connection to any given Docker hosts.; 1263)
Traceback (most recent call last):
  File "/home/airflow/.local/lib/python3.12/site-packages/airflow/task/task_runner/standard_task_runner.py", line 117, in _start_by_fork
    ret = args.func(args, dag=self.dag)
          ^^^^^^^^^^^^^^^^^^^^^^^^^^^^^
  File "/home/airflow/.local/lib/python3.12/site-packages/airflow/cli/cli_config.py", line 49, in command
    return func(*args, **kwargs)
           ^^^^^^^^^^^^^^^^^^^^^
  File "/home/airflow/.local/lib/python3.12/site-packages/airflow/utils/cli.py", line 116, in wrapper
    return f(*args, **kwargs)
           ^^^^^^^^^^^^^^^^^^
  File "/home/airflow/.local/lib/python3.12/site-packages/airflow/cli/commands/task_command.py", line 483, in task_run
    task_return_code = _run_task_by_selected_method(args, _dag, ti)
                       ^^^^^^^^^^^^^^^^^^^^^^^^^^^^^^^^^^^^^^^^^^^^
  File "/home/airflow/.local/lib/python3.12/site-packages/airflow/cli/commands/task_command.py", line 256, in _run_task_by_selected_method
    return _run_raw_task(args, ti)
           ^^^^^^^^^^^^^^^^^^^^^^^
  File "/home/airflow/.local/lib/python3.12/site-packages/airflow/cli/commands/task_command.py", line 341, in _run_raw_task
    return ti._run_raw_task(
           ^^^^^^^^^^^^^^^^^
  File "/home/airflow/.local/lib/python3.12/site-packages/airflow/utils/session.py", line 97, in wrapper
    return func(*args, session=session, **kwargs)
           ^^^^^^^^^^^^^^^^^^^^^^^^^^^^^^^^^^^^^^
  File "/home/airflow/.local/lib/python3.12/site-packages/airflow/models/taskinstance.py", line 3006, in _run_raw_task
    return _run_raw_task(
           ^^^^^^^^^^^^^^
  File "/home/airflow/.local/lib/python3.12/site-packages/airflow/models/taskinstance.py", line 274, in _run_raw_task
    TaskInstance._execute_task_with_callbacks(
  File "/home/airflow/.local/lib/python3.12/site-packages/airflow/models/taskinstance.py", line 3161, in _execute_task_with_callbacks
    result = self._execute_task(context, task_orig)
             ^^^^^^^^^^^^^^^^^^^^^^^^^^^^^^^^^^^^^^
  File "/home/airflow/.local/lib/python3.12/site-packages/airflow/models/taskinstance.py", line 3185, in _execute_task
    return _execute_task(self, context, task_orig)
           ^^^^^^^^^^^^^^^^^^^^^^^^^^^^^^^^^^^^^^^
  File "/home/airflow/.local/lib/python3.12/site-packages/airflow/models/taskinstance.py", line 768, in _execute_task
    result = _execute_callable(context=context, **execute_callable_kwargs)
             ^^^^^^^^^^^^^^^^^^^^^^^^^^^^^^^^^^^^^^^^^^^^^^^^^^^^^^^^^^^^^
  File "/home/airflow/.local/lib/python3.12/site-packages/airflow/models/taskinstance.py", line 734, in _execute_callable
    return ExecutionCallableRunner(
           ^^^^^^^^^^^^^^^^^^^^^^^^
  File "/home/airflow/.local/lib/python3.12/site-packages/airflow/utils/operator_helpers.py", line 252, in run
    return self.func(*args, **kwargs)
           ^^^^^^^^^^^^^^^^^^^^^^^^^^
  File "/home/airflow/.local/lib/python3.12/site-packages/airflow/models/baseoperator.py", line 424, in wrapper
    return func(self, *args, **kwargs)
           ^^^^^^^^^^^^^^^^^^^^^^^^^^^
  File "/home/airflow/.local/lib/python3.12/site-packages/airflow/providers/docker/operators/docker.py", line 467, in execute
    if self.force_pull or not self.cli.images(name=self.image):
                              ^^^^^^^^
  File "/home/airflow/.local/lib/python3.12/site-packages/airflow/providers/docker/operators/docker.py", line 341, in cli
    return self.hook.api_client
           ^^^^^^^^^^^^^^^^^^^^
  File "/usr/local/lib/python3.12/functools.py", line 998, in __get__
    val = self.func(instance)
          ^^^^^^^^^^^^^^^^^^^
  File "/home/airflow/.local/lib/python3.12/site-packages/airflow/providers/docker/hooks/docker.py", line 161, in api_client
    raise AirflowException("Failed to establish connection to any given Docker hosts.")
airflow.exceptions.AirflowException: Failed to establish connection to any given Docker hosts.
[2025-03-26T13:18:09.429+0000] {local_task_job_runner.py:266} INFO - Task exited with return code 1
[2025-03-26T13:18:09.503+0000] {local_task_job_runner.py:245} INFO - ::endgroup::
[2025-03-26T13:38:19.433+0000] {local_task_job_runner.py:123} INFO - ::group::Pre task execution logs
[2025-03-26T13:38:19.603+0000] {taskinstance.py:2614} INFO - Dependencies all met for dep_context=non-requeueable deps ti=<TaskInstance: containers1_dag.php_app2 scheduled__2024-03-04T00:00:00+00:00 [queued]>
[2025-03-26T13:38:19.764+0000] {taskinstance.py:2614} INFO - Dependencies all met for dep_context=requeueable deps ti=<TaskInstance: containers1_dag.php_app2 scheduled__2024-03-04T00:00:00+00:00 [queued]>
[2025-03-26T13:38:19.766+0000] {taskinstance.py:2867} INFO - Starting attempt 1 of 6
[2025-03-26T13:38:20.073+0000] {taskinstance.py:2890} INFO - Executing <Task(DockerOperator): php_app2> on 2024-03-04 00:00:00+00:00
[2025-03-26T13:38:20.137+0000] {logging_mixin.py:190} WARNING - /home/***/.local/lib/python3.12/site-packages/***/task/task_runner/standard_task_runner.py:70 DeprecationWarning: This process (pid=252) is multi-threaded, use of fork() may lead to deadlocks in the child.
[2025-03-26T13:38:20.147+0000] {standard_task_runner.py:72} INFO - Started process 270 to run task
[2025-03-26T13:38:20.144+0000] {standard_task_runner.py:104} INFO - Running: ['***', 'tasks', 'run', 'containers1_dag', 'php_app2', 'scheduled__2024-03-04T00:00:00+00:00', '--job-id', '9', '--raw', '--subdir', 'DAGS_FOLDER/containers1_dag.py', '--cfg-path', '/tmp/tmppsw5th9k']
[2025-03-26T13:38:20.161+0000] {standard_task_runner.py:105} INFO - Job 9: Subtask php_app2
[2025-03-26T13:38:20.649+0000] {task_command.py:467} INFO - Running <TaskInstance: containers1_dag.php_app2 scheduled__2024-03-04T00:00:00+00:00 [running]> on host 3d581a580455
[2025-03-26T13:38:22.383+0000] {taskinstance.py:3134} INFO - Exporting env vars: AIRFLOW_CTX_DAG_OWNER='andre' AIRFLOW_CTX_DAG_ID='containers1_dag' AIRFLOW_CTX_TASK_ID='php_app2' AIRFLOW_CTX_EXECUTION_DATE='2024-03-04T00:00:00+00:00' AIRFLOW_CTX_TRY_NUMBER='1' AIRFLOW_CTX_DAG_RUN_ID='scheduled__2024-03-04T00:00:00+00:00'
[2025-03-26T13:38:22.386+0000] {taskinstance.py:732} INFO - ::endgroup::
[2025-03-26T13:38:22.717+0000] {docker.py:345} INFO - Starting docker container from image php-app2
[2025-03-26T13:38:22.746+0000] {docker.py:353} WARNING - Using remote engine or docker-in-docker and mounting temporary volume from host is not supported. Falling back to `mount_tmp_dir=False` mode. You can set `mount_tmp_dir` parameter to False to disable mounting and remove the warning
[2025-03-26T13:38:25.704+0000] {docker.py:69} INFO - array(11) {
[2025-03-26T13:38:25.712+0000] {docker.py:69} INFO -   [0]=>
[2025-03-26T13:38:25.713+0000] {docker.py:69} INFO -   object(stdClass)#2 (3) {
[2025-03-26T13:38:25.716+0000] {docker.py:69} INFO -     ["contador"]=>
[2025-03-26T13:38:25.717+0000] {docker.py:69} INFO -     int(0)
[2025-03-26T13:38:25.717+0000] {docker.py:69} INFO -     ["container"]=>
[2025-03-26T13:38:25.718+0000] {docker.py:69} INFO -     string(8) "php-app1"
[2025-03-26T13:38:25.718+0000] {docker.py:69} INFO -     ["timestamp"]=>
[2025-03-26T13:38:25.719+0000] {docker.py:69} INFO -     int(1742852307)
[2025-03-26T13:38:25.720+0000] {docker.py:69} INFO -   }
[2025-03-26T13:38:25.720+0000] {docker.py:69} INFO -   [1]=>
[2025-03-26T13:38:25.721+0000] {docker.py:69} INFO -   object(stdClass)#3 (3) {
[2025-03-26T13:38:25.721+0000] {docker.py:69} INFO -     ["contador"]=>
[2025-03-26T13:38:25.722+0000] {docker.py:69} INFO -     int(1)
[2025-03-26T13:38:25.722+0000] {docker.py:69} INFO -     ["container"]=>
[2025-03-26T13:38:25.722+0000] {docker.py:69} INFO -     string(8) "php-app2"
[2025-03-26T13:38:25.723+0000] {docker.py:69} INFO -     ["timestamp"]=>
[2025-03-26T13:38:25.724+0000] {docker.py:69} INFO -     int(1742852309)
[2025-03-26T13:38:25.724+0000] {docker.py:69} INFO -   }
[2025-03-26T13:38:25.725+0000] {docker.py:69} INFO -   [2]=>
[2025-03-26T13:38:25.725+0000] {docker.py:69} INFO -   object(stdClass)#4 (3) {
[2025-03-26T13:38:25.726+0000] {docker.py:69} INFO -     ["contador"]=>
[2025-03-26T13:38:25.726+0000] {docker.py:69} INFO -     int(1)
[2025-03-26T13:38:25.727+0000] {docker.py:69} INFO -     ["container"]=>
[2025-03-26T13:38:25.727+0000] {docker.py:69} INFO -     string(8) "php-app1"
[2025-03-26T13:38:25.728+0000] {docker.py:69} INFO -     ["timestamp"]=>
[2025-03-26T13:38:25.728+0000] {docker.py:69} INFO -     int(1742852311)
[2025-03-26T13:38:25.728+0000] {docker.py:69} INFO -   }
[2025-03-26T13:38:25.729+0000] {docker.py:69} INFO -   [3]=>
[2025-03-26T13:38:25.729+0000] {docker.py:69} INFO -   object(stdClass)#5 (3) {
[2025-03-26T13:38:25.730+0000] {docker.py:69} INFO -     ["contador"]=>
[2025-03-26T13:38:25.730+0000] {docker.py:69} INFO -     int(1)
[2025-03-26T13:38:25.731+0000] {docker.py:69} INFO -     ["container"]=>
[2025-03-26T13:38:25.731+0000] {docker.py:69} INFO -     string(8) "php-app2"
[2025-03-26T13:38:25.732+0000] {docker.py:69} INFO -     ["timestamp"]=>
[2025-03-26T13:38:25.734+0000] {docker.py:69} INFO -     int(1742852314)
[2025-03-26T13:38:25.736+0000] {docker.py:69} INFO -   }
[2025-03-26T13:38:25.737+0000] {docker.py:69} INFO -   [4]=>
[2025-03-26T13:38:25.738+0000] {docker.py:69} INFO -   object(stdClass)#6 (3) {
[2025-03-26T13:38:25.740+0000] {docker.py:69} INFO -     ["contador"]=>
[2025-03-26T13:38:25.740+0000] {docker.py:69} INFO -     int(1)
[2025-03-26T13:38:25.741+0000] {docker.py:69} INFO -     ["container"]=>
[2025-03-26T13:38:25.741+0000] {docker.py:69} INFO -     string(8) "php-app2"
[2025-03-26T13:38:25.745+0000] {docker.py:69} INFO -     ["timestamp"]=>
[2025-03-26T13:38:25.746+0000] {docker.py:69} INFO -     int(1742996301)
[2025-03-26T13:38:25.746+0000] {docker.py:69} INFO -   }
[2025-03-26T13:38:25.747+0000] {docker.py:69} INFO -   [5]=>
[2025-03-26T13:38:25.747+0000] {docker.py:69} INFO -   object(stdClass)#7 (3) {
[2025-03-26T13:38:25.747+0000] {docker.py:69} INFO -     ["contador"]=>
[2025-03-26T13:38:25.748+0000] {docker.py:69} INFO -     int(1)
[2025-03-26T13:38:25.749+0000] {docker.py:69} INFO -     ["container"]=>
[2025-03-26T13:38:25.749+0000] {docker.py:69} INFO -     string(8) "php-app1"
[2025-03-26T13:38:25.750+0000] {docker.py:69} INFO -     ["timestamp"]=>
[2025-03-26T13:38:25.750+0000] {docker.py:69} INFO -     int(1742996302)
[2025-03-26T13:38:25.751+0000] {docker.py:69} INFO -   }
[2025-03-26T13:38:25.751+0000] {docker.py:69} INFO -   [6]=>
[2025-03-26T13:38:25.752+0000] {docker.py:69} INFO -   object(stdClass)#8 (3) {
[2025-03-26T13:38:25.752+0000] {docker.py:69} INFO -     ["contador"]=>
[2025-03-26T13:38:25.753+0000] {docker.py:69} INFO -     int(1)
[2025-03-26T13:38:25.753+0000] {docker.py:69} INFO -     ["container"]=>
[2025-03-26T13:38:25.754+0000] {docker.py:69} INFO -     string(8) "php-app1"
[2025-03-26T13:38:25.754+0000] {docker.py:69} INFO -     ["timestamp"]=>
[2025-03-26T13:38:25.754+0000] {docker.py:69} INFO -     int(1742996302)
[2025-03-26T13:38:25.755+0000] {docker.py:69} INFO -   }
[2025-03-26T13:38:25.755+0000] {docker.py:69} INFO -   [7]=>
[2025-03-26T13:38:25.760+0000] {docker.py:69} INFO -   object(stdClass)#9 (3) {
[2025-03-26T13:38:25.829+0000] {docker.py:69} INFO -     ["contador"]=>
[2025-03-26T13:38:25.829+0000] {docker.py:69} INFO -     int(1)
[2025-03-26T13:38:25.830+0000] {docker.py:69} INFO -     ["container"]=>
[2025-03-26T13:38:25.830+0000] {docker.py:69} INFO -     string(8) "php-app2"
[2025-03-26T13:38:25.831+0000] {docker.py:69} INFO -     ["timestamp"]=>
[2025-03-26T13:38:25.927+0000] {docker.py:69} INFO -     int(1742996303)
[2025-03-26T13:38:25.927+0000] {docker.py:69} INFO -   }
[2025-03-26T13:38:25.927+0000] {docker.py:69} INFO -   [8]=>
[2025-03-26T13:38:25.928+0000] {docker.py:69} INFO -   object(stdClass)#10 (3) {
[2025-03-26T13:38:25.928+0000] {docker.py:69} INFO -     ["contador"]=>
[2025-03-26T13:38:25.929+0000] {docker.py:69} INFO -     int(1)
[2025-03-26T13:38:25.929+0000] {docker.py:69} INFO -     ["container"]=>
[2025-03-26T13:38:25.930+0000] {docker.py:69} INFO -     string(8) "php-app1"
[2025-03-26T13:38:25.930+0000] {docker.py:69} INFO -     ["timestamp"]=>
[2025-03-26T13:38:25.930+0000] {docker.py:69} INFO -     int(1742996304)
[2025-03-26T13:38:25.931+0000] {docker.py:69} INFO -   }
[2025-03-26T13:38:25.931+0000] {docker.py:69} INFO -   [9]=>
[2025-03-26T13:38:25.932+0000] {docker.py:69} INFO -   object(stdClass)#11 (3) {
[2025-03-26T13:38:25.932+0000] {docker.py:69} INFO -     ["contador"]=>
[2025-03-26T13:38:25.933+0000] {docker.py:69} INFO -     int(1)
[2025-03-26T13:38:25.933+0000] {docker.py:69} INFO -     ["container"]=>
[2025-03-26T13:38:25.934+0000] {docker.py:69} INFO -     string(8) "php-app2"
[2025-03-26T13:38:25.934+0000] {docker.py:69} INFO -     ["timestamp"]=>
[2025-03-26T13:38:25.934+0000] {docker.py:69} INFO -     int(1742996305)
[2025-03-26T13:38:25.935+0000] {docker.py:69} INFO -   }
[2025-03-26T13:38:25.935+0000] {docker.py:69} INFO -   [10]=>
[2025-03-26T13:38:25.936+0000] {docker.py:69} INFO -   array(3) {
[2025-03-26T13:38:25.936+0000] {docker.py:69} INFO -     ["contador"]=>
[2025-03-26T13:38:25.936+0000] {docker.py:69} INFO -     int(1)
[2025-03-26T13:38:25.937+0000] {docker.py:69} INFO -     ["container"]=>
[2025-03-26T13:38:25.937+0000] {docker.py:69} INFO -     string(8) "php-app2"
[2025-03-26T13:38:25.938+0000] {docker.py:69} INFO -     ["timestamp"]=>
[2025-03-26T13:38:25.938+0000] {docker.py:69} INFO -     int(1742996305)
[2025-03-26T13:38:25.938+0000] {docker.py:69} INFO -   }
[2025-03-26T13:38:25.939+0000] {docker.py:69} INFO - }
[2025-03-26T13:38:28.520+0000] {taskinstance.py:341} INFO - ::group::Post task execution logs
[2025-03-26T13:38:28.523+0000] {taskinstance.py:353} INFO - Marking task as SUCCESS. dag_id=containers1_dag, task_id=php_app2, run_id=scheduled__2024-03-04T00:00:00+00:00, execution_date=20240304T000000, start_date=20250326T133819, end_date=20250326T133828
[2025-03-26T13:38:28.965+0000] {local_task_job_runner.py:266} INFO - Task exited with return code 0
[2025-03-26T13:38:29.071+0000] {taskinstance.py:3901} INFO - 0 downstream tasks scheduled from follow-on schedule check
[2025-03-26T13:38:29.226+0000] {local_task_job_runner.py:245} INFO - ::endgroup::
