[2025-03-24T22:19:13.314+0000] {local_task_job_runner.py:123} INFO - ::group::Pre task execution logs
[2025-03-24T22:19:13.367+0000] {taskinstance.py:2614} INFO - Dependencies all met for dep_context=non-requeueable deps ti=<TaskInstance: containers1_dag.php_app1 scheduled__2024-03-16T00:00:00+00:00 [queued]>
[2025-03-24T22:19:13.404+0000] {taskinstance.py:2614} INFO - Dependencies all met for dep_context=requeueable deps ti=<TaskInstance: containers1_dag.php_app1 scheduled__2024-03-16T00:00:00+00:00 [queued]>
[2025-03-24T22:19:13.404+0000] {taskinstance.py:2867} INFO - Starting attempt 1 of 6
[2025-03-24T22:19:13.455+0000] {taskinstance.py:2890} INFO - Executing <Task(BashOperator): php_app1> on 2024-03-16 00:00:00+00:00
[2025-03-24T22:19:13.472+0000] {logging_mixin.py:190} WARNING - /home/***/.local/lib/python3.12/site-packages/***/task/task_runner/standard_task_runner.py:70 DeprecationWarning: This process (pid=4912) is multi-threaded, use of fork() may lead to deadlocks in the child.
[2025-03-24T22:19:13.479+0000] {standard_task_runner.py:72} INFO - Started process 4919 to run task
[2025-03-24T22:19:13.475+0000] {standard_task_runner.py:104} INFO - Running: ['***', 'tasks', 'run', 'containers1_dag', 'php_app1', 'scheduled__2024-03-16T00:00:00+00:00', '--job-id', '126', '--raw', '--subdir', 'DAGS_FOLDER/containers1_dag.py', '--cfg-path', '/tmp/tmp34x954nx']
[2025-03-24T22:19:13.480+0000] {standard_task_runner.py:105} INFO - Job 126: Subtask php_app1
[2025-03-24T22:19:13.604+0000] {task_command.py:467} INFO - Running <TaskInstance: containers1_dag.php_app1 scheduled__2024-03-16T00:00:00+00:00 [running]> on host b9050090f7f5
[2025-03-24T22:19:13.796+0000] {taskinstance.py:3134} INFO - Exporting env vars: AIRFLOW_CTX_DAG_OWNER='andreeppinghaus' AIRFLOW_CTX_DAG_ID='containers1_dag' AIRFLOW_CTX_TASK_ID='php_app1' AIRFLOW_CTX_EXECUTION_DATE='2024-03-16T00:00:00+00:00' AIRFLOW_CTX_TRY_NUMBER='1' AIRFLOW_CTX_DAG_RUN_ID='scheduled__2024-03-16T00:00:00+00:00'
[2025-03-24T22:19:13.797+0000] {taskinstance.py:732} INFO - ::endgroup::
[2025-03-24T22:19:13.820+0000] {subprocess.py:78} INFO - Tmp dir root location: /tmp
[2025-03-24T22:19:13.821+0000] {subprocess.py:88} INFO - Running command: ['/usr/bin/bash', '-c', 'sudo docker run -v $(pwd)/../in:/usr/src/app/in -v $(pwd):/usr/src/app php-app1']
[2025-03-24T22:19:13.838+0000] {subprocess.py:99} INFO - Output:
[2025-03-24T22:19:13.850+0000] {subprocess.py:106} INFO - sudo: a terminal is required to read the password; either use the -S option to read from standard input or configure an askpass helper
[2025-03-24T22:19:13.851+0000] {subprocess.py:106} INFO - sudo: a password is required
[2025-03-24T22:19:13.852+0000] {subprocess.py:110} INFO - Command exited with return code 1
[2025-03-24T22:19:13.865+0000] {taskinstance.py:3313} ERROR - Task failed with exception
Traceback (most recent call last):
  File "/home/airflow/.local/lib/python3.12/site-packages/airflow/models/taskinstance.py", line 768, in _execute_task
    result = _execute_callable(context=context, **execute_callable_kwargs)
             ^^^^^^^^^^^^^^^^^^^^^^^^^^^^^^^^^^^^^^^^^^^^^^^^^^^^^^^^^^^^^
  File "/home/airflow/.local/lib/python3.12/site-packages/airflow/models/taskinstance.py", line 734, in _execute_callable
    return ExecutionCallableRunner(
           ^^^^^^^^^^^^^^^^^^^^^^^^
  File "/home/airflow/.local/lib/python3.12/site-packages/airflow/utils/operator_helpers.py", line 252, in run
    return self.func(*args, **kwargs)
           ^^^^^^^^^^^^^^^^^^^^^^^^^^
  File "/home/airflow/.local/lib/python3.12/site-packages/airflow/models/baseoperator.py", line 424, in wrapper
    return func(self, *args, **kwargs)
           ^^^^^^^^^^^^^^^^^^^^^^^^^^^
  File "/home/airflow/.local/lib/python3.12/site-packages/airflow/operators/bash.py", line 276, in execute
    raise AirflowException(
airflow.exceptions.AirflowException: Bash command failed. The command returned a non-zero exit code 1.
[2025-03-24T22:19:13.878+0000] {taskinstance.py:1226} INFO - Marking task as UP_FOR_RETRY. dag_id=containers1_dag, task_id=php_app1, run_id=scheduled__2024-03-16T00:00:00+00:00, execution_date=20240316T000000, start_date=20250324T221913, end_date=20250324T221913
[2025-03-24T22:19:13.925+0000] {taskinstance.py:341} INFO - ::group::Post task execution logs
[2025-03-24T22:19:13.926+0000] {standard_task_runner.py:124} ERROR - Failed to execute job 126 for task php_app1 (Bash command failed. The command returned a non-zero exit code 1.; 4919)
Traceback (most recent call last):
  File "/home/airflow/.local/lib/python3.12/site-packages/airflow/task/task_runner/standard_task_runner.py", line 117, in _start_by_fork
    ret = args.func(args, dag=self.dag)
          ^^^^^^^^^^^^^^^^^^^^^^^^^^^^^
  File "/home/airflow/.local/lib/python3.12/site-packages/airflow/cli/cli_config.py", line 49, in command
    return func(*args, **kwargs)
           ^^^^^^^^^^^^^^^^^^^^^
  File "/home/airflow/.local/lib/python3.12/site-packages/airflow/utils/cli.py", line 116, in wrapper
    return f(*args, **kwargs)
           ^^^^^^^^^^^^^^^^^^
  File "/home/airflow/.local/lib/python3.12/site-packages/airflow/cli/commands/task_command.py", line 483, in task_run
    task_return_code = _run_task_by_selected_method(args, _dag, ti)
                       ^^^^^^^^^^^^^^^^^^^^^^^^^^^^^^^^^^^^^^^^^^^^
  File "/home/airflow/.local/lib/python3.12/site-packages/airflow/cli/commands/task_command.py", line 256, in _run_task_by_selected_method
    return _run_raw_task(args, ti)
           ^^^^^^^^^^^^^^^^^^^^^^^
  File "/home/airflow/.local/lib/python3.12/site-packages/airflow/cli/commands/task_command.py", line 341, in _run_raw_task
    return ti._run_raw_task(
           ^^^^^^^^^^^^^^^^^
  File "/home/airflow/.local/lib/python3.12/site-packages/airflow/utils/session.py", line 97, in wrapper
    return func(*args, session=session, **kwargs)
           ^^^^^^^^^^^^^^^^^^^^^^^^^^^^^^^^^^^^^^
  File "/home/airflow/.local/lib/python3.12/site-packages/airflow/models/taskinstance.py", line 3006, in _run_raw_task
    return _run_raw_task(
           ^^^^^^^^^^^^^^
  File "/home/airflow/.local/lib/python3.12/site-packages/airflow/models/taskinstance.py", line 274, in _run_raw_task
    TaskInstance._execute_task_with_callbacks(
  File "/home/airflow/.local/lib/python3.12/site-packages/airflow/models/taskinstance.py", line 3161, in _execute_task_with_callbacks
    result = self._execute_task(context, task_orig)
             ^^^^^^^^^^^^^^^^^^^^^^^^^^^^^^^^^^^^^^
  File "/home/airflow/.local/lib/python3.12/site-packages/airflow/models/taskinstance.py", line 3185, in _execute_task
    return _execute_task(self, context, task_orig)
           ^^^^^^^^^^^^^^^^^^^^^^^^^^^^^^^^^^^^^^^
  File "/home/airflow/.local/lib/python3.12/site-packages/airflow/models/taskinstance.py", line 768, in _execute_task
    result = _execute_callable(context=context, **execute_callable_kwargs)
             ^^^^^^^^^^^^^^^^^^^^^^^^^^^^^^^^^^^^^^^^^^^^^^^^^^^^^^^^^^^^^
  File "/home/airflow/.local/lib/python3.12/site-packages/airflow/models/taskinstance.py", line 734, in _execute_callable
    return ExecutionCallableRunner(
           ^^^^^^^^^^^^^^^^^^^^^^^^
  File "/home/airflow/.local/lib/python3.12/site-packages/airflow/utils/operator_helpers.py", line 252, in run
    return self.func(*args, **kwargs)
           ^^^^^^^^^^^^^^^^^^^^^^^^^^
  File "/home/airflow/.local/lib/python3.12/site-packages/airflow/models/baseoperator.py", line 424, in wrapper
    return func(self, *args, **kwargs)
           ^^^^^^^^^^^^^^^^^^^^^^^^^^^
  File "/home/airflow/.local/lib/python3.12/site-packages/airflow/operators/bash.py", line 276, in execute
    raise AirflowException(
airflow.exceptions.AirflowException: Bash command failed. The command returned a non-zero exit code 1.
[2025-03-24T22:19:13.977+0000] {local_task_job_runner.py:266} INFO - Task exited with return code 1
[2025-03-24T22:19:14.008+0000] {taskinstance.py:3901} INFO - 0 downstream tasks scheduled from follow-on schedule check
[2025-03-24T22:19:14.016+0000] {local_task_job_runner.py:245} INFO - ::endgroup::
[2025-03-25T00:18:43.880+0000] {local_task_job_runner.py:123} INFO - ::group::Pre task execution logs
[2025-03-25T00:18:43.956+0000] {taskinstance.py:2614} INFO - Dependencies all met for dep_context=non-requeueable deps ti=<TaskInstance: containers1_dag.php_app1 scheduled__2024-03-16T00:00:00+00:00 [queued]>
[2025-03-25T00:18:43.981+0000] {taskinstance.py:2614} INFO - Dependencies all met for dep_context=requeueable deps ti=<TaskInstance: containers1_dag.php_app1 scheduled__2024-03-16T00:00:00+00:00 [queued]>
[2025-03-25T00:18:43.981+0000] {taskinstance.py:2867} INFO - Starting attempt 1 of 6
[2025-03-25T00:18:44.057+0000] {taskinstance.py:2890} INFO - Executing <Task(DockerOperator): php_app1> on 2024-03-16 00:00:00+00:00
[2025-03-25T00:18:44.098+0000] {logging_mixin.py:190} WARNING - /home/***/.local/lib/python3.12/site-packages/***/task/task_runner/standard_task_runner.py:70 DeprecationWarning: This process (pid=480) is multi-threaded, use of fork() may lead to deadlocks in the child.
[2025-03-25T00:18:44.100+0000] {standard_task_runner.py:72} INFO - Started process 487 to run task
[2025-03-25T00:18:44.099+0000] {standard_task_runner.py:104} INFO - Running: ['***', 'tasks', 'run', 'containers1_dag', 'php_app1', 'scheduled__2024-03-16T00:00:00+00:00', '--job-id', '32', '--raw', '--subdir', 'DAGS_FOLDER/containers1_dag.py', '--cfg-path', '/tmp/tmp0bspd55t']
[2025-03-25T00:18:44.106+0000] {standard_task_runner.py:105} INFO - Job 32: Subtask php_app1
[2025-03-25T00:18:44.342+0000] {task_command.py:467} INFO - Running <TaskInstance: containers1_dag.php_app1 scheduled__2024-03-16T00:00:00+00:00 [running]> on host 0f77abd8a5ce
[2025-03-25T00:18:44.697+0000] {taskinstance.py:3134} INFO - Exporting env vars: AIRFLOW_CTX_DAG_OWNER='andre' AIRFLOW_CTX_DAG_ID='containers1_dag' AIRFLOW_CTX_TASK_ID='php_app1' AIRFLOW_CTX_EXECUTION_DATE='2024-03-16T00:00:00+00:00' AIRFLOW_CTX_TRY_NUMBER='1' AIRFLOW_CTX_DAG_RUN_ID='scheduled__2024-03-16T00:00:00+00:00'
[2025-03-25T00:18:44.699+0000] {taskinstance.py:732} INFO - ::endgroup::
[2025-03-25T00:18:44.759+0000] {docker.py:157} ERROR - Failed to establish connection to Docker host unix://var/run/docker.sock: Error while fetching server API version: ('Connection aborted.', FileNotFoundError(2, 'No such file or directory'))
[2025-03-25T00:18:44.789+0000] {taskinstance.py:3313} ERROR - Task failed with exception
Traceback (most recent call last):
  File "/home/airflow/.local/lib/python3.12/site-packages/airflow/models/taskinstance.py", line 768, in _execute_task
    result = _execute_callable(context=context, **execute_callable_kwargs)
             ^^^^^^^^^^^^^^^^^^^^^^^^^^^^^^^^^^^^^^^^^^^^^^^^^^^^^^^^^^^^^
  File "/home/airflow/.local/lib/python3.12/site-packages/airflow/models/taskinstance.py", line 734, in _execute_callable
    return ExecutionCallableRunner(
           ^^^^^^^^^^^^^^^^^^^^^^^^
  File "/home/airflow/.local/lib/python3.12/site-packages/airflow/utils/operator_helpers.py", line 252, in run
    return self.func(*args, **kwargs)
           ^^^^^^^^^^^^^^^^^^^^^^^^^^
  File "/home/airflow/.local/lib/python3.12/site-packages/airflow/models/baseoperator.py", line 424, in wrapper
    return func(self, *args, **kwargs)
           ^^^^^^^^^^^^^^^^^^^^^^^^^^^
  File "/home/airflow/.local/lib/python3.12/site-packages/airflow/providers/docker/operators/docker.py", line 467, in execute
    if self.force_pull or not self.cli.images(name=self.image):
                              ^^^^^^^^
  File "/home/airflow/.local/lib/python3.12/site-packages/airflow/providers/docker/operators/docker.py", line 341, in cli
    return self.hook.api_client
           ^^^^^^^^^^^^^^^^^^^^
  File "/usr/local/lib/python3.12/functools.py", line 998, in __get__
    val = self.func(instance)
          ^^^^^^^^^^^^^^^^^^^
  File "/home/airflow/.local/lib/python3.12/site-packages/airflow/providers/docker/hooks/docker.py", line 161, in api_client
    raise AirflowException("Failed to establish connection to any given Docker hosts.")
airflow.exceptions.AirflowException: Failed to establish connection to any given Docker hosts.
[2025-03-25T00:18:44.807+0000] {taskinstance.py:1226} INFO - Marking task as UP_FOR_RETRY. dag_id=containers1_dag, task_id=php_app1, run_id=scheduled__2024-03-16T00:00:00+00:00, execution_date=20240316T000000, start_date=20250325T001843, end_date=20250325T001844
[2025-03-25T00:18:44.915+0000] {taskinstance.py:341} INFO - ::group::Post task execution logs
[2025-03-25T00:18:44.916+0000] {standard_task_runner.py:124} ERROR - Failed to execute job 32 for task php_app1 (Failed to establish connection to any given Docker hosts.; 487)
Traceback (most recent call last):
  File "/home/airflow/.local/lib/python3.12/site-packages/airflow/task/task_runner/standard_task_runner.py", line 117, in _start_by_fork
    ret = args.func(args, dag=self.dag)
          ^^^^^^^^^^^^^^^^^^^^^^^^^^^^^
  File "/home/airflow/.local/lib/python3.12/site-packages/airflow/cli/cli_config.py", line 49, in command
    return func(*args, **kwargs)
           ^^^^^^^^^^^^^^^^^^^^^
  File "/home/airflow/.local/lib/python3.12/site-packages/airflow/utils/cli.py", line 116, in wrapper
    return f(*args, **kwargs)
           ^^^^^^^^^^^^^^^^^^
  File "/home/airflow/.local/lib/python3.12/site-packages/airflow/cli/commands/task_command.py", line 483, in task_run
    task_return_code = _run_task_by_selected_method(args, _dag, ti)
                       ^^^^^^^^^^^^^^^^^^^^^^^^^^^^^^^^^^^^^^^^^^^^
  File "/home/airflow/.local/lib/python3.12/site-packages/airflow/cli/commands/task_command.py", line 256, in _run_task_by_selected_method
    return _run_raw_task(args, ti)
           ^^^^^^^^^^^^^^^^^^^^^^^
  File "/home/airflow/.local/lib/python3.12/site-packages/airflow/cli/commands/task_command.py", line 341, in _run_raw_task
    return ti._run_raw_task(
           ^^^^^^^^^^^^^^^^^
  File "/home/airflow/.local/lib/python3.12/site-packages/airflow/utils/session.py", line 97, in wrapper
    return func(*args, session=session, **kwargs)
           ^^^^^^^^^^^^^^^^^^^^^^^^^^^^^^^^^^^^^^
  File "/home/airflow/.local/lib/python3.12/site-packages/airflow/models/taskinstance.py", line 3006, in _run_raw_task
    return _run_raw_task(
           ^^^^^^^^^^^^^^
  File "/home/airflow/.local/lib/python3.12/site-packages/airflow/models/taskinstance.py", line 274, in _run_raw_task
    TaskInstance._execute_task_with_callbacks(
  File "/home/airflow/.local/lib/python3.12/site-packages/airflow/models/taskinstance.py", line 3161, in _execute_task_with_callbacks
    result = self._execute_task(context, task_orig)
             ^^^^^^^^^^^^^^^^^^^^^^^^^^^^^^^^^^^^^^
  File "/home/airflow/.local/lib/python3.12/site-packages/airflow/models/taskinstance.py", line 3185, in _execute_task
    return _execute_task(self, context, task_orig)
           ^^^^^^^^^^^^^^^^^^^^^^^^^^^^^^^^^^^^^^^
  File "/home/airflow/.local/lib/python3.12/site-packages/airflow/models/taskinstance.py", line 768, in _execute_task
    result = _execute_callable(context=context, **execute_callable_kwargs)
             ^^^^^^^^^^^^^^^^^^^^^^^^^^^^^^^^^^^^^^^^^^^^^^^^^^^^^^^^^^^^^
  File "/home/airflow/.local/lib/python3.12/site-packages/airflow/models/taskinstance.py", line 734, in _execute_callable
    return ExecutionCallableRunner(
           ^^^^^^^^^^^^^^^^^^^^^^^^
  File "/home/airflow/.local/lib/python3.12/site-packages/airflow/utils/operator_helpers.py", line 252, in run
    return self.func(*args, **kwargs)
           ^^^^^^^^^^^^^^^^^^^^^^^^^^
  File "/home/airflow/.local/lib/python3.12/site-packages/airflow/models/baseoperator.py", line 424, in wrapper
    return func(self, *args, **kwargs)
           ^^^^^^^^^^^^^^^^^^^^^^^^^^^
  File "/home/airflow/.local/lib/python3.12/site-packages/airflow/providers/docker/operators/docker.py", line 467, in execute
    if self.force_pull or not self.cli.images(name=self.image):
                              ^^^^^^^^
  File "/home/airflow/.local/lib/python3.12/site-packages/airflow/providers/docker/operators/docker.py", line 341, in cli
    return self.hook.api_client
           ^^^^^^^^^^^^^^^^^^^^
  File "/usr/local/lib/python3.12/functools.py", line 998, in __get__
    val = self.func(instance)
          ^^^^^^^^^^^^^^^^^^^
  File "/home/airflow/.local/lib/python3.12/site-packages/airflow/providers/docker/hooks/docker.py", line 161, in api_client
    raise AirflowException("Failed to establish connection to any given Docker hosts.")
airflow.exceptions.AirflowException: Failed to establish connection to any given Docker hosts.
[2025-03-25T00:18:44.967+0000] {local_task_job_runner.py:266} INFO - Task exited with return code 1
[2025-03-25T00:18:45.043+0000] {taskinstance.py:3901} INFO - 0 downstream tasks scheduled from follow-on schedule check
[2025-03-25T00:18:45.052+0000] {local_task_job_runner.py:245} INFO - ::endgroup::
