[2025-03-24T22:19:24.235+0000] {local_task_job_runner.py:123} INFO - ::group::Pre task execution logs
[2025-03-24T22:19:24.519+0000] {taskinstance.py:2614} INFO - Dependencies all met for dep_context=non-requeueable deps ti=<TaskInstance: containers1_dag.php_app2 scheduled__2024-03-07T00:00:00+00:00 [queued]>
[2025-03-24T22:19:24.696+0000] {taskinstance.py:2614} INFO - Dependencies all met for dep_context=requeueable deps ti=<TaskInstance: containers1_dag.php_app2 scheduled__2024-03-07T00:00:00+00:00 [queued]>
[2025-03-24T22:19:24.699+0000] {taskinstance.py:2867} INFO - Starting attempt 1 of 6
[2025-03-24T22:19:25.081+0000] {taskinstance.py:2890} INFO - Executing <Task(BashOperator): php_app2> on 2024-03-07 00:00:00+00:00
[2025-03-24T22:19:25.169+0000] {logging_mixin.py:190} WARNING - /home/***/.local/lib/python3.12/site-packages/***/task/task_runner/standard_task_runner.py:70 DeprecationWarning: This process (pid=4952) is multi-threaded, use of fork() may lead to deadlocks in the child.
[2025-03-24T22:19:25.170+0000] {standard_task_runner.py:72} INFO - Started process 4973 to run task
[2025-03-24T22:19:25.166+0000] {standard_task_runner.py:104} INFO - Running: ['***', 'tasks', 'run', 'containers1_dag', 'php_app2', 'scheduled__2024-03-07T00:00:00+00:00', '--job-id', '130', '--raw', '--subdir', 'DAGS_FOLDER/containers1_dag.py', '--cfg-path', '/tmp/tmppxrk61vj']
[2025-03-24T22:19:25.176+0000] {standard_task_runner.py:105} INFO - Job 130: Subtask php_app2
[2025-03-24T22:19:25.589+0000] {task_command.py:467} INFO - Running <TaskInstance: containers1_dag.php_app2 scheduled__2024-03-07T00:00:00+00:00 [running]> on host b9050090f7f5
[2025-03-24T22:19:26.270+0000] {taskinstance.py:3134} INFO - Exporting env vars: AIRFLOW_CTX_DAG_OWNER='andreeppinghaus' AIRFLOW_CTX_DAG_ID='containers1_dag' AIRFLOW_CTX_TASK_ID='php_app2' AIRFLOW_CTX_EXECUTION_DATE='2024-03-07T00:00:00+00:00' AIRFLOW_CTX_TRY_NUMBER='1' AIRFLOW_CTX_DAG_RUN_ID='scheduled__2024-03-07T00:00:00+00:00'
[2025-03-24T22:19:26.306+0000] {taskinstance.py:732} INFO - ::endgroup::
[2025-03-24T22:19:26.453+0000] {subprocess.py:78} INFO - Tmp dir root location: /tmp
[2025-03-24T22:19:26.454+0000] {subprocess.py:88} INFO - Running command: ['/usr/bin/bash', '-c', 'sudo docker run -v $(pwd)/../in:/usr/src/app/in -v $(pwd):/usr/src/app php-app2']
[2025-03-24T22:19:26.584+0000] {subprocess.py:99} INFO - Output:
[2025-03-24T22:19:26.682+0000] {subprocess.py:106} INFO - sudo: a terminal is required to read the password; either use the -S option to read from standard input or configure an askpass helper
[2025-03-24T22:19:26.683+0000] {subprocess.py:106} INFO - sudo: a password is required
[2025-03-24T22:19:26.684+0000] {subprocess.py:110} INFO - Command exited with return code 1
[2025-03-24T22:19:26.835+0000] {taskinstance.py:3313} ERROR - Task failed with exception
Traceback (most recent call last):
  File "/home/airflow/.local/lib/python3.12/site-packages/airflow/models/taskinstance.py", line 768, in _execute_task
    result = _execute_callable(context=context, **execute_callable_kwargs)
             ^^^^^^^^^^^^^^^^^^^^^^^^^^^^^^^^^^^^^^^^^^^^^^^^^^^^^^^^^^^^^
  File "/home/airflow/.local/lib/python3.12/site-packages/airflow/models/taskinstance.py", line 734, in _execute_callable
    return ExecutionCallableRunner(
           ^^^^^^^^^^^^^^^^^^^^^^^^
  File "/home/airflow/.local/lib/python3.12/site-packages/airflow/utils/operator_helpers.py", line 252, in run
    return self.func(*args, **kwargs)
           ^^^^^^^^^^^^^^^^^^^^^^^^^^
  File "/home/airflow/.local/lib/python3.12/site-packages/airflow/models/baseoperator.py", line 424, in wrapper
    return func(self, *args, **kwargs)
           ^^^^^^^^^^^^^^^^^^^^^^^^^^^
  File "/home/airflow/.local/lib/python3.12/site-packages/airflow/operators/bash.py", line 276, in execute
    raise AirflowException(
airflow.exceptions.AirflowException: Bash command failed. The command returned a non-zero exit code 1.
[2025-03-24T22:19:26.951+0000] {taskinstance.py:1226} INFO - Marking task as UP_FOR_RETRY. dag_id=containers1_dag, task_id=php_app2, run_id=scheduled__2024-03-07T00:00:00+00:00, execution_date=20240307T000000, start_date=20250324T221924, end_date=20250324T221926
[2025-03-24T22:19:27.205+0000] {taskinstance.py:341} INFO - ::group::Post task execution logs
[2025-03-24T22:19:27.209+0000] {standard_task_runner.py:124} ERROR - Failed to execute job 130 for task php_app2 (Bash command failed. The command returned a non-zero exit code 1.; 4973)
Traceback (most recent call last):
  File "/home/airflow/.local/lib/python3.12/site-packages/airflow/task/task_runner/standard_task_runner.py", line 117, in _start_by_fork
    ret = args.func(args, dag=self.dag)
          ^^^^^^^^^^^^^^^^^^^^^^^^^^^^^
  File "/home/airflow/.local/lib/python3.12/site-packages/airflow/cli/cli_config.py", line 49, in command
    return func(*args, **kwargs)
           ^^^^^^^^^^^^^^^^^^^^^
  File "/home/airflow/.local/lib/python3.12/site-packages/airflow/utils/cli.py", line 116, in wrapper
    return f(*args, **kwargs)
           ^^^^^^^^^^^^^^^^^^
  File "/home/airflow/.local/lib/python3.12/site-packages/airflow/cli/commands/task_command.py", line 483, in task_run
    task_return_code = _run_task_by_selected_method(args, _dag, ti)
                       ^^^^^^^^^^^^^^^^^^^^^^^^^^^^^^^^^^^^^^^^^^^^
  File "/home/airflow/.local/lib/python3.12/site-packages/airflow/cli/commands/task_command.py", line 256, in _run_task_by_selected_method
    return _run_raw_task(args, ti)
           ^^^^^^^^^^^^^^^^^^^^^^^
  File "/home/airflow/.local/lib/python3.12/site-packages/airflow/cli/commands/task_command.py", line 341, in _run_raw_task
    return ti._run_raw_task(
           ^^^^^^^^^^^^^^^^^
  File "/home/airflow/.local/lib/python3.12/site-packages/airflow/utils/session.py", line 97, in wrapper
    return func(*args, session=session, **kwargs)
           ^^^^^^^^^^^^^^^^^^^^^^^^^^^^^^^^^^^^^^
  File "/home/airflow/.local/lib/python3.12/site-packages/airflow/models/taskinstance.py", line 3006, in _run_raw_task
    return _run_raw_task(
           ^^^^^^^^^^^^^^
  File "/home/airflow/.local/lib/python3.12/site-packages/airflow/models/taskinstance.py", line 274, in _run_raw_task
    TaskInstance._execute_task_with_callbacks(
  File "/home/airflow/.local/lib/python3.12/site-packages/airflow/models/taskinstance.py", line 3161, in _execute_task_with_callbacks
    result = self._execute_task(context, task_orig)
             ^^^^^^^^^^^^^^^^^^^^^^^^^^^^^^^^^^^^^^
  File "/home/airflow/.local/lib/python3.12/site-packages/airflow/models/taskinstance.py", line 3185, in _execute_task
    return _execute_task(self, context, task_orig)
           ^^^^^^^^^^^^^^^^^^^^^^^^^^^^^^^^^^^^^^^
  File "/home/airflow/.local/lib/python3.12/site-packages/airflow/models/taskinstance.py", line 768, in _execute_task
    result = _execute_callable(context=context, **execute_callable_kwargs)
             ^^^^^^^^^^^^^^^^^^^^^^^^^^^^^^^^^^^^^^^^^^^^^^^^^^^^^^^^^^^^^
  File "/home/airflow/.local/lib/python3.12/site-packages/airflow/models/taskinstance.py", line 734, in _execute_callable
    return ExecutionCallableRunner(
           ^^^^^^^^^^^^^^^^^^^^^^^^
  File "/home/airflow/.local/lib/python3.12/site-packages/airflow/utils/operator_helpers.py", line 252, in run
    return self.func(*args, **kwargs)
           ^^^^^^^^^^^^^^^^^^^^^^^^^^
  File "/home/airflow/.local/lib/python3.12/site-packages/airflow/models/baseoperator.py", line 424, in wrapper
    return func(self, *args, **kwargs)
           ^^^^^^^^^^^^^^^^^^^^^^^^^^^
  File "/home/airflow/.local/lib/python3.12/site-packages/airflow/operators/bash.py", line 276, in execute
    raise AirflowException(
airflow.exceptions.AirflowException: Bash command failed. The command returned a non-zero exit code 1.
[2025-03-24T22:19:27.344+0000] {local_task_job_runner.py:266} INFO - Task exited with return code 1
[2025-03-24T22:19:27.636+0000] {taskinstance.py:3901} INFO - 0 downstream tasks scheduled from follow-on schedule check
[2025-03-24T22:19:27.667+0000] {local_task_job_runner.py:245} INFO - ::endgroup::
[2025-03-24T22:24:18.325+0000] {local_task_job_runner.py:123} INFO - ::group::Pre task execution logs
[2025-03-24T22:24:18.497+0000] {taskinstance.py:2614} INFO - Dependencies all met for dep_context=non-requeueable deps ti=<TaskInstance: containers1_dag.php_app2 scheduled__2024-03-07T00:00:00+00:00 [queued]>
[2025-03-24T22:24:18.605+0000] {taskinstance.py:2614} INFO - Dependencies all met for dep_context=requeueable deps ti=<TaskInstance: containers1_dag.php_app2 scheduled__2024-03-07T00:00:00+00:00 [queued]>
[2025-03-24T22:24:18.606+0000] {taskinstance.py:2867} INFO - Starting attempt 1 of 6
[2025-03-24T22:24:18.674+0000] {taskinstance.py:2890} INFO - Executing <Task(BashOperator): php_app2> on 2024-03-07 00:00:00+00:00
[2025-03-24T22:24:18.721+0000] {logging_mixin.py:190} WARNING - /home/***/.local/lib/python3.12/site-packages/***/task/task_runner/standard_task_runner.py:70 DeprecationWarning: This process (pid=5256) is multi-threaded, use of fork() may lead to deadlocks in the child.
[2025-03-24T22:24:18.723+0000] {standard_task_runner.py:72} INFO - Started process 5284 to run task
[2025-03-24T22:24:18.746+0000] {standard_task_runner.py:104} INFO - Running: ['***', 'tasks', 'run', 'containers1_dag', 'php_app2', 'scheduled__2024-03-07T00:00:00+00:00', '--job-id', '155', '--raw', '--subdir', 'DAGS_FOLDER/containers1_dag.py', '--cfg-path', '/tmp/tmp5venvxt_']
[2025-03-24T22:24:18.782+0000] {standard_task_runner.py:105} INFO - Job 155: Subtask php_app2
[2025-03-24T22:24:19.165+0000] {task_command.py:467} INFO - Running <TaskInstance: containers1_dag.php_app2 scheduled__2024-03-07T00:00:00+00:00 [running]> on host b9050090f7f5
[2025-03-24T22:24:19.807+0000] {taskinstance.py:3134} INFO - Exporting env vars: AIRFLOW_CTX_DAG_OWNER='andre' AIRFLOW_CTX_DAG_ID='containers1_dag' AIRFLOW_CTX_TASK_ID='php_app2' AIRFLOW_CTX_EXECUTION_DATE='2024-03-07T00:00:00+00:00' AIRFLOW_CTX_TRY_NUMBER='1' AIRFLOW_CTX_DAG_RUN_ID='scheduled__2024-03-07T00:00:00+00:00'
[2025-03-24T22:24:19.808+0000] {taskinstance.py:732} INFO - ::endgroup::
[2025-03-24T22:24:19.858+0000] {subprocess.py:78} INFO - Tmp dir root location: /tmp
[2025-03-24T22:24:19.859+0000] {subprocess.py:88} INFO - Running command: ['/usr/bin/bash', '-c', 'sudo docker run -v $(pwd)/../in:/usr/src/app/in -v $(pwd):/usr/src/app php-app2']
[2025-03-24T22:24:19.910+0000] {subprocess.py:99} INFO - Output:
[2025-03-24T22:24:20.018+0000] {subprocess.py:106} INFO - sudo: a terminal is required to read the password; either use the -S option to read from standard input or configure an askpass helper
[2025-03-24T22:24:20.025+0000] {subprocess.py:106} INFO - sudo: a password is required
[2025-03-24T22:24:20.032+0000] {subprocess.py:110} INFO - Command exited with return code 1
[2025-03-24T22:24:20.122+0000] {taskinstance.py:3313} ERROR - Task failed with exception
Traceback (most recent call last):
  File "/home/airflow/.local/lib/python3.12/site-packages/airflow/models/taskinstance.py", line 768, in _execute_task
    result = _execute_callable(context=context, **execute_callable_kwargs)
             ^^^^^^^^^^^^^^^^^^^^^^^^^^^^^^^^^^^^^^^^^^^^^^^^^^^^^^^^^^^^^
  File "/home/airflow/.local/lib/python3.12/site-packages/airflow/models/taskinstance.py", line 734, in _execute_callable
    return ExecutionCallableRunner(
           ^^^^^^^^^^^^^^^^^^^^^^^^
  File "/home/airflow/.local/lib/python3.12/site-packages/airflow/utils/operator_helpers.py", line 252, in run
    return self.func(*args, **kwargs)
           ^^^^^^^^^^^^^^^^^^^^^^^^^^
  File "/home/airflow/.local/lib/python3.12/site-packages/airflow/models/baseoperator.py", line 424, in wrapper
    return func(self, *args, **kwargs)
           ^^^^^^^^^^^^^^^^^^^^^^^^^^^
  File "/home/airflow/.local/lib/python3.12/site-packages/airflow/operators/bash.py", line 276, in execute
    raise AirflowException(
airflow.exceptions.AirflowException: Bash command failed. The command returned a non-zero exit code 1.
[2025-03-24T22:24:20.166+0000] {taskinstance.py:1226} INFO - Marking task as UP_FOR_RETRY. dag_id=containers1_dag, task_id=php_app2, run_id=scheduled__2024-03-07T00:00:00+00:00, execution_date=20240307T000000, start_date=20250324T222418, end_date=20250324T222420
[2025-03-24T22:24:20.365+0000] {taskinstance.py:341} INFO - ::group::Post task execution logs
[2025-03-24T22:24:20.366+0000] {standard_task_runner.py:124} ERROR - Failed to execute job 155 for task php_app2 (Bash command failed. The command returned a non-zero exit code 1.; 5284)
Traceback (most recent call last):
  File "/home/airflow/.local/lib/python3.12/site-packages/airflow/task/task_runner/standard_task_runner.py", line 117, in _start_by_fork
    ret = args.func(args, dag=self.dag)
          ^^^^^^^^^^^^^^^^^^^^^^^^^^^^^
  File "/home/airflow/.local/lib/python3.12/site-packages/airflow/cli/cli_config.py", line 49, in command
    return func(*args, **kwargs)
           ^^^^^^^^^^^^^^^^^^^^^
  File "/home/airflow/.local/lib/python3.12/site-packages/airflow/utils/cli.py", line 116, in wrapper
    return f(*args, **kwargs)
           ^^^^^^^^^^^^^^^^^^
  File "/home/airflow/.local/lib/python3.12/site-packages/airflow/cli/commands/task_command.py", line 483, in task_run
    task_return_code = _run_task_by_selected_method(args, _dag, ti)
                       ^^^^^^^^^^^^^^^^^^^^^^^^^^^^^^^^^^^^^^^^^^^^
  File "/home/airflow/.local/lib/python3.12/site-packages/airflow/cli/commands/task_command.py", line 256, in _run_task_by_selected_method
    return _run_raw_task(args, ti)
           ^^^^^^^^^^^^^^^^^^^^^^^
  File "/home/airflow/.local/lib/python3.12/site-packages/airflow/cli/commands/task_command.py", line 341, in _run_raw_task
    return ti._run_raw_task(
           ^^^^^^^^^^^^^^^^^
  File "/home/airflow/.local/lib/python3.12/site-packages/airflow/utils/session.py", line 97, in wrapper
    return func(*args, session=session, **kwargs)
           ^^^^^^^^^^^^^^^^^^^^^^^^^^^^^^^^^^^^^^
  File "/home/airflow/.local/lib/python3.12/site-packages/airflow/models/taskinstance.py", line 3006, in _run_raw_task
    return _run_raw_task(
           ^^^^^^^^^^^^^^
  File "/home/airflow/.local/lib/python3.12/site-packages/airflow/models/taskinstance.py", line 274, in _run_raw_task
    TaskInstance._execute_task_with_callbacks(
  File "/home/airflow/.local/lib/python3.12/site-packages/airflow/models/taskinstance.py", line 3161, in _execute_task_with_callbacks
    result = self._execute_task(context, task_orig)
             ^^^^^^^^^^^^^^^^^^^^^^^^^^^^^^^^^^^^^^
  File "/home/airflow/.local/lib/python3.12/site-packages/airflow/models/taskinstance.py", line 3185, in _execute_task
    return _execute_task(self, context, task_orig)
           ^^^^^^^^^^^^^^^^^^^^^^^^^^^^^^^^^^^^^^^
  File "/home/airflow/.local/lib/python3.12/site-packages/airflow/models/taskinstance.py", line 768, in _execute_task
    result = _execute_callable(context=context, **execute_callable_kwargs)
             ^^^^^^^^^^^^^^^^^^^^^^^^^^^^^^^^^^^^^^^^^^^^^^^^^^^^^^^^^^^^^
  File "/home/airflow/.local/lib/python3.12/site-packages/airflow/models/taskinstance.py", line 734, in _execute_callable
    return ExecutionCallableRunner(
           ^^^^^^^^^^^^^^^^^^^^^^^^
  File "/home/airflow/.local/lib/python3.12/site-packages/airflow/utils/operator_helpers.py", line 252, in run
    return self.func(*args, **kwargs)
           ^^^^^^^^^^^^^^^^^^^^^^^^^^
  File "/home/airflow/.local/lib/python3.12/site-packages/airflow/models/baseoperator.py", line 424, in wrapper
    return func(self, *args, **kwargs)
           ^^^^^^^^^^^^^^^^^^^^^^^^^^^
  File "/home/airflow/.local/lib/python3.12/site-packages/airflow/operators/bash.py", line 276, in execute
    raise AirflowException(
airflow.exceptions.AirflowException: Bash command failed. The command returned a non-zero exit code 1.
[2025-03-24T22:24:20.431+0000] {local_task_job_runner.py:266} INFO - Task exited with return code 1
[2025-03-24T22:24:20.619+0000] {taskinstance.py:3901} INFO - 0 downstream tasks scheduled from follow-on schedule check
[2025-03-24T22:24:20.642+0000] {local_task_job_runner.py:245} INFO - ::endgroup::
[2025-03-24T22:27:23.926+0000] {local_task_job_runner.py:123} INFO - ::group::Pre task execution logs
[2025-03-24T22:27:24.024+0000] {taskinstance.py:2614} INFO - Dependencies all met for dep_context=non-requeueable deps ti=<TaskInstance: containers1_dag.php_app2 scheduled__2024-03-07T00:00:00+00:00 [queued]>
[2025-03-24T22:27:24.117+0000] {taskinstance.py:2614} INFO - Dependencies all met for dep_context=requeueable deps ti=<TaskInstance: containers1_dag.php_app2 scheduled__2024-03-07T00:00:00+00:00 [queued]>
[2025-03-24T22:27:24.118+0000] {taskinstance.py:2867} INFO - Starting attempt 1 of 6
[2025-03-24T22:27:24.168+0000] {taskinstance.py:2890} INFO - Executing <Task(BashOperator): php_app2> on 2024-03-07 00:00:00+00:00
[2025-03-24T22:27:24.230+0000] {logging_mixin.py:190} WARNING - /home/***/.local/lib/python3.12/site-packages/***/task/task_runner/standard_task_runner.py:70 DeprecationWarning: This process (pid=5608) is multi-threaded, use of fork() may lead to deadlocks in the child.
[2025-03-24T22:27:24.237+0000] {standard_task_runner.py:104} INFO - Running: ['***', 'tasks', 'run', 'containers1_dag', 'php_app2', 'scheduled__2024-03-07T00:00:00+00:00', '--job-id', '188', '--raw', '--subdir', 'DAGS_FOLDER/containers1_dag.py', '--cfg-path', '/tmp/tmpxlmue0bg']
[2025-03-24T22:27:24.270+0000] {standard_task_runner.py:105} INFO - Job 188: Subtask php_app2
[2025-03-24T22:27:24.263+0000] {standard_task_runner.py:72} INFO - Started process 5643 to run task
[2025-03-24T22:27:24.867+0000] {task_command.py:467} INFO - Running <TaskInstance: containers1_dag.php_app2 scheduled__2024-03-07T00:00:00+00:00 [running]> on host b9050090f7f5
[2025-03-24T22:27:25.681+0000] {taskinstance.py:3134} INFO - Exporting env vars: AIRFLOW_CTX_DAG_OWNER='andre' AIRFLOW_CTX_DAG_ID='containers1_dag' AIRFLOW_CTX_TASK_ID='php_app2' AIRFLOW_CTX_EXECUTION_DATE='2024-03-07T00:00:00+00:00' AIRFLOW_CTX_TRY_NUMBER='1' AIRFLOW_CTX_DAG_RUN_ID='scheduled__2024-03-07T00:00:00+00:00'
[2025-03-24T22:27:25.688+0000] {taskinstance.py:732} INFO - ::endgroup::
[2025-03-24T22:27:25.781+0000] {subprocess.py:78} INFO - Tmp dir root location: /tmp
[2025-03-24T22:27:25.782+0000] {subprocess.py:88} INFO - Running command: ['/usr/bin/bash', '-c', 'docker run -v $(pwd)/../in:/usr/src/app/in -v $(pwd):/usr/src/app php-app2']
[2025-03-24T22:27:25.863+0000] {subprocess.py:99} INFO - Output:
[2025-03-24T22:27:26.069+0000] {subprocess.py:106} INFO - docker: Cannot connect to the Docker daemon at unix:///var/run/docker.sock. Is the docker daemon running?.
[2025-03-24T22:27:26.070+0000] {subprocess.py:106} INFO - See 'docker run --help'.
[2025-03-24T22:27:26.083+0000] {subprocess.py:110} INFO - Command exited with return code 125
[2025-03-24T22:27:26.326+0000] {taskinstance.py:3313} ERROR - Task failed with exception
Traceback (most recent call last):
  File "/home/airflow/.local/lib/python3.12/site-packages/airflow/models/taskinstance.py", line 768, in _execute_task
    result = _execute_callable(context=context, **execute_callable_kwargs)
             ^^^^^^^^^^^^^^^^^^^^^^^^^^^^^^^^^^^^^^^^^^^^^^^^^^^^^^^^^^^^^
  File "/home/airflow/.local/lib/python3.12/site-packages/airflow/models/taskinstance.py", line 734, in _execute_callable
    return ExecutionCallableRunner(
           ^^^^^^^^^^^^^^^^^^^^^^^^
  File "/home/airflow/.local/lib/python3.12/site-packages/airflow/utils/operator_helpers.py", line 252, in run
    return self.func(*args, **kwargs)
           ^^^^^^^^^^^^^^^^^^^^^^^^^^
  File "/home/airflow/.local/lib/python3.12/site-packages/airflow/models/baseoperator.py", line 424, in wrapper
    return func(self, *args, **kwargs)
           ^^^^^^^^^^^^^^^^^^^^^^^^^^^
  File "/home/airflow/.local/lib/python3.12/site-packages/airflow/operators/bash.py", line 276, in execute
    raise AirflowException(
airflow.exceptions.AirflowException: Bash command failed. The command returned a non-zero exit code 125.
[2025-03-24T22:27:26.471+0000] {taskinstance.py:1226} INFO - Marking task as UP_FOR_RETRY. dag_id=containers1_dag, task_id=php_app2, run_id=scheduled__2024-03-07T00:00:00+00:00, execution_date=20240307T000000, start_date=20250324T222724, end_date=20250324T222726
[2025-03-24T22:27:27.038+0000] {taskinstance.py:341} INFO - ::group::Post task execution logs
[2025-03-24T22:27:27.046+0000] {standard_task_runner.py:124} ERROR - Failed to execute job 188 for task php_app2 (Bash command failed. The command returned a non-zero exit code 125.; 5643)
Traceback (most recent call last):
  File "/home/airflow/.local/lib/python3.12/site-packages/airflow/task/task_runner/standard_task_runner.py", line 117, in _start_by_fork
    ret = args.func(args, dag=self.dag)
          ^^^^^^^^^^^^^^^^^^^^^^^^^^^^^
  File "/home/airflow/.local/lib/python3.12/site-packages/airflow/cli/cli_config.py", line 49, in command
    return func(*args, **kwargs)
           ^^^^^^^^^^^^^^^^^^^^^
  File "/home/airflow/.local/lib/python3.12/site-packages/airflow/utils/cli.py", line 116, in wrapper
    return f(*args, **kwargs)
           ^^^^^^^^^^^^^^^^^^
  File "/home/airflow/.local/lib/python3.12/site-packages/airflow/cli/commands/task_command.py", line 483, in task_run
    task_return_code = _run_task_by_selected_method(args, _dag, ti)
                       ^^^^^^^^^^^^^^^^^^^^^^^^^^^^^^^^^^^^^^^^^^^^
  File "/home/airflow/.local/lib/python3.12/site-packages/airflow/cli/commands/task_command.py", line 256, in _run_task_by_selected_method
    return _run_raw_task(args, ti)
           ^^^^^^^^^^^^^^^^^^^^^^^
  File "/home/airflow/.local/lib/python3.12/site-packages/airflow/cli/commands/task_command.py", line 341, in _run_raw_task
    return ti._run_raw_task(
           ^^^^^^^^^^^^^^^^^
  File "/home/airflow/.local/lib/python3.12/site-packages/airflow/utils/session.py", line 97, in wrapper
    return func(*args, session=session, **kwargs)
           ^^^^^^^^^^^^^^^^^^^^^^^^^^^^^^^^^^^^^^
  File "/home/airflow/.local/lib/python3.12/site-packages/airflow/models/taskinstance.py", line 3006, in _run_raw_task
    return _run_raw_task(
           ^^^^^^^^^^^^^^
  File "/home/airflow/.local/lib/python3.12/site-packages/airflow/models/taskinstance.py", line 274, in _run_raw_task
    TaskInstance._execute_task_with_callbacks(
  File "/home/airflow/.local/lib/python3.12/site-packages/airflow/models/taskinstance.py", line 3161, in _execute_task_with_callbacks
    result = self._execute_task(context, task_orig)
             ^^^^^^^^^^^^^^^^^^^^^^^^^^^^^^^^^^^^^^
  File "/home/airflow/.local/lib/python3.12/site-packages/airflow/models/taskinstance.py", line 3185, in _execute_task
    return _execute_task(self, context, task_orig)
           ^^^^^^^^^^^^^^^^^^^^^^^^^^^^^^^^^^^^^^^
  File "/home/airflow/.local/lib/python3.12/site-packages/airflow/models/taskinstance.py", line 768, in _execute_task
    result = _execute_callable(context=context, **execute_callable_kwargs)
             ^^^^^^^^^^^^^^^^^^^^^^^^^^^^^^^^^^^^^^^^^^^^^^^^^^^^^^^^^^^^^
  File "/home/airflow/.local/lib/python3.12/site-packages/airflow/models/taskinstance.py", line 734, in _execute_callable
    return ExecutionCallableRunner(
           ^^^^^^^^^^^^^^^^^^^^^^^^
  File "/home/airflow/.local/lib/python3.12/site-packages/airflow/utils/operator_helpers.py", line 252, in run
    return self.func(*args, **kwargs)
           ^^^^^^^^^^^^^^^^^^^^^^^^^^
  File "/home/airflow/.local/lib/python3.12/site-packages/airflow/models/baseoperator.py", line 424, in wrapper
    return func(self, *args, **kwargs)
           ^^^^^^^^^^^^^^^^^^^^^^^^^^^
  File "/home/airflow/.local/lib/python3.12/site-packages/airflow/operators/bash.py", line 276, in execute
    raise AirflowException(
airflow.exceptions.AirflowException: Bash command failed. The command returned a non-zero exit code 125.
[2025-03-24T22:27:27.155+0000] {local_task_job_runner.py:266} INFO - Task exited with return code 1
[2025-03-24T22:27:27.289+0000] {taskinstance.py:3901} INFO - 0 downstream tasks scheduled from follow-on schedule check
[2025-03-24T22:27:27.333+0000] {local_task_job_runner.py:245} INFO - ::endgroup::
[2025-03-24T23:57:27.538+0000] {local_task_job_runner.py:123} INFO - ::group::Pre task execution logs
[2025-03-24T23:57:27.844+0000] {taskinstance.py:2614} INFO - Dependencies all met for dep_context=non-requeueable deps ti=<TaskInstance: containers1_dag.php_app2 scheduled__2024-03-07T00:00:00+00:00 [queued]>
[2025-03-24T23:57:27.908+0000] {taskinstance.py:2614} INFO - Dependencies all met for dep_context=requeueable deps ti=<TaskInstance: containers1_dag.php_app2 scheduled__2024-03-07T00:00:00+00:00 [queued]>
[2025-03-24T23:57:27.909+0000] {taskinstance.py:2867} INFO - Starting attempt 1 of 6
[2025-03-24T23:57:28.091+0000] {taskinstance.py:2890} INFO - Executing <Task(BashOperator): php_app2> on 2024-03-07 00:00:00+00:00
[2025-03-24T23:57:28.139+0000] {standard_task_runner.py:104} INFO - Running: ['***', 'tasks', 'run', 'containers1_dag', 'php_app2', 'scheduled__2024-03-07T00:00:00+00:00', '--job-id', '16', '--raw', '--subdir', 'DAGS_FOLDER/containers1_dag.py', '--cfg-path', '/tmp/tmpdrkbljq_']
[2025-03-24T23:57:28.142+0000] {standard_task_runner.py:105} INFO - Job 16: Subtask php_app2
[2025-03-24T23:57:28.172+0000] {logging_mixin.py:190} WARNING - /home/***/.local/lib/python3.12/site-packages/***/task/task_runner/standard_task_runner.py:70 DeprecationWarning: This process (pid=278) is multi-threaded, use of fork() may lead to deadlocks in the child.
[2025-03-24T23:57:28.173+0000] {standard_task_runner.py:72} INFO - Started process 376 to run task
[2025-03-24T23:57:28.338+0000] {task_command.py:467} INFO - Running <TaskInstance: containers1_dag.php_app2 scheduled__2024-03-07T00:00:00+00:00 [running]> on host 8e89fdaa3360
[2025-03-24T23:57:28.568+0000] {taskinstance.py:3134} INFO - Exporting env vars: AIRFLOW_CTX_DAG_OWNER='andre' AIRFLOW_CTX_DAG_ID='containers1_dag' AIRFLOW_CTX_TASK_ID='php_app2' AIRFLOW_CTX_EXECUTION_DATE='2024-03-07T00:00:00+00:00' AIRFLOW_CTX_TRY_NUMBER='1' AIRFLOW_CTX_DAG_RUN_ID='scheduled__2024-03-07T00:00:00+00:00'
[2025-03-24T23:57:28.569+0000] {taskinstance.py:732} INFO - ::endgroup::
[2025-03-24T23:57:28.622+0000] {subprocess.py:78} INFO - Tmp dir root location: /tmp
[2025-03-24T23:57:28.623+0000] {subprocess.py:88} INFO - Running command: ['/usr/bin/bash', '-c', 'docker run -v $(pwd)/../in:/usr/src/app/in -v $(pwd):/usr/src/app php-app2']
[2025-03-24T23:57:28.654+0000] {subprocess.py:99} INFO - Output:
[2025-03-24T23:57:28.695+0000] {subprocess.py:106} INFO - docker: Cannot connect to the Docker daemon at unix:///var/run/docker.sock. Is the docker daemon running?.
[2025-03-24T23:57:28.698+0000] {subprocess.py:106} INFO - See 'docker run --help'.
[2025-03-24T23:57:28.700+0000] {subprocess.py:110} INFO - Command exited with return code 125
[2025-03-24T23:57:28.726+0000] {taskinstance.py:3313} ERROR - Task failed with exception
Traceback (most recent call last):
  File "/home/airflow/.local/lib/python3.12/site-packages/airflow/models/taskinstance.py", line 768, in _execute_task
    result = _execute_callable(context=context, **execute_callable_kwargs)
             ^^^^^^^^^^^^^^^^^^^^^^^^^^^^^^^^^^^^^^^^^^^^^^^^^^^^^^^^^^^^^
  File "/home/airflow/.local/lib/python3.12/site-packages/airflow/models/taskinstance.py", line 734, in _execute_callable
    return ExecutionCallableRunner(
           ^^^^^^^^^^^^^^^^^^^^^^^^
  File "/home/airflow/.local/lib/python3.12/site-packages/airflow/utils/operator_helpers.py", line 252, in run
    return self.func(*args, **kwargs)
           ^^^^^^^^^^^^^^^^^^^^^^^^^^
  File "/home/airflow/.local/lib/python3.12/site-packages/airflow/models/baseoperator.py", line 424, in wrapper
    return func(self, *args, **kwargs)
           ^^^^^^^^^^^^^^^^^^^^^^^^^^^
  File "/home/airflow/.local/lib/python3.12/site-packages/airflow/operators/bash.py", line 276, in execute
    raise AirflowException(
airflow.exceptions.AirflowException: Bash command failed. The command returned a non-zero exit code 125.
[2025-03-24T23:57:28.743+0000] {taskinstance.py:1226} INFO - Marking task as UP_FOR_RETRY. dag_id=containers1_dag, task_id=php_app2, run_id=scheduled__2024-03-07T00:00:00+00:00, execution_date=20240307T000000, start_date=20250324T235727, end_date=20250324T235728
[2025-03-24T23:57:28.815+0000] {taskinstance.py:341} INFO - ::group::Post task execution logs
[2025-03-24T23:57:28.816+0000] {standard_task_runner.py:124} ERROR - Failed to execute job 16 for task php_app2 (Bash command failed. The command returned a non-zero exit code 125.; 376)
Traceback (most recent call last):
  File "/home/airflow/.local/lib/python3.12/site-packages/airflow/task/task_runner/standard_task_runner.py", line 117, in _start_by_fork
    ret = args.func(args, dag=self.dag)
          ^^^^^^^^^^^^^^^^^^^^^^^^^^^^^
  File "/home/airflow/.local/lib/python3.12/site-packages/airflow/cli/cli_config.py", line 49, in command
    return func(*args, **kwargs)
           ^^^^^^^^^^^^^^^^^^^^^
  File "/home/airflow/.local/lib/python3.12/site-packages/airflow/utils/cli.py", line 116, in wrapper
    return f(*args, **kwargs)
           ^^^^^^^^^^^^^^^^^^
  File "/home/airflow/.local/lib/python3.12/site-packages/airflow/cli/commands/task_command.py", line 483, in task_run
    task_return_code = _run_task_by_selected_method(args, _dag, ti)
                       ^^^^^^^^^^^^^^^^^^^^^^^^^^^^^^^^^^^^^^^^^^^^
  File "/home/airflow/.local/lib/python3.12/site-packages/airflow/cli/commands/task_command.py", line 256, in _run_task_by_selected_method
    return _run_raw_task(args, ti)
           ^^^^^^^^^^^^^^^^^^^^^^^
  File "/home/airflow/.local/lib/python3.12/site-packages/airflow/cli/commands/task_command.py", line 341, in _run_raw_task
    return ti._run_raw_task(
           ^^^^^^^^^^^^^^^^^
  File "/home/airflow/.local/lib/python3.12/site-packages/airflow/utils/session.py", line 97, in wrapper
    return func(*args, session=session, **kwargs)
           ^^^^^^^^^^^^^^^^^^^^^^^^^^^^^^^^^^^^^^
  File "/home/airflow/.local/lib/python3.12/site-packages/airflow/models/taskinstance.py", line 3006, in _run_raw_task
    return _run_raw_task(
           ^^^^^^^^^^^^^^
  File "/home/airflow/.local/lib/python3.12/site-packages/airflow/models/taskinstance.py", line 274, in _run_raw_task
    TaskInstance._execute_task_with_callbacks(
  File "/home/airflow/.local/lib/python3.12/site-packages/airflow/models/taskinstance.py", line 3161, in _execute_task_with_callbacks
    result = self._execute_task(context, task_orig)
             ^^^^^^^^^^^^^^^^^^^^^^^^^^^^^^^^^^^^^^
  File "/home/airflow/.local/lib/python3.12/site-packages/airflow/models/taskinstance.py", line 3185, in _execute_task
    return _execute_task(self, context, task_orig)
           ^^^^^^^^^^^^^^^^^^^^^^^^^^^^^^^^^^^^^^^
  File "/home/airflow/.local/lib/python3.12/site-packages/airflow/models/taskinstance.py", line 768, in _execute_task
    result = _execute_callable(context=context, **execute_callable_kwargs)
             ^^^^^^^^^^^^^^^^^^^^^^^^^^^^^^^^^^^^^^^^^^^^^^^^^^^^^^^^^^^^^
  File "/home/airflow/.local/lib/python3.12/site-packages/airflow/models/taskinstance.py", line 734, in _execute_callable
    return ExecutionCallableRunner(
           ^^^^^^^^^^^^^^^^^^^^^^^^
  File "/home/airflow/.local/lib/python3.12/site-packages/airflow/utils/operator_helpers.py", line 252, in run
    return self.func(*args, **kwargs)
           ^^^^^^^^^^^^^^^^^^^^^^^^^^
  File "/home/airflow/.local/lib/python3.12/site-packages/airflow/models/baseoperator.py", line 424, in wrapper
    return func(self, *args, **kwargs)
           ^^^^^^^^^^^^^^^^^^^^^^^^^^^
  File "/home/airflow/.local/lib/python3.12/site-packages/airflow/operators/bash.py", line 276, in execute
    raise AirflowException(
airflow.exceptions.AirflowException: Bash command failed. The command returned a non-zero exit code 125.
[2025-03-24T23:57:28.843+0000] {local_task_job_runner.py:266} INFO - Task exited with return code 1
[2025-03-24T23:57:28.860+0000] {local_task_job_runner.py:245} INFO - ::endgroup::
