[2025-03-24T22:19:12.041+0000] {local_task_job_runner.py:123} INFO - ::group::Pre task execution logs
[2025-03-24T22:19:12.100+0000] {taskinstance.py:2614} INFO - Dependencies all met for dep_context=non-requeueable deps ti=<TaskInstance: containers1_dag.php_app1 scheduled__2024-03-13T00:00:00+00:00 [queued]>
[2025-03-24T22:19:12.137+0000] {taskinstance.py:2614} INFO - Dependencies all met for dep_context=requeueable deps ti=<TaskInstance: containers1_dag.php_app1 scheduled__2024-03-13T00:00:00+00:00 [queued]>
[2025-03-24T22:19:12.137+0000] {taskinstance.py:2867} INFO - Starting attempt 1 of 6
[2025-03-24T22:19:12.380+0000] {taskinstance.py:2890} INFO - Executing <Task(BashOperator): php_app1> on 2024-03-13 00:00:00+00:00
[2025-03-24T22:19:12.421+0000] {logging_mixin.py:190} WARNING - /home/***/.local/lib/python3.12/site-packages/***/task/task_runner/standard_task_runner.py:70 DeprecationWarning: This process (pid=4891) is multi-threaded, use of fork() may lead to deadlocks in the child.
[2025-03-24T22:19:12.426+0000] {standard_task_runner.py:72} INFO - Started process 4903 to run task
[2025-03-24T22:19:12.422+0000] {standard_task_runner.py:104} INFO - Running: ['***', 'tasks', 'run', 'containers1_dag', 'php_app1', 'scheduled__2024-03-13T00:00:00+00:00', '--job-id', '123', '--raw', '--subdir', 'DAGS_FOLDER/containers1_dag.py', '--cfg-path', '/tmp/tmpfluc4g_c']
[2025-03-24T22:19:12.433+0000] {standard_task_runner.py:105} INFO - Job 123: Subtask php_app1
[2025-03-24T22:19:12.592+0000] {task_command.py:467} INFO - Running <TaskInstance: containers1_dag.php_app1 scheduled__2024-03-13T00:00:00+00:00 [running]> on host b9050090f7f5
[2025-03-24T22:19:12.907+0000] {taskinstance.py:3134} INFO - Exporting env vars: AIRFLOW_CTX_DAG_OWNER='andreeppinghaus' AIRFLOW_CTX_DAG_ID='containers1_dag' AIRFLOW_CTX_TASK_ID='php_app1' AIRFLOW_CTX_EXECUTION_DATE='2024-03-13T00:00:00+00:00' AIRFLOW_CTX_TRY_NUMBER='1' AIRFLOW_CTX_DAG_RUN_ID='scheduled__2024-03-13T00:00:00+00:00'
[2025-03-24T22:19:12.908+0000] {taskinstance.py:732} INFO - ::endgroup::
[2025-03-24T22:19:12.963+0000] {subprocess.py:78} INFO - Tmp dir root location: /tmp
[2025-03-24T22:19:12.964+0000] {subprocess.py:88} INFO - Running command: ['/usr/bin/bash', '-c', 'sudo docker run -v $(pwd)/../in:/usr/src/app/in -v $(pwd):/usr/src/app php-app1']
[2025-03-24T22:19:13.009+0000] {subprocess.py:99} INFO - Output:
[2025-03-24T22:19:13.041+0000] {subprocess.py:106} INFO - sudo: a terminal is required to read the password; either use the -S option to read from standard input or configure an askpass helper
[2025-03-24T22:19:13.045+0000] {subprocess.py:106} INFO - sudo: a password is required
[2025-03-24T22:19:13.046+0000] {subprocess.py:110} INFO - Command exited with return code 1
[2025-03-24T22:19:13.113+0000] {taskinstance.py:3313} ERROR - Task failed with exception
Traceback (most recent call last):
  File "/home/airflow/.local/lib/python3.12/site-packages/airflow/models/taskinstance.py", line 768, in _execute_task
    result = _execute_callable(context=context, **execute_callable_kwargs)
             ^^^^^^^^^^^^^^^^^^^^^^^^^^^^^^^^^^^^^^^^^^^^^^^^^^^^^^^^^^^^^
  File "/home/airflow/.local/lib/python3.12/site-packages/airflow/models/taskinstance.py", line 734, in _execute_callable
    return ExecutionCallableRunner(
           ^^^^^^^^^^^^^^^^^^^^^^^^
  File "/home/airflow/.local/lib/python3.12/site-packages/airflow/utils/operator_helpers.py", line 252, in run
    return self.func(*args, **kwargs)
           ^^^^^^^^^^^^^^^^^^^^^^^^^^
  File "/home/airflow/.local/lib/python3.12/site-packages/airflow/models/baseoperator.py", line 424, in wrapper
    return func(self, *args, **kwargs)
           ^^^^^^^^^^^^^^^^^^^^^^^^^^^
  File "/home/airflow/.local/lib/python3.12/site-packages/airflow/operators/bash.py", line 276, in execute
    raise AirflowException(
airflow.exceptions.AirflowException: Bash command failed. The command returned a non-zero exit code 1.
[2025-03-24T22:19:13.147+0000] {taskinstance.py:1226} INFO - Marking task as UP_FOR_RETRY. dag_id=containers1_dag, task_id=php_app1, run_id=scheduled__2024-03-13T00:00:00+00:00, execution_date=20240313T000000, start_date=20250324T221912, end_date=20250324T221913
[2025-03-24T22:19:13.349+0000] {taskinstance.py:341} INFO - ::group::Post task execution logs
[2025-03-24T22:19:13.350+0000] {standard_task_runner.py:124} ERROR - Failed to execute job 123 for task php_app1 (Bash command failed. The command returned a non-zero exit code 1.; 4903)
Traceback (most recent call last):
  File "/home/airflow/.local/lib/python3.12/site-packages/airflow/task/task_runner/standard_task_runner.py", line 117, in _start_by_fork
    ret = args.func(args, dag=self.dag)
          ^^^^^^^^^^^^^^^^^^^^^^^^^^^^^
  File "/home/airflow/.local/lib/python3.12/site-packages/airflow/cli/cli_config.py", line 49, in command
    return func(*args, **kwargs)
           ^^^^^^^^^^^^^^^^^^^^^
  File "/home/airflow/.local/lib/python3.12/site-packages/airflow/utils/cli.py", line 116, in wrapper
    return f(*args, **kwargs)
           ^^^^^^^^^^^^^^^^^^
  File "/home/airflow/.local/lib/python3.12/site-packages/airflow/cli/commands/task_command.py", line 483, in task_run
    task_return_code = _run_task_by_selected_method(args, _dag, ti)
                       ^^^^^^^^^^^^^^^^^^^^^^^^^^^^^^^^^^^^^^^^^^^^
  File "/home/airflow/.local/lib/python3.12/site-packages/airflow/cli/commands/task_command.py", line 256, in _run_task_by_selected_method
    return _run_raw_task(args, ti)
           ^^^^^^^^^^^^^^^^^^^^^^^
  File "/home/airflow/.local/lib/python3.12/site-packages/airflow/cli/commands/task_command.py", line 341, in _run_raw_task
    return ti._run_raw_task(
           ^^^^^^^^^^^^^^^^^
  File "/home/airflow/.local/lib/python3.12/site-packages/airflow/utils/session.py", line 97, in wrapper
    return func(*args, session=session, **kwargs)
           ^^^^^^^^^^^^^^^^^^^^^^^^^^^^^^^^^^^^^^
  File "/home/airflow/.local/lib/python3.12/site-packages/airflow/models/taskinstance.py", line 3006, in _run_raw_task
    return _run_raw_task(
           ^^^^^^^^^^^^^^
  File "/home/airflow/.local/lib/python3.12/site-packages/airflow/models/taskinstance.py", line 274, in _run_raw_task
    TaskInstance._execute_task_with_callbacks(
  File "/home/airflow/.local/lib/python3.12/site-packages/airflow/models/taskinstance.py", line 3161, in _execute_task_with_callbacks
    result = self._execute_task(context, task_orig)
             ^^^^^^^^^^^^^^^^^^^^^^^^^^^^^^^^^^^^^^
  File "/home/airflow/.local/lib/python3.12/site-packages/airflow/models/taskinstance.py", line 3185, in _execute_task
    return _execute_task(self, context, task_orig)
           ^^^^^^^^^^^^^^^^^^^^^^^^^^^^^^^^^^^^^^^
  File "/home/airflow/.local/lib/python3.12/site-packages/airflow/models/taskinstance.py", line 768, in _execute_task
    result = _execute_callable(context=context, **execute_callable_kwargs)
             ^^^^^^^^^^^^^^^^^^^^^^^^^^^^^^^^^^^^^^^^^^^^^^^^^^^^^^^^^^^^^
  File "/home/airflow/.local/lib/python3.12/site-packages/airflow/models/taskinstance.py", line 734, in _execute_callable
    return ExecutionCallableRunner(
           ^^^^^^^^^^^^^^^^^^^^^^^^
  File "/home/airflow/.local/lib/python3.12/site-packages/airflow/utils/operator_helpers.py", line 252, in run
    return self.func(*args, **kwargs)
           ^^^^^^^^^^^^^^^^^^^^^^^^^^
  File "/home/airflow/.local/lib/python3.12/site-packages/airflow/models/baseoperator.py", line 424, in wrapper
    return func(self, *args, **kwargs)
           ^^^^^^^^^^^^^^^^^^^^^^^^^^^
  File "/home/airflow/.local/lib/python3.12/site-packages/airflow/operators/bash.py", line 276, in execute
    raise AirflowException(
airflow.exceptions.AirflowException: Bash command failed. The command returned a non-zero exit code 1.
[2025-03-24T22:19:13.382+0000] {local_task_job_runner.py:266} INFO - Task exited with return code 1
[2025-03-24T22:19:13.440+0000] {taskinstance.py:3901} INFO - 0 downstream tasks scheduled from follow-on schedule check
[2025-03-24T22:19:13.446+0000] {local_task_job_runner.py:245} INFO - ::endgroup::
[2025-03-24T22:24:22.985+0000] {local_task_job_runner.py:123} INFO - ::group::Pre task execution logs
[2025-03-24T22:24:23.200+0000] {taskinstance.py:2614} INFO - Dependencies all met for dep_context=non-requeueable deps ti=<TaskInstance: containers1_dag.php_app1 scheduled__2024-03-13T00:00:00+00:00 [queued]>
[2025-03-24T22:24:23.250+0000] {taskinstance.py:2614} INFO - Dependencies all met for dep_context=requeueable deps ti=<TaskInstance: containers1_dag.php_app1 scheduled__2024-03-13T00:00:00+00:00 [queued]>
[2025-03-24T22:24:23.251+0000] {taskinstance.py:2867} INFO - Starting attempt 1 of 6
[2025-03-24T22:24:23.354+0000] {taskinstance.py:2890} INFO - Executing <Task(BashOperator): php_app1> on 2024-03-13 00:00:00+00:00
[2025-03-24T22:24:23.427+0000] {standard_task_runner.py:104} INFO - Running: ['***', 'tasks', 'run', 'containers1_dag', 'php_app1', 'scheduled__2024-03-13T00:00:00+00:00', '--job-id', '168', '--raw', '--subdir', 'DAGS_FOLDER/containers1_dag.py', '--cfg-path', '/tmp/tmpjr_dhkv2']
[2025-03-24T22:24:23.431+0000] {standard_task_runner.py:105} INFO - Job 168: Subtask php_app1
[2025-03-24T22:24:23.479+0000] {logging_mixin.py:190} WARNING - /home/***/.local/lib/python3.12/site-packages/***/task/task_runner/standard_task_runner.py:70 DeprecationWarning: This process (pid=5345) is multi-threaded, use of fork() may lead to deadlocks in the child.
[2025-03-24T22:24:23.498+0000] {standard_task_runner.py:72} INFO - Started process 5377 to run task
[2025-03-24T22:24:23.954+0000] {task_command.py:467} INFO - Running <TaskInstance: containers1_dag.php_app1 scheduled__2024-03-13T00:00:00+00:00 [running]> on host b9050090f7f5
[2025-03-24T22:24:24.722+0000] {taskinstance.py:3134} INFO - Exporting env vars: AIRFLOW_CTX_DAG_OWNER='andre' AIRFLOW_CTX_DAG_ID='containers1_dag' AIRFLOW_CTX_TASK_ID='php_app1' AIRFLOW_CTX_EXECUTION_DATE='2024-03-13T00:00:00+00:00' AIRFLOW_CTX_TRY_NUMBER='1' AIRFLOW_CTX_DAG_RUN_ID='scheduled__2024-03-13T00:00:00+00:00'
[2025-03-24T22:24:24.724+0000] {taskinstance.py:732} INFO - ::endgroup::
[2025-03-24T22:24:24.974+0000] {subprocess.py:78} INFO - Tmp dir root location: /tmp
[2025-03-24T22:24:24.975+0000] {subprocess.py:88} INFO - Running command: ['/usr/bin/bash', '-c', 'sudo docker run -v $(pwd)/../in:/usr/src/app/in -v $(pwd):/usr/src/app php-app1']
[2025-03-24T22:24:25.028+0000] {subprocess.py:99} INFO - Output:
[2025-03-24T22:24:25.064+0000] {subprocess.py:106} INFO - sudo: a terminal is required to read the password; either use the -S option to read from standard input or configure an askpass helper
[2025-03-24T22:24:25.068+0000] {subprocess.py:106} INFO - sudo: a password is required
[2025-03-24T22:24:25.069+0000] {subprocess.py:110} INFO - Command exited with return code 1
[2025-03-24T22:24:25.110+0000] {taskinstance.py:3313} ERROR - Task failed with exception
Traceback (most recent call last):
  File "/home/airflow/.local/lib/python3.12/site-packages/airflow/models/taskinstance.py", line 768, in _execute_task
    result = _execute_callable(context=context, **execute_callable_kwargs)
             ^^^^^^^^^^^^^^^^^^^^^^^^^^^^^^^^^^^^^^^^^^^^^^^^^^^^^^^^^^^^^
  File "/home/airflow/.local/lib/python3.12/site-packages/airflow/models/taskinstance.py", line 734, in _execute_callable
    return ExecutionCallableRunner(
           ^^^^^^^^^^^^^^^^^^^^^^^^
  File "/home/airflow/.local/lib/python3.12/site-packages/airflow/utils/operator_helpers.py", line 252, in run
    return self.func(*args, **kwargs)
           ^^^^^^^^^^^^^^^^^^^^^^^^^^
  File "/home/airflow/.local/lib/python3.12/site-packages/airflow/models/baseoperator.py", line 424, in wrapper
    return func(self, *args, **kwargs)
           ^^^^^^^^^^^^^^^^^^^^^^^^^^^
  File "/home/airflow/.local/lib/python3.12/site-packages/airflow/operators/bash.py", line 276, in execute
    raise AirflowException(
airflow.exceptions.AirflowException: Bash command failed. The command returned a non-zero exit code 1.
[2025-03-24T22:24:25.147+0000] {taskinstance.py:1226} INFO - Marking task as UP_FOR_RETRY. dag_id=containers1_dag, task_id=php_app1, run_id=scheduled__2024-03-13T00:00:00+00:00, execution_date=20240313T000000, start_date=20250324T222423, end_date=20250324T222425
[2025-03-24T22:24:25.302+0000] {taskinstance.py:341} INFO - ::group::Post task execution logs
[2025-03-24T22:24:25.303+0000] {standard_task_runner.py:124} ERROR - Failed to execute job 168 for task php_app1 (Bash command failed. The command returned a non-zero exit code 1.; 5377)
Traceback (most recent call last):
  File "/home/airflow/.local/lib/python3.12/site-packages/airflow/task/task_runner/standard_task_runner.py", line 117, in _start_by_fork
    ret = args.func(args, dag=self.dag)
          ^^^^^^^^^^^^^^^^^^^^^^^^^^^^^
  File "/home/airflow/.local/lib/python3.12/site-packages/airflow/cli/cli_config.py", line 49, in command
    return func(*args, **kwargs)
           ^^^^^^^^^^^^^^^^^^^^^
  File "/home/airflow/.local/lib/python3.12/site-packages/airflow/utils/cli.py", line 116, in wrapper
    return f(*args, **kwargs)
           ^^^^^^^^^^^^^^^^^^
  File "/home/airflow/.local/lib/python3.12/site-packages/airflow/cli/commands/task_command.py", line 483, in task_run
    task_return_code = _run_task_by_selected_method(args, _dag, ti)
                       ^^^^^^^^^^^^^^^^^^^^^^^^^^^^^^^^^^^^^^^^^^^^
  File "/home/airflow/.local/lib/python3.12/site-packages/airflow/cli/commands/task_command.py", line 256, in _run_task_by_selected_method
    return _run_raw_task(args, ti)
           ^^^^^^^^^^^^^^^^^^^^^^^
  File "/home/airflow/.local/lib/python3.12/site-packages/airflow/cli/commands/task_command.py", line 341, in _run_raw_task
    return ti._run_raw_task(
           ^^^^^^^^^^^^^^^^^
  File "/home/airflow/.local/lib/python3.12/site-packages/airflow/utils/session.py", line 97, in wrapper
    return func(*args, session=session, **kwargs)
           ^^^^^^^^^^^^^^^^^^^^^^^^^^^^^^^^^^^^^^
  File "/home/airflow/.local/lib/python3.12/site-packages/airflow/models/taskinstance.py", line 3006, in _run_raw_task
    return _run_raw_task(
           ^^^^^^^^^^^^^^
  File "/home/airflow/.local/lib/python3.12/site-packages/airflow/models/taskinstance.py", line 274, in _run_raw_task
    TaskInstance._execute_task_with_callbacks(
  File "/home/airflow/.local/lib/python3.12/site-packages/airflow/models/taskinstance.py", line 3161, in _execute_task_with_callbacks
    result = self._execute_task(context, task_orig)
             ^^^^^^^^^^^^^^^^^^^^^^^^^^^^^^^^^^^^^^
  File "/home/airflow/.local/lib/python3.12/site-packages/airflow/models/taskinstance.py", line 3185, in _execute_task
    return _execute_task(self, context, task_orig)
           ^^^^^^^^^^^^^^^^^^^^^^^^^^^^^^^^^^^^^^^
  File "/home/airflow/.local/lib/python3.12/site-packages/airflow/models/taskinstance.py", line 768, in _execute_task
    result = _execute_callable(context=context, **execute_callable_kwargs)
             ^^^^^^^^^^^^^^^^^^^^^^^^^^^^^^^^^^^^^^^^^^^^^^^^^^^^^^^^^^^^^
  File "/home/airflow/.local/lib/python3.12/site-packages/airflow/models/taskinstance.py", line 734, in _execute_callable
    return ExecutionCallableRunner(
           ^^^^^^^^^^^^^^^^^^^^^^^^
  File "/home/airflow/.local/lib/python3.12/site-packages/airflow/utils/operator_helpers.py", line 252, in run
    return self.func(*args, **kwargs)
           ^^^^^^^^^^^^^^^^^^^^^^^^^^
  File "/home/airflow/.local/lib/python3.12/site-packages/airflow/models/baseoperator.py", line 424, in wrapper
    return func(self, *args, **kwargs)
           ^^^^^^^^^^^^^^^^^^^^^^^^^^^
  File "/home/airflow/.local/lib/python3.12/site-packages/airflow/operators/bash.py", line 276, in execute
    raise AirflowException(
airflow.exceptions.AirflowException: Bash command failed. The command returned a non-zero exit code 1.
[2025-03-24T22:24:25.356+0000] {local_task_job_runner.py:266} INFO - Task exited with return code 1
[2025-03-24T22:24:25.433+0000] {taskinstance.py:3901} INFO - 0 downstream tasks scheduled from follow-on schedule check
[2025-03-24T22:24:25.442+0000] {local_task_job_runner.py:245} INFO - ::endgroup::
[2025-03-24T22:27:31.106+0000] {local_task_job_runner.py:123} INFO - ::group::Pre task execution logs
[2025-03-24T22:27:31.153+0000] {taskinstance.py:2614} INFO - Dependencies all met for dep_context=non-requeueable deps ti=<TaskInstance: containers1_dag.php_app1 scheduled__2024-03-13T00:00:00+00:00 [queued]>
[2025-03-24T22:27:31.172+0000] {taskinstance.py:2614} INFO - Dependencies all met for dep_context=requeueable deps ti=<TaskInstance: containers1_dag.php_app1 scheduled__2024-03-13T00:00:00+00:00 [queued]>
[2025-03-24T22:27:31.173+0000] {taskinstance.py:2867} INFO - Starting attempt 1 of 6
[2025-03-24T22:27:31.222+0000] {taskinstance.py:2890} INFO - Executing <Task(BashOperator): php_app1> on 2024-03-13 00:00:00+00:00
[2025-03-24T22:27:31.255+0000] {logging_mixin.py:190} WARNING - /home/***/.local/lib/python3.12/site-packages/***/task/task_runner/standard_task_runner.py:70 DeprecationWarning: This process (pid=5827) is multi-threaded, use of fork() may lead to deadlocks in the child.
[2025-03-24T22:27:31.265+0000] {standard_task_runner.py:72} INFO - Started process 5831 to run task
[2025-03-24T22:27:31.260+0000] {standard_task_runner.py:104} INFO - Running: ['***', 'tasks', 'run', 'containers1_dag', 'php_app1', 'scheduled__2024-03-13T00:00:00+00:00', '--job-id', '197', '--raw', '--subdir', 'DAGS_FOLDER/containers1_dag.py', '--cfg-path', '/tmp/tmpiii0zm1r']
[2025-03-24T22:27:31.268+0000] {standard_task_runner.py:105} INFO - Job 197: Subtask php_app1
[2025-03-24T22:27:31.651+0000] {task_command.py:467} INFO - Running <TaskInstance: containers1_dag.php_app1 scheduled__2024-03-13T00:00:00+00:00 [running]> on host b9050090f7f5
[2025-03-24T22:27:32.483+0000] {taskinstance.py:3134} INFO - Exporting env vars: AIRFLOW_CTX_DAG_OWNER='andre' AIRFLOW_CTX_DAG_ID='containers1_dag' AIRFLOW_CTX_TASK_ID='php_app1' AIRFLOW_CTX_EXECUTION_DATE='2024-03-13T00:00:00+00:00' AIRFLOW_CTX_TRY_NUMBER='1' AIRFLOW_CTX_DAG_RUN_ID='scheduled__2024-03-13T00:00:00+00:00'
[2025-03-24T22:27:32.495+0000] {taskinstance.py:732} INFO - ::endgroup::
[2025-03-24T22:27:32.661+0000] {subprocess.py:78} INFO - Tmp dir root location: /tmp
[2025-03-24T22:27:32.664+0000] {subprocess.py:88} INFO - Running command: ['/usr/bin/bash', '-c', 'docker run -v $(pwd)/../in:/usr/src/app/in -v $(pwd):/usr/src/app php-app1']
[2025-03-24T22:27:32.723+0000] {subprocess.py:99} INFO - Output:
[2025-03-24T22:27:32.797+0000] {subprocess.py:106} INFO - docker: Cannot connect to the Docker daemon at unix:///var/run/docker.sock. Is the docker daemon running?.
[2025-03-24T22:27:32.798+0000] {subprocess.py:106} INFO - See 'docker run --help'.
[2025-03-24T22:27:32.819+0000] {subprocess.py:110} INFO - Command exited with return code 125
[2025-03-24T22:27:32.891+0000] {taskinstance.py:3313} ERROR - Task failed with exception
Traceback (most recent call last):
  File "/home/airflow/.local/lib/python3.12/site-packages/airflow/models/taskinstance.py", line 768, in _execute_task
    result = _execute_callable(context=context, **execute_callable_kwargs)
             ^^^^^^^^^^^^^^^^^^^^^^^^^^^^^^^^^^^^^^^^^^^^^^^^^^^^^^^^^^^^^
  File "/home/airflow/.local/lib/python3.12/site-packages/airflow/models/taskinstance.py", line 734, in _execute_callable
    return ExecutionCallableRunner(
           ^^^^^^^^^^^^^^^^^^^^^^^^
  File "/home/airflow/.local/lib/python3.12/site-packages/airflow/utils/operator_helpers.py", line 252, in run
    return self.func(*args, **kwargs)
           ^^^^^^^^^^^^^^^^^^^^^^^^^^
  File "/home/airflow/.local/lib/python3.12/site-packages/airflow/models/baseoperator.py", line 424, in wrapper
    return func(self, *args, **kwargs)
           ^^^^^^^^^^^^^^^^^^^^^^^^^^^
  File "/home/airflow/.local/lib/python3.12/site-packages/airflow/operators/bash.py", line 276, in execute
    raise AirflowException(
airflow.exceptions.AirflowException: Bash command failed. The command returned a non-zero exit code 125.
[2025-03-24T22:27:32.931+0000] {taskinstance.py:1226} INFO - Marking task as UP_FOR_RETRY. dag_id=containers1_dag, task_id=php_app1, run_id=scheduled__2024-03-13T00:00:00+00:00, execution_date=20240313T000000, start_date=20250324T222731, end_date=20250324T222732
[2025-03-24T22:27:33.115+0000] {taskinstance.py:341} INFO - ::group::Post task execution logs
[2025-03-24T22:27:33.126+0000] {standard_task_runner.py:124} ERROR - Failed to execute job 197 for task php_app1 (Bash command failed. The command returned a non-zero exit code 125.; 5831)
Traceback (most recent call last):
  File "/home/airflow/.local/lib/python3.12/site-packages/airflow/task/task_runner/standard_task_runner.py", line 117, in _start_by_fork
    ret = args.func(args, dag=self.dag)
          ^^^^^^^^^^^^^^^^^^^^^^^^^^^^^
  File "/home/airflow/.local/lib/python3.12/site-packages/airflow/cli/cli_config.py", line 49, in command
    return func(*args, **kwargs)
           ^^^^^^^^^^^^^^^^^^^^^
  File "/home/airflow/.local/lib/python3.12/site-packages/airflow/utils/cli.py", line 116, in wrapper
    return f(*args, **kwargs)
           ^^^^^^^^^^^^^^^^^^
  File "/home/airflow/.local/lib/python3.12/site-packages/airflow/cli/commands/task_command.py", line 483, in task_run
    task_return_code = _run_task_by_selected_method(args, _dag, ti)
                       ^^^^^^^^^^^^^^^^^^^^^^^^^^^^^^^^^^^^^^^^^^^^
  File "/home/airflow/.local/lib/python3.12/site-packages/airflow/cli/commands/task_command.py", line 256, in _run_task_by_selected_method
    return _run_raw_task(args, ti)
           ^^^^^^^^^^^^^^^^^^^^^^^
  File "/home/airflow/.local/lib/python3.12/site-packages/airflow/cli/commands/task_command.py", line 341, in _run_raw_task
    return ti._run_raw_task(
           ^^^^^^^^^^^^^^^^^
  File "/home/airflow/.local/lib/python3.12/site-packages/airflow/utils/session.py", line 97, in wrapper
    return func(*args, session=session, **kwargs)
           ^^^^^^^^^^^^^^^^^^^^^^^^^^^^^^^^^^^^^^
  File "/home/airflow/.local/lib/python3.12/site-packages/airflow/models/taskinstance.py", line 3006, in _run_raw_task
    return _run_raw_task(
           ^^^^^^^^^^^^^^
  File "/home/airflow/.local/lib/python3.12/site-packages/airflow/models/taskinstance.py", line 274, in _run_raw_task
    TaskInstance._execute_task_with_callbacks(
  File "/home/airflow/.local/lib/python3.12/site-packages/airflow/models/taskinstance.py", line 3161, in _execute_task_with_callbacks
    result = self._execute_task(context, task_orig)
             ^^^^^^^^^^^^^^^^^^^^^^^^^^^^^^^^^^^^^^
  File "/home/airflow/.local/lib/python3.12/site-packages/airflow/models/taskinstance.py", line 3185, in _execute_task
    return _execute_task(self, context, task_orig)
           ^^^^^^^^^^^^^^^^^^^^^^^^^^^^^^^^^^^^^^^
  File "/home/airflow/.local/lib/python3.12/site-packages/airflow/models/taskinstance.py", line 768, in _execute_task
    result = _execute_callable(context=context, **execute_callable_kwargs)
             ^^^^^^^^^^^^^^^^^^^^^^^^^^^^^^^^^^^^^^^^^^^^^^^^^^^^^^^^^^^^^
  File "/home/airflow/.local/lib/python3.12/site-packages/airflow/models/taskinstance.py", line 734, in _execute_callable
    return ExecutionCallableRunner(
           ^^^^^^^^^^^^^^^^^^^^^^^^
  File "/home/airflow/.local/lib/python3.12/site-packages/airflow/utils/operator_helpers.py", line 252, in run
    return self.func(*args, **kwargs)
           ^^^^^^^^^^^^^^^^^^^^^^^^^^
  File "/home/airflow/.local/lib/python3.12/site-packages/airflow/models/baseoperator.py", line 424, in wrapper
    return func(self, *args, **kwargs)
           ^^^^^^^^^^^^^^^^^^^^^^^^^^^
  File "/home/airflow/.local/lib/python3.12/site-packages/airflow/operators/bash.py", line 276, in execute
    raise AirflowException(
airflow.exceptions.AirflowException: Bash command failed. The command returned a non-zero exit code 125.
[2025-03-24T22:27:33.198+0000] {local_task_job_runner.py:266} INFO - Task exited with return code 1
[2025-03-24T22:27:33.279+0000] {taskinstance.py:3901} INFO - 0 downstream tasks scheduled from follow-on schedule check
[2025-03-24T22:27:33.308+0000] {local_task_job_runner.py:245} INFO - ::endgroup::
[2025-03-24T23:57:31.813+0000] {local_task_job_runner.py:123} INFO - ::group::Pre task execution logs
[2025-03-24T23:57:31.887+0000] {taskinstance.py:2614} INFO - Dependencies all met for dep_context=non-requeueable deps ti=<TaskInstance: containers1_dag.php_app1 scheduled__2024-03-13T00:00:00+00:00 [queued]>
[2025-03-24T23:57:31.913+0000] {taskinstance.py:2614} INFO - Dependencies all met for dep_context=requeueable deps ti=<TaskInstance: containers1_dag.php_app1 scheduled__2024-03-13T00:00:00+00:00 [queued]>
[2025-03-24T23:57:31.914+0000] {taskinstance.py:2867} INFO - Starting attempt 1 of 6
[2025-03-24T23:57:31.966+0000] {taskinstance.py:2890} INFO - Executing <Task(BashOperator): php_app1> on 2024-03-13 00:00:00+00:00
[2025-03-24T23:57:31.989+0000] {standard_task_runner.py:104} INFO - Running: ['***', 'tasks', 'run', 'containers1_dag', 'php_app1', 'scheduled__2024-03-13T00:00:00+00:00', '--job-id', '27', '--raw', '--subdir', 'DAGS_FOLDER/containers1_dag.py', '--cfg-path', '/tmp/tmpkidsr5w5']
[2025-03-24T23:57:32.012+0000] {standard_task_runner.py:105} INFO - Job 27: Subtask php_app1
[2025-03-24T23:57:32.025+0000] {logging_mixin.py:190} WARNING - /home/***/.local/lib/python3.12/site-packages/***/task/task_runner/standard_task_runner.py:70 DeprecationWarning: This process (pid=495) is multi-threaded, use of fork() may lead to deadlocks in the child.
[2025-03-24T23:57:32.028+0000] {standard_task_runner.py:72} INFO - Started process 524 to run task
[2025-03-24T23:57:32.226+0000] {task_command.py:467} INFO - Running <TaskInstance: containers1_dag.php_app1 scheduled__2024-03-13T00:00:00+00:00 [running]> on host 8e89fdaa3360
[2025-03-24T23:57:32.571+0000] {taskinstance.py:3134} INFO - Exporting env vars: AIRFLOW_CTX_DAG_OWNER='andre' AIRFLOW_CTX_DAG_ID='containers1_dag' AIRFLOW_CTX_TASK_ID='php_app1' AIRFLOW_CTX_EXECUTION_DATE='2024-03-13T00:00:00+00:00' AIRFLOW_CTX_TRY_NUMBER='1' AIRFLOW_CTX_DAG_RUN_ID='scheduled__2024-03-13T00:00:00+00:00'
[2025-03-24T23:57:32.576+0000] {taskinstance.py:732} INFO - ::endgroup::
[2025-03-24T23:57:32.667+0000] {subprocess.py:78} INFO - Tmp dir root location: /tmp
[2025-03-24T23:57:32.668+0000] {subprocess.py:88} INFO - Running command: ['/usr/bin/bash', '-c', 'docker run -v $(pwd)/../in:/usr/src/app/in -v $(pwd):/usr/src/app php-app1']
[2025-03-24T23:57:32.699+0000] {subprocess.py:99} INFO - Output:
[2025-03-24T23:57:32.753+0000] {subprocess.py:106} INFO - docker: Cannot connect to the Docker daemon at unix:///var/run/docker.sock. Is the docker daemon running?.
[2025-03-24T23:57:32.754+0000] {subprocess.py:106} INFO - See 'docker run --help'.
[2025-03-24T23:57:32.757+0000] {subprocess.py:110} INFO - Command exited with return code 125
[2025-03-24T23:57:32.779+0000] {taskinstance.py:3313} ERROR - Task failed with exception
Traceback (most recent call last):
  File "/home/airflow/.local/lib/python3.12/site-packages/airflow/models/taskinstance.py", line 768, in _execute_task
    result = _execute_callable(context=context, **execute_callable_kwargs)
             ^^^^^^^^^^^^^^^^^^^^^^^^^^^^^^^^^^^^^^^^^^^^^^^^^^^^^^^^^^^^^
  File "/home/airflow/.local/lib/python3.12/site-packages/airflow/models/taskinstance.py", line 734, in _execute_callable
    return ExecutionCallableRunner(
           ^^^^^^^^^^^^^^^^^^^^^^^^
  File "/home/airflow/.local/lib/python3.12/site-packages/airflow/utils/operator_helpers.py", line 252, in run
    return self.func(*args, **kwargs)
           ^^^^^^^^^^^^^^^^^^^^^^^^^^
  File "/home/airflow/.local/lib/python3.12/site-packages/airflow/models/baseoperator.py", line 424, in wrapper
    return func(self, *args, **kwargs)
           ^^^^^^^^^^^^^^^^^^^^^^^^^^^
  File "/home/airflow/.local/lib/python3.12/site-packages/airflow/operators/bash.py", line 276, in execute
    raise AirflowException(
airflow.exceptions.AirflowException: Bash command failed. The command returned a non-zero exit code 125.
[2025-03-24T23:57:32.798+0000] {taskinstance.py:1226} INFO - Marking task as UP_FOR_RETRY. dag_id=containers1_dag, task_id=php_app1, run_id=scheduled__2024-03-13T00:00:00+00:00, execution_date=20240313T000000, start_date=20250324T235731, end_date=20250324T235732
[2025-03-24T23:57:32.884+0000] {taskinstance.py:341} INFO - ::group::Post task execution logs
[2025-03-24T23:57:32.885+0000] {standard_task_runner.py:124} ERROR - Failed to execute job 27 for task php_app1 (Bash command failed. The command returned a non-zero exit code 125.; 524)
Traceback (most recent call last):
  File "/home/airflow/.local/lib/python3.12/site-packages/airflow/task/task_runner/standard_task_runner.py", line 117, in _start_by_fork
    ret = args.func(args, dag=self.dag)
          ^^^^^^^^^^^^^^^^^^^^^^^^^^^^^
  File "/home/airflow/.local/lib/python3.12/site-packages/airflow/cli/cli_config.py", line 49, in command
    return func(*args, **kwargs)
           ^^^^^^^^^^^^^^^^^^^^^
  File "/home/airflow/.local/lib/python3.12/site-packages/airflow/utils/cli.py", line 116, in wrapper
    return f(*args, **kwargs)
           ^^^^^^^^^^^^^^^^^^
  File "/home/airflow/.local/lib/python3.12/site-packages/airflow/cli/commands/task_command.py", line 483, in task_run
    task_return_code = _run_task_by_selected_method(args, _dag, ti)
                       ^^^^^^^^^^^^^^^^^^^^^^^^^^^^^^^^^^^^^^^^^^^^
  File "/home/airflow/.local/lib/python3.12/site-packages/airflow/cli/commands/task_command.py", line 256, in _run_task_by_selected_method
    return _run_raw_task(args, ti)
           ^^^^^^^^^^^^^^^^^^^^^^^
  File "/home/airflow/.local/lib/python3.12/site-packages/airflow/cli/commands/task_command.py", line 341, in _run_raw_task
    return ti._run_raw_task(
           ^^^^^^^^^^^^^^^^^
  File "/home/airflow/.local/lib/python3.12/site-packages/airflow/utils/session.py", line 97, in wrapper
    return func(*args, session=session, **kwargs)
           ^^^^^^^^^^^^^^^^^^^^^^^^^^^^^^^^^^^^^^
  File "/home/airflow/.local/lib/python3.12/site-packages/airflow/models/taskinstance.py", line 3006, in _run_raw_task
    return _run_raw_task(
           ^^^^^^^^^^^^^^
  File "/home/airflow/.local/lib/python3.12/site-packages/airflow/models/taskinstance.py", line 274, in _run_raw_task
    TaskInstance._execute_task_with_callbacks(
  File "/home/airflow/.local/lib/python3.12/site-packages/airflow/models/taskinstance.py", line 3161, in _execute_task_with_callbacks
    result = self._execute_task(context, task_orig)
             ^^^^^^^^^^^^^^^^^^^^^^^^^^^^^^^^^^^^^^
  File "/home/airflow/.local/lib/python3.12/site-packages/airflow/models/taskinstance.py", line 3185, in _execute_task
    return _execute_task(self, context, task_orig)
           ^^^^^^^^^^^^^^^^^^^^^^^^^^^^^^^^^^^^^^^
  File "/home/airflow/.local/lib/python3.12/site-packages/airflow/models/taskinstance.py", line 768, in _execute_task
    result = _execute_callable(context=context, **execute_callable_kwargs)
             ^^^^^^^^^^^^^^^^^^^^^^^^^^^^^^^^^^^^^^^^^^^^^^^^^^^^^^^^^^^^^
  File "/home/airflow/.local/lib/python3.12/site-packages/airflow/models/taskinstance.py", line 734, in _execute_callable
    return ExecutionCallableRunner(
           ^^^^^^^^^^^^^^^^^^^^^^^^
  File "/home/airflow/.local/lib/python3.12/site-packages/airflow/utils/operator_helpers.py", line 252, in run
    return self.func(*args, **kwargs)
           ^^^^^^^^^^^^^^^^^^^^^^^^^^
  File "/home/airflow/.local/lib/python3.12/site-packages/airflow/models/baseoperator.py", line 424, in wrapper
    return func(self, *args, **kwargs)
           ^^^^^^^^^^^^^^^^^^^^^^^^^^^
  File "/home/airflow/.local/lib/python3.12/site-packages/airflow/operators/bash.py", line 276, in execute
    raise AirflowException(
airflow.exceptions.AirflowException: Bash command failed. The command returned a non-zero exit code 125.
[2025-03-24T23:57:32.933+0000] {local_task_job_runner.py:266} INFO - Task exited with return code 1
[2025-03-24T23:57:32.952+0000] {local_task_job_runner.py:245} INFO - ::endgroup::
[2025-03-25T00:18:40.397+0000] {local_task_job_runner.py:123} INFO - ::group::Pre task execution logs
[2025-03-25T00:18:40.465+0000] {taskinstance.py:2614} INFO - Dependencies all met for dep_context=non-requeueable deps ti=<TaskInstance: containers1_dag.php_app1 scheduled__2024-03-13T00:00:00+00:00 [queued]>
[2025-03-25T00:18:40.486+0000] {taskinstance.py:2614} INFO - Dependencies all met for dep_context=requeueable deps ti=<TaskInstance: containers1_dag.php_app1 scheduled__2024-03-13T00:00:00+00:00 [queued]>
[2025-03-25T00:18:40.486+0000] {taskinstance.py:2867} INFO - Starting attempt 1 of 6
[2025-03-25T00:18:40.531+0000] {taskinstance.py:2890} INFO - Executing <Task(DockerOperator): php_app1> on 2024-03-13 00:00:00+00:00
[2025-03-25T00:18:40.571+0000] {logging_mixin.py:190} WARNING - /home/***/.local/lib/python3.12/site-packages/***/task/task_runner/standard_task_runner.py:70 DeprecationWarning: This process (pid=452) is multi-threaded, use of fork() may lead to deadlocks in the child.
[2025-03-25T00:18:40.572+0000] {standard_task_runner.py:72} INFO - Started process 465 to run task
[2025-03-25T00:18:40.574+0000] {standard_task_runner.py:104} INFO - Running: ['***', 'tasks', 'run', 'containers1_dag', 'php_app1', 'scheduled__2024-03-13T00:00:00+00:00', '--job-id', '28', '--raw', '--subdir', 'DAGS_FOLDER/containers1_dag.py', '--cfg-path', '/tmp/tmpndoz6mx1']
[2025-03-25T00:18:40.588+0000] {standard_task_runner.py:105} INFO - Job 28: Subtask php_app1
[2025-03-25T00:18:41.234+0000] {task_command.py:467} INFO - Running <TaskInstance: containers1_dag.php_app1 scheduled__2024-03-13T00:00:00+00:00 [running]> on host 0f77abd8a5ce
[2025-03-25T00:18:41.959+0000] {taskinstance.py:3134} INFO - Exporting env vars: AIRFLOW_CTX_DAG_OWNER='andre' AIRFLOW_CTX_DAG_ID='containers1_dag' AIRFLOW_CTX_TASK_ID='php_app1' AIRFLOW_CTX_EXECUTION_DATE='2024-03-13T00:00:00+00:00' AIRFLOW_CTX_TRY_NUMBER='1' AIRFLOW_CTX_DAG_RUN_ID='scheduled__2024-03-13T00:00:00+00:00'
[2025-03-25T00:18:41.960+0000] {taskinstance.py:732} INFO - ::endgroup::
[2025-03-25T00:18:42.042+0000] {docker.py:157} ERROR - Failed to establish connection to Docker host unix://var/run/docker.sock: Error while fetching server API version: ('Connection aborted.', FileNotFoundError(2, 'No such file or directory'))
[2025-03-25T00:18:42.138+0000] {taskinstance.py:3313} ERROR - Task failed with exception
Traceback (most recent call last):
  File "/home/airflow/.local/lib/python3.12/site-packages/airflow/models/taskinstance.py", line 768, in _execute_task
    result = _execute_callable(context=context, **execute_callable_kwargs)
             ^^^^^^^^^^^^^^^^^^^^^^^^^^^^^^^^^^^^^^^^^^^^^^^^^^^^^^^^^^^^^
  File "/home/airflow/.local/lib/python3.12/site-packages/airflow/models/taskinstance.py", line 734, in _execute_callable
    return ExecutionCallableRunner(
           ^^^^^^^^^^^^^^^^^^^^^^^^
  File "/home/airflow/.local/lib/python3.12/site-packages/airflow/utils/operator_helpers.py", line 252, in run
    return self.func(*args, **kwargs)
           ^^^^^^^^^^^^^^^^^^^^^^^^^^
  File "/home/airflow/.local/lib/python3.12/site-packages/airflow/models/baseoperator.py", line 424, in wrapper
    return func(self, *args, **kwargs)
           ^^^^^^^^^^^^^^^^^^^^^^^^^^^
  File "/home/airflow/.local/lib/python3.12/site-packages/airflow/providers/docker/operators/docker.py", line 467, in execute
    if self.force_pull or not self.cli.images(name=self.image):
                              ^^^^^^^^
  File "/home/airflow/.local/lib/python3.12/site-packages/airflow/providers/docker/operators/docker.py", line 341, in cli
    return self.hook.api_client
           ^^^^^^^^^^^^^^^^^^^^
  File "/usr/local/lib/python3.12/functools.py", line 998, in __get__
    val = self.func(instance)
          ^^^^^^^^^^^^^^^^^^^
  File "/home/airflow/.local/lib/python3.12/site-packages/airflow/providers/docker/hooks/docker.py", line 161, in api_client
    raise AirflowException("Failed to establish connection to any given Docker hosts.")
airflow.exceptions.AirflowException: Failed to establish connection to any given Docker hosts.
[2025-03-25T00:18:42.156+0000] {taskinstance.py:1226} INFO - Marking task as UP_FOR_RETRY. dag_id=containers1_dag, task_id=php_app1, run_id=scheduled__2024-03-13T00:00:00+00:00, execution_date=20240313T000000, start_date=20250325T001840, end_date=20250325T001842
[2025-03-25T00:18:42.505+0000] {taskinstance.py:341} INFO - ::group::Post task execution logs
[2025-03-25T00:18:42.506+0000] {standard_task_runner.py:124} ERROR - Failed to execute job 28 for task php_app1 (Failed to establish connection to any given Docker hosts.; 465)
Traceback (most recent call last):
  File "/home/airflow/.local/lib/python3.12/site-packages/airflow/task/task_runner/standard_task_runner.py", line 117, in _start_by_fork
    ret = args.func(args, dag=self.dag)
          ^^^^^^^^^^^^^^^^^^^^^^^^^^^^^
  File "/home/airflow/.local/lib/python3.12/site-packages/airflow/cli/cli_config.py", line 49, in command
    return func(*args, **kwargs)
           ^^^^^^^^^^^^^^^^^^^^^
  File "/home/airflow/.local/lib/python3.12/site-packages/airflow/utils/cli.py", line 116, in wrapper
    return f(*args, **kwargs)
           ^^^^^^^^^^^^^^^^^^
  File "/home/airflow/.local/lib/python3.12/site-packages/airflow/cli/commands/task_command.py", line 483, in task_run
    task_return_code = _run_task_by_selected_method(args, _dag, ti)
                       ^^^^^^^^^^^^^^^^^^^^^^^^^^^^^^^^^^^^^^^^^^^^
  File "/home/airflow/.local/lib/python3.12/site-packages/airflow/cli/commands/task_command.py", line 256, in _run_task_by_selected_method
    return _run_raw_task(args, ti)
           ^^^^^^^^^^^^^^^^^^^^^^^
  File "/home/airflow/.local/lib/python3.12/site-packages/airflow/cli/commands/task_command.py", line 341, in _run_raw_task
    return ti._run_raw_task(
           ^^^^^^^^^^^^^^^^^
  File "/home/airflow/.local/lib/python3.12/site-packages/airflow/utils/session.py", line 97, in wrapper
    return func(*args, session=session, **kwargs)
           ^^^^^^^^^^^^^^^^^^^^^^^^^^^^^^^^^^^^^^
  File "/home/airflow/.local/lib/python3.12/site-packages/airflow/models/taskinstance.py", line 3006, in _run_raw_task
    return _run_raw_task(
           ^^^^^^^^^^^^^^
  File "/home/airflow/.local/lib/python3.12/site-packages/airflow/models/taskinstance.py", line 274, in _run_raw_task
    TaskInstance._execute_task_with_callbacks(
  File "/home/airflow/.local/lib/python3.12/site-packages/airflow/models/taskinstance.py", line 3161, in _execute_task_with_callbacks
    result = self._execute_task(context, task_orig)
             ^^^^^^^^^^^^^^^^^^^^^^^^^^^^^^^^^^^^^^
  File "/home/airflow/.local/lib/python3.12/site-packages/airflow/models/taskinstance.py", line 3185, in _execute_task
    return _execute_task(self, context, task_orig)
           ^^^^^^^^^^^^^^^^^^^^^^^^^^^^^^^^^^^^^^^
  File "/home/airflow/.local/lib/python3.12/site-packages/airflow/models/taskinstance.py", line 768, in _execute_task
    result = _execute_callable(context=context, **execute_callable_kwargs)
             ^^^^^^^^^^^^^^^^^^^^^^^^^^^^^^^^^^^^^^^^^^^^^^^^^^^^^^^^^^^^^
  File "/home/airflow/.local/lib/python3.12/site-packages/airflow/models/taskinstance.py", line 734, in _execute_callable
    return ExecutionCallableRunner(
           ^^^^^^^^^^^^^^^^^^^^^^^^
  File "/home/airflow/.local/lib/python3.12/site-packages/airflow/utils/operator_helpers.py", line 252, in run
    return self.func(*args, **kwargs)
           ^^^^^^^^^^^^^^^^^^^^^^^^^^
  File "/home/airflow/.local/lib/python3.12/site-packages/airflow/models/baseoperator.py", line 424, in wrapper
    return func(self, *args, **kwargs)
           ^^^^^^^^^^^^^^^^^^^^^^^^^^^
  File "/home/airflow/.local/lib/python3.12/site-packages/airflow/providers/docker/operators/docker.py", line 467, in execute
    if self.force_pull or not self.cli.images(name=self.image):
                              ^^^^^^^^
  File "/home/airflow/.local/lib/python3.12/site-packages/airflow/providers/docker/operators/docker.py", line 341, in cli
    return self.hook.api_client
           ^^^^^^^^^^^^^^^^^^^^
  File "/usr/local/lib/python3.12/functools.py", line 998, in __get__
    val = self.func(instance)
          ^^^^^^^^^^^^^^^^^^^
  File "/home/airflow/.local/lib/python3.12/site-packages/airflow/providers/docker/hooks/docker.py", line 161, in api_client
    raise AirflowException("Failed to establish connection to any given Docker hosts.")
airflow.exceptions.AirflowException: Failed to establish connection to any given Docker hosts.
[2025-03-25T00:18:42.706+0000] {local_task_job_runner.py:266} INFO - Task exited with return code 1
[2025-03-25T00:18:42.922+0000] {local_task_job_runner.py:245} INFO - ::endgroup::
[2025-03-25T00:25:48.991+0000] {local_task_job_runner.py:123} INFO - ::group::Pre task execution logs
[2025-03-25T00:25:49.084+0000] {taskinstance.py:2614} INFO - Dependencies all met for dep_context=non-requeueable deps ti=<TaskInstance: containers1_dag.php_app1 scheduled__2024-03-13T00:00:00+00:00 [queued]>
[2025-03-25T00:25:49.136+0000] {taskinstance.py:2614} INFO - Dependencies all met for dep_context=requeueable deps ti=<TaskInstance: containers1_dag.php_app1 scheduled__2024-03-13T00:00:00+00:00 [queued]>
[2025-03-25T00:25:49.136+0000] {taskinstance.py:2867} INFO - Starting attempt 1 of 6
[2025-03-25T00:25:49.194+0000] {taskinstance.py:2890} INFO - Executing <Task(DockerOperator): php_app1> on 2024-03-13 00:00:00+00:00
[2025-03-25T00:25:49.229+0000] {logging_mixin.py:190} WARNING - /home/***/.local/lib/python3.12/site-packages/***/task/task_runner/standard_task_runner.py:70 DeprecationWarning: This process (pid=272) is multi-threaded, use of fork() may lead to deadlocks in the child.
[2025-03-25T00:25:49.226+0000] {standard_task_runner.py:104} INFO - Running: ['***', 'tasks', 'run', 'containers1_dag', 'php_app1', 'scheduled__2024-03-13T00:00:00+00:00', '--job-id', '28', '--raw', '--subdir', 'DAGS_FOLDER/containers1_dag.py', '--cfg-path', '/tmp/tmp8w1lu60a']
[2025-03-25T00:25:49.231+0000] {standard_task_runner.py:72} INFO - Started process 292 to run task
[2025-03-25T00:25:49.232+0000] {standard_task_runner.py:105} INFO - Job 28: Subtask php_app1
[2025-03-25T00:25:49.395+0000] {task_command.py:467} INFO - Running <TaskInstance: containers1_dag.php_app1 scheduled__2024-03-13T00:00:00+00:00 [running]> on host 7e2e363232cf
[2025-03-25T00:25:49.715+0000] {taskinstance.py:3134} INFO - Exporting env vars: AIRFLOW_CTX_DAG_OWNER='andre' AIRFLOW_CTX_DAG_ID='containers1_dag' AIRFLOW_CTX_TASK_ID='php_app1' AIRFLOW_CTX_EXECUTION_DATE='2024-03-13T00:00:00+00:00' AIRFLOW_CTX_TRY_NUMBER='1' AIRFLOW_CTX_DAG_RUN_ID='scheduled__2024-03-13T00:00:00+00:00'
[2025-03-25T00:25:49.717+0000] {taskinstance.py:732} INFO - ::endgroup::
[2025-03-25T00:25:49.767+0000] {docker.py:157} ERROR - Failed to establish connection to Docker host unix://var/run/docker.sock: Error while fetching server API version: ('Connection aborted.', FileNotFoundError(2, 'No such file or directory'))
[2025-03-25T00:25:49.787+0000] {taskinstance.py:3313} ERROR - Task failed with exception
Traceback (most recent call last):
  File "/home/airflow/.local/lib/python3.12/site-packages/airflow/models/taskinstance.py", line 768, in _execute_task
    result = _execute_callable(context=context, **execute_callable_kwargs)
             ^^^^^^^^^^^^^^^^^^^^^^^^^^^^^^^^^^^^^^^^^^^^^^^^^^^^^^^^^^^^^
  File "/home/airflow/.local/lib/python3.12/site-packages/airflow/models/taskinstance.py", line 734, in _execute_callable
    return ExecutionCallableRunner(
           ^^^^^^^^^^^^^^^^^^^^^^^^
  File "/home/airflow/.local/lib/python3.12/site-packages/airflow/utils/operator_helpers.py", line 252, in run
    return self.func(*args, **kwargs)
           ^^^^^^^^^^^^^^^^^^^^^^^^^^
  File "/home/airflow/.local/lib/python3.12/site-packages/airflow/models/baseoperator.py", line 424, in wrapper
    return func(self, *args, **kwargs)
           ^^^^^^^^^^^^^^^^^^^^^^^^^^^
  File "/home/airflow/.local/lib/python3.12/site-packages/airflow/providers/docker/operators/docker.py", line 467, in execute
    if self.force_pull or not self.cli.images(name=self.image):
                              ^^^^^^^^
  File "/home/airflow/.local/lib/python3.12/site-packages/airflow/providers/docker/operators/docker.py", line 341, in cli
    return self.hook.api_client
           ^^^^^^^^^^^^^^^^^^^^
  File "/usr/local/lib/python3.12/functools.py", line 998, in __get__
    val = self.func(instance)
          ^^^^^^^^^^^^^^^^^^^
  File "/home/airflow/.local/lib/python3.12/site-packages/airflow/providers/docker/hooks/docker.py", line 161, in api_client
    raise AirflowException("Failed to establish connection to any given Docker hosts.")
airflow.exceptions.AirflowException: Failed to establish connection to any given Docker hosts.
[2025-03-25T00:25:49.806+0000] {taskinstance.py:1226} INFO - Marking task as UP_FOR_RETRY. dag_id=containers1_dag, task_id=php_app1, run_id=scheduled__2024-03-13T00:00:00+00:00, execution_date=20240313T000000, start_date=20250325T002549, end_date=20250325T002549
[2025-03-25T00:25:49.892+0000] {taskinstance.py:341} INFO - ::group::Post task execution logs
[2025-03-25T00:25:49.893+0000] {standard_task_runner.py:124} ERROR - Failed to execute job 28 for task php_app1 (Failed to establish connection to any given Docker hosts.; 292)
Traceback (most recent call last):
  File "/home/airflow/.local/lib/python3.12/site-packages/airflow/task/task_runner/standard_task_runner.py", line 117, in _start_by_fork
    ret = args.func(args, dag=self.dag)
          ^^^^^^^^^^^^^^^^^^^^^^^^^^^^^
  File "/home/airflow/.local/lib/python3.12/site-packages/airflow/cli/cli_config.py", line 49, in command
    return func(*args, **kwargs)
           ^^^^^^^^^^^^^^^^^^^^^
  File "/home/airflow/.local/lib/python3.12/site-packages/airflow/utils/cli.py", line 116, in wrapper
    return f(*args, **kwargs)
           ^^^^^^^^^^^^^^^^^^
  File "/home/airflow/.local/lib/python3.12/site-packages/airflow/cli/commands/task_command.py", line 483, in task_run
    task_return_code = _run_task_by_selected_method(args, _dag, ti)
                       ^^^^^^^^^^^^^^^^^^^^^^^^^^^^^^^^^^^^^^^^^^^^
  File "/home/airflow/.local/lib/python3.12/site-packages/airflow/cli/commands/task_command.py", line 256, in _run_task_by_selected_method
    return _run_raw_task(args, ti)
           ^^^^^^^^^^^^^^^^^^^^^^^
  File "/home/airflow/.local/lib/python3.12/site-packages/airflow/cli/commands/task_command.py", line 341, in _run_raw_task
    return ti._run_raw_task(
           ^^^^^^^^^^^^^^^^^
  File "/home/airflow/.local/lib/python3.12/site-packages/airflow/utils/session.py", line 97, in wrapper
    return func(*args, session=session, **kwargs)
           ^^^^^^^^^^^^^^^^^^^^^^^^^^^^^^^^^^^^^^
  File "/home/airflow/.local/lib/python3.12/site-packages/airflow/models/taskinstance.py", line 3006, in _run_raw_task
    return _run_raw_task(
           ^^^^^^^^^^^^^^
  File "/home/airflow/.local/lib/python3.12/site-packages/airflow/models/taskinstance.py", line 274, in _run_raw_task
    TaskInstance._execute_task_with_callbacks(
  File "/home/airflow/.local/lib/python3.12/site-packages/airflow/models/taskinstance.py", line 3161, in _execute_task_with_callbacks
    result = self._execute_task(context, task_orig)
             ^^^^^^^^^^^^^^^^^^^^^^^^^^^^^^^^^^^^^^
  File "/home/airflow/.local/lib/python3.12/site-packages/airflow/models/taskinstance.py", line 3185, in _execute_task
    return _execute_task(self, context, task_orig)
           ^^^^^^^^^^^^^^^^^^^^^^^^^^^^^^^^^^^^^^^
  File "/home/airflow/.local/lib/python3.12/site-packages/airflow/models/taskinstance.py", line 768, in _execute_task
    result = _execute_callable(context=context, **execute_callable_kwargs)
             ^^^^^^^^^^^^^^^^^^^^^^^^^^^^^^^^^^^^^^^^^^^^^^^^^^^^^^^^^^^^^
  File "/home/airflow/.local/lib/python3.12/site-packages/airflow/models/taskinstance.py", line 734, in _execute_callable
    return ExecutionCallableRunner(
           ^^^^^^^^^^^^^^^^^^^^^^^^
  File "/home/airflow/.local/lib/python3.12/site-packages/airflow/utils/operator_helpers.py", line 252, in run
    return self.func(*args, **kwargs)
           ^^^^^^^^^^^^^^^^^^^^^^^^^^
  File "/home/airflow/.local/lib/python3.12/site-packages/airflow/models/baseoperator.py", line 424, in wrapper
    return func(self, *args, **kwargs)
           ^^^^^^^^^^^^^^^^^^^^^^^^^^^
  File "/home/airflow/.local/lib/python3.12/site-packages/airflow/providers/docker/operators/docker.py", line 467, in execute
    if self.force_pull or not self.cli.images(name=self.image):
                              ^^^^^^^^
  File "/home/airflow/.local/lib/python3.12/site-packages/airflow/providers/docker/operators/docker.py", line 341, in cli
    return self.hook.api_client
           ^^^^^^^^^^^^^^^^^^^^
  File "/usr/local/lib/python3.12/functools.py", line 998, in __get__
    val = self.func(instance)
          ^^^^^^^^^^^^^^^^^^^
  File "/home/airflow/.local/lib/python3.12/site-packages/airflow/providers/docker/hooks/docker.py", line 161, in api_client
    raise AirflowException("Failed to establish connection to any given Docker hosts.")
airflow.exceptions.AirflowException: Failed to establish connection to any given Docker hosts.
[2025-03-25T00:25:49.942+0000] {local_task_job_runner.py:266} INFO - Task exited with return code 1
[2025-03-25T00:25:50.011+0000] {taskinstance.py:3901} INFO - 0 downstream tasks scheduled from follow-on schedule check
[2025-03-25T00:25:50.021+0000] {local_task_job_runner.py:245} INFO - ::endgroup::
