[2025-03-24T22:19:25.092+0000] {local_task_job_runner.py:123} INFO - ::group::Pre task execution logs
[2025-03-24T22:19:25.296+0000] {taskinstance.py:2614} INFO - Dependencies all met for dep_context=non-requeueable deps ti=<TaskInstance: containers1_dag.php_app2 scheduled__2024-03-14T00:00:00+00:00 [queued]>
[2025-03-24T22:19:25.445+0000] {taskinstance.py:2614} INFO - Dependencies all met for dep_context=requeueable deps ti=<TaskInstance: containers1_dag.php_app2 scheduled__2024-03-14T00:00:00+00:00 [queued]>
[2025-03-24T22:19:25.452+0000] {taskinstance.py:2867} INFO - Starting attempt 1 of 6
[2025-03-24T22:19:25.714+0000] {taskinstance.py:2890} INFO - Executing <Task(BashOperator): php_app2> on 2024-03-14 00:00:00+00:00
[2025-03-24T22:19:25.755+0000] {logging_mixin.py:190} WARNING - /home/***/.local/lib/python3.12/site-packages/***/task/task_runner/standard_task_runner.py:70 DeprecationWarning: This process (pid=4958) is multi-threaded, use of fork() may lead to deadlocks in the child.
[2025-03-24T22:19:25.756+0000] {standard_task_runner.py:72} INFO - Started process 4983 to run task
[2025-03-24T22:19:25.786+0000] {standard_task_runner.py:104} INFO - Running: ['***', 'tasks', 'run', 'containers1_dag', 'php_app2', 'scheduled__2024-03-14T00:00:00+00:00', '--job-id', '137', '--raw', '--subdir', 'DAGS_FOLDER/containers1_dag.py', '--cfg-path', '/tmp/tmpc86vaql3']
[2025-03-24T22:19:25.811+0000] {standard_task_runner.py:105} INFO - Job 137: Subtask php_app2
[2025-03-24T22:19:26.937+0000] {task_command.py:467} INFO - Running <TaskInstance: containers1_dag.php_app2 scheduled__2024-03-14T00:00:00+00:00 [running]> on host b9050090f7f5
[2025-03-24T22:19:27.635+0000] {taskinstance.py:3134} INFO - Exporting env vars: AIRFLOW_CTX_DAG_OWNER='andreeppinghaus' AIRFLOW_CTX_DAG_ID='containers1_dag' AIRFLOW_CTX_TASK_ID='php_app2' AIRFLOW_CTX_EXECUTION_DATE='2024-03-14T00:00:00+00:00' AIRFLOW_CTX_TRY_NUMBER='1' AIRFLOW_CTX_DAG_RUN_ID='scheduled__2024-03-14T00:00:00+00:00'
[2025-03-24T22:19:27.646+0000] {taskinstance.py:732} INFO - ::endgroup::
[2025-03-24T22:19:27.816+0000] {subprocess.py:78} INFO - Tmp dir root location: /tmp
[2025-03-24T22:19:27.853+0000] {subprocess.py:88} INFO - Running command: ['/usr/bin/bash', '-c', 'sudo docker run -v $(pwd)/../in:/usr/src/app/in -v $(pwd):/usr/src/app php-app2']
[2025-03-24T22:19:27.986+0000] {subprocess.py:99} INFO - Output:
[2025-03-24T22:19:28.137+0000] {subprocess.py:106} INFO - sudo: a terminal is required to read the password; either use the -S option to read from standard input or configure an askpass helper
[2025-03-24T22:19:28.156+0000] {subprocess.py:106} INFO - sudo: a password is required
[2025-03-24T22:19:28.168+0000] {subprocess.py:110} INFO - Command exited with return code 1
[2025-03-24T22:19:28.275+0000] {taskinstance.py:3313} ERROR - Task failed with exception
Traceback (most recent call last):
  File "/home/airflow/.local/lib/python3.12/site-packages/airflow/models/taskinstance.py", line 768, in _execute_task
    result = _execute_callable(context=context, **execute_callable_kwargs)
             ^^^^^^^^^^^^^^^^^^^^^^^^^^^^^^^^^^^^^^^^^^^^^^^^^^^^^^^^^^^^^
  File "/home/airflow/.local/lib/python3.12/site-packages/airflow/models/taskinstance.py", line 734, in _execute_callable
    return ExecutionCallableRunner(
           ^^^^^^^^^^^^^^^^^^^^^^^^
  File "/home/airflow/.local/lib/python3.12/site-packages/airflow/utils/operator_helpers.py", line 252, in run
    return self.func(*args, **kwargs)
           ^^^^^^^^^^^^^^^^^^^^^^^^^^
  File "/home/airflow/.local/lib/python3.12/site-packages/airflow/models/baseoperator.py", line 424, in wrapper
    return func(self, *args, **kwargs)
           ^^^^^^^^^^^^^^^^^^^^^^^^^^^
  File "/home/airflow/.local/lib/python3.12/site-packages/airflow/operators/bash.py", line 276, in execute
    raise AirflowException(
airflow.exceptions.AirflowException: Bash command failed. The command returned a non-zero exit code 1.
[2025-03-24T22:19:28.318+0000] {taskinstance.py:1226} INFO - Marking task as UP_FOR_RETRY. dag_id=containers1_dag, task_id=php_app2, run_id=scheduled__2024-03-14T00:00:00+00:00, execution_date=20240314T000000, start_date=20250324T221925, end_date=20250324T221928
[2025-03-24T22:19:28.539+0000] {taskinstance.py:341} INFO - ::group::Post task execution logs
[2025-03-24T22:19:28.544+0000] {standard_task_runner.py:124} ERROR - Failed to execute job 137 for task php_app2 (Bash command failed. The command returned a non-zero exit code 1.; 4983)
Traceback (most recent call last):
  File "/home/airflow/.local/lib/python3.12/site-packages/airflow/task/task_runner/standard_task_runner.py", line 117, in _start_by_fork
    ret = args.func(args, dag=self.dag)
          ^^^^^^^^^^^^^^^^^^^^^^^^^^^^^
  File "/home/airflow/.local/lib/python3.12/site-packages/airflow/cli/cli_config.py", line 49, in command
    return func(*args, **kwargs)
           ^^^^^^^^^^^^^^^^^^^^^
  File "/home/airflow/.local/lib/python3.12/site-packages/airflow/utils/cli.py", line 116, in wrapper
    return f(*args, **kwargs)
           ^^^^^^^^^^^^^^^^^^
  File "/home/airflow/.local/lib/python3.12/site-packages/airflow/cli/commands/task_command.py", line 483, in task_run
    task_return_code = _run_task_by_selected_method(args, _dag, ti)
                       ^^^^^^^^^^^^^^^^^^^^^^^^^^^^^^^^^^^^^^^^^^^^
  File "/home/airflow/.local/lib/python3.12/site-packages/airflow/cli/commands/task_command.py", line 256, in _run_task_by_selected_method
    return _run_raw_task(args, ti)
           ^^^^^^^^^^^^^^^^^^^^^^^
  File "/home/airflow/.local/lib/python3.12/site-packages/airflow/cli/commands/task_command.py", line 341, in _run_raw_task
    return ti._run_raw_task(
           ^^^^^^^^^^^^^^^^^
  File "/home/airflow/.local/lib/python3.12/site-packages/airflow/utils/session.py", line 97, in wrapper
    return func(*args, session=session, **kwargs)
           ^^^^^^^^^^^^^^^^^^^^^^^^^^^^^^^^^^^^^^
  File "/home/airflow/.local/lib/python3.12/site-packages/airflow/models/taskinstance.py", line 3006, in _run_raw_task
    return _run_raw_task(
           ^^^^^^^^^^^^^^
  File "/home/airflow/.local/lib/python3.12/site-packages/airflow/models/taskinstance.py", line 274, in _run_raw_task
    TaskInstance._execute_task_with_callbacks(
  File "/home/airflow/.local/lib/python3.12/site-packages/airflow/models/taskinstance.py", line 3161, in _execute_task_with_callbacks
    result = self._execute_task(context, task_orig)
             ^^^^^^^^^^^^^^^^^^^^^^^^^^^^^^^^^^^^^^
  File "/home/airflow/.local/lib/python3.12/site-packages/airflow/models/taskinstance.py", line 3185, in _execute_task
    return _execute_task(self, context, task_orig)
           ^^^^^^^^^^^^^^^^^^^^^^^^^^^^^^^^^^^^^^^
  File "/home/airflow/.local/lib/python3.12/site-packages/airflow/models/taskinstance.py", line 768, in _execute_task
    result = _execute_callable(context=context, **execute_callable_kwargs)
             ^^^^^^^^^^^^^^^^^^^^^^^^^^^^^^^^^^^^^^^^^^^^^^^^^^^^^^^^^^^^^
  File "/home/airflow/.local/lib/python3.12/site-packages/airflow/models/taskinstance.py", line 734, in _execute_callable
    return ExecutionCallableRunner(
           ^^^^^^^^^^^^^^^^^^^^^^^^
  File "/home/airflow/.local/lib/python3.12/site-packages/airflow/utils/operator_helpers.py", line 252, in run
    return self.func(*args, **kwargs)
           ^^^^^^^^^^^^^^^^^^^^^^^^^^
  File "/home/airflow/.local/lib/python3.12/site-packages/airflow/models/baseoperator.py", line 424, in wrapper
    return func(self, *args, **kwargs)
           ^^^^^^^^^^^^^^^^^^^^^^^^^^^
  File "/home/airflow/.local/lib/python3.12/site-packages/airflow/operators/bash.py", line 276, in execute
    raise AirflowException(
airflow.exceptions.AirflowException: Bash command failed. The command returned a non-zero exit code 1.
[2025-03-24T22:19:28.601+0000] {local_task_job_runner.py:266} INFO - Task exited with return code 1
[2025-03-24T22:19:28.661+0000] {taskinstance.py:3901} INFO - 0 downstream tasks scheduled from follow-on schedule check
[2025-03-24T22:19:28.675+0000] {local_task_job_runner.py:245} INFO - ::endgroup::
[2025-03-24T22:24:23.587+0000] {local_task_job_runner.py:123} INFO - ::group::Pre task execution logs
[2025-03-24T22:24:23.758+0000] {taskinstance.py:2614} INFO - Dependencies all met for dep_context=non-requeueable deps ti=<TaskInstance: containers1_dag.php_app2 scheduled__2024-03-14T00:00:00+00:00 [queued]>
[2025-03-24T22:24:23.800+0000] {taskinstance.py:2614} INFO - Dependencies all met for dep_context=requeueable deps ti=<TaskInstance: containers1_dag.php_app2 scheduled__2024-03-14T00:00:00+00:00 [queued]>
[2025-03-24T22:24:23.801+0000] {taskinstance.py:2867} INFO - Starting attempt 1 of 6
[2025-03-24T22:24:23.839+0000] {taskinstance.py:2890} INFO - Executing <Task(BashOperator): php_app2> on 2024-03-14 00:00:00+00:00
[2025-03-24T22:24:23.854+0000] {logging_mixin.py:190} WARNING - /home/***/.local/lib/python3.12/site-packages/***/task/task_runner/standard_task_runner.py:70 DeprecationWarning: This process (pid=5364) is multi-threaded, use of fork() may lead to deadlocks in the child.
[2025-03-24T22:24:23.856+0000] {standard_task_runner.py:72} INFO - Started process 5388 to run task
[2025-03-24T22:24:23.854+0000] {standard_task_runner.py:104} INFO - Running: ['***', 'tasks', 'run', 'containers1_dag', 'php_app2', 'scheduled__2024-03-14T00:00:00+00:00', '--job-id', '169', '--raw', '--subdir', 'DAGS_FOLDER/containers1_dag.py', '--cfg-path', '/tmp/tmpk54pah84']
[2025-03-24T22:24:23.859+0000] {standard_task_runner.py:105} INFO - Job 169: Subtask php_app2
[2025-03-24T22:24:24.206+0000] {task_command.py:467} INFO - Running <TaskInstance: containers1_dag.php_app2 scheduled__2024-03-14T00:00:00+00:00 [running]> on host b9050090f7f5
[2025-03-24T22:24:24.865+0000] {taskinstance.py:3134} INFO - Exporting env vars: AIRFLOW_CTX_DAG_OWNER='andre' AIRFLOW_CTX_DAG_ID='containers1_dag' AIRFLOW_CTX_TASK_ID='php_app2' AIRFLOW_CTX_EXECUTION_DATE='2024-03-14T00:00:00+00:00' AIRFLOW_CTX_TRY_NUMBER='1' AIRFLOW_CTX_DAG_RUN_ID='scheduled__2024-03-14T00:00:00+00:00'
[2025-03-24T22:24:24.867+0000] {taskinstance.py:732} INFO - ::endgroup::
[2025-03-24T22:24:24.960+0000] {subprocess.py:78} INFO - Tmp dir root location: /tmp
[2025-03-24T22:24:24.962+0000] {subprocess.py:88} INFO - Running command: ['/usr/bin/bash', '-c', 'sudo docker run -v $(pwd)/../in:/usr/src/app/in -v $(pwd):/usr/src/app php-app2']
[2025-03-24T22:24:25.052+0000] {subprocess.py:99} INFO - Output:
[2025-03-24T22:24:25.122+0000] {subprocess.py:106} INFO - sudo: a terminal is required to read the password; either use the -S option to read from standard input or configure an askpass helper
[2025-03-24T22:24:25.128+0000] {subprocess.py:106} INFO - sudo: a password is required
[2025-03-24T22:24:25.137+0000] {subprocess.py:110} INFO - Command exited with return code 1
[2025-03-24T22:24:25.196+0000] {taskinstance.py:3313} ERROR - Task failed with exception
Traceback (most recent call last):
  File "/home/airflow/.local/lib/python3.12/site-packages/airflow/models/taskinstance.py", line 768, in _execute_task
    result = _execute_callable(context=context, **execute_callable_kwargs)
             ^^^^^^^^^^^^^^^^^^^^^^^^^^^^^^^^^^^^^^^^^^^^^^^^^^^^^^^^^^^^^
  File "/home/airflow/.local/lib/python3.12/site-packages/airflow/models/taskinstance.py", line 734, in _execute_callable
    return ExecutionCallableRunner(
           ^^^^^^^^^^^^^^^^^^^^^^^^
  File "/home/airflow/.local/lib/python3.12/site-packages/airflow/utils/operator_helpers.py", line 252, in run
    return self.func(*args, **kwargs)
           ^^^^^^^^^^^^^^^^^^^^^^^^^^
  File "/home/airflow/.local/lib/python3.12/site-packages/airflow/models/baseoperator.py", line 424, in wrapper
    return func(self, *args, **kwargs)
           ^^^^^^^^^^^^^^^^^^^^^^^^^^^
  File "/home/airflow/.local/lib/python3.12/site-packages/airflow/operators/bash.py", line 276, in execute
    raise AirflowException(
airflow.exceptions.AirflowException: Bash command failed. The command returned a non-zero exit code 1.
[2025-03-24T22:24:25.222+0000] {taskinstance.py:1226} INFO - Marking task as UP_FOR_RETRY. dag_id=containers1_dag, task_id=php_app2, run_id=scheduled__2024-03-14T00:00:00+00:00, execution_date=20240314T000000, start_date=20250324T222423, end_date=20250324T222425
[2025-03-24T22:24:25.334+0000] {taskinstance.py:341} INFO - ::group::Post task execution logs
[2025-03-24T22:24:25.335+0000] {standard_task_runner.py:124} ERROR - Failed to execute job 169 for task php_app2 (Bash command failed. The command returned a non-zero exit code 1.; 5388)
Traceback (most recent call last):
  File "/home/airflow/.local/lib/python3.12/site-packages/airflow/task/task_runner/standard_task_runner.py", line 117, in _start_by_fork
    ret = args.func(args, dag=self.dag)
          ^^^^^^^^^^^^^^^^^^^^^^^^^^^^^
  File "/home/airflow/.local/lib/python3.12/site-packages/airflow/cli/cli_config.py", line 49, in command
    return func(*args, **kwargs)
           ^^^^^^^^^^^^^^^^^^^^^
  File "/home/airflow/.local/lib/python3.12/site-packages/airflow/utils/cli.py", line 116, in wrapper
    return f(*args, **kwargs)
           ^^^^^^^^^^^^^^^^^^
  File "/home/airflow/.local/lib/python3.12/site-packages/airflow/cli/commands/task_command.py", line 483, in task_run
    task_return_code = _run_task_by_selected_method(args, _dag, ti)
                       ^^^^^^^^^^^^^^^^^^^^^^^^^^^^^^^^^^^^^^^^^^^^
  File "/home/airflow/.local/lib/python3.12/site-packages/airflow/cli/commands/task_command.py", line 256, in _run_task_by_selected_method
    return _run_raw_task(args, ti)
           ^^^^^^^^^^^^^^^^^^^^^^^
  File "/home/airflow/.local/lib/python3.12/site-packages/airflow/cli/commands/task_command.py", line 341, in _run_raw_task
    return ti._run_raw_task(
           ^^^^^^^^^^^^^^^^^
  File "/home/airflow/.local/lib/python3.12/site-packages/airflow/utils/session.py", line 97, in wrapper
    return func(*args, session=session, **kwargs)
           ^^^^^^^^^^^^^^^^^^^^^^^^^^^^^^^^^^^^^^
  File "/home/airflow/.local/lib/python3.12/site-packages/airflow/models/taskinstance.py", line 3006, in _run_raw_task
    return _run_raw_task(
           ^^^^^^^^^^^^^^
  File "/home/airflow/.local/lib/python3.12/site-packages/airflow/models/taskinstance.py", line 274, in _run_raw_task
    TaskInstance._execute_task_with_callbacks(
  File "/home/airflow/.local/lib/python3.12/site-packages/airflow/models/taskinstance.py", line 3161, in _execute_task_with_callbacks
    result = self._execute_task(context, task_orig)
             ^^^^^^^^^^^^^^^^^^^^^^^^^^^^^^^^^^^^^^
  File "/home/airflow/.local/lib/python3.12/site-packages/airflow/models/taskinstance.py", line 3185, in _execute_task
    return _execute_task(self, context, task_orig)
           ^^^^^^^^^^^^^^^^^^^^^^^^^^^^^^^^^^^^^^^
  File "/home/airflow/.local/lib/python3.12/site-packages/airflow/models/taskinstance.py", line 768, in _execute_task
    result = _execute_callable(context=context, **execute_callable_kwargs)
             ^^^^^^^^^^^^^^^^^^^^^^^^^^^^^^^^^^^^^^^^^^^^^^^^^^^^^^^^^^^^^
  File "/home/airflow/.local/lib/python3.12/site-packages/airflow/models/taskinstance.py", line 734, in _execute_callable
    return ExecutionCallableRunner(
           ^^^^^^^^^^^^^^^^^^^^^^^^
  File "/home/airflow/.local/lib/python3.12/site-packages/airflow/utils/operator_helpers.py", line 252, in run
    return self.func(*args, **kwargs)
           ^^^^^^^^^^^^^^^^^^^^^^^^^^
  File "/home/airflow/.local/lib/python3.12/site-packages/airflow/models/baseoperator.py", line 424, in wrapper
    return func(self, *args, **kwargs)
           ^^^^^^^^^^^^^^^^^^^^^^^^^^^
  File "/home/airflow/.local/lib/python3.12/site-packages/airflow/operators/bash.py", line 276, in execute
    raise AirflowException(
airflow.exceptions.AirflowException: Bash command failed. The command returned a non-zero exit code 1.
[2025-03-24T22:24:25.357+0000] {local_task_job_runner.py:266} INFO - Task exited with return code 1
[2025-03-24T22:24:25.435+0000] {taskinstance.py:3901} INFO - 0 downstream tasks scheduled from follow-on schedule check
[2025-03-24T22:24:25.451+0000] {local_task_job_runner.py:245} INFO - ::endgroup::
[2025-03-24T22:27:32.188+0000] {local_task_job_runner.py:123} INFO - ::group::Pre task execution logs
[2025-03-24T22:27:32.328+0000] {taskinstance.py:2614} INFO - Dependencies all met for dep_context=non-requeueable deps ti=<TaskInstance: containers1_dag.php_app2 scheduled__2024-03-14T00:00:00+00:00 [queued]>
[2025-03-24T22:27:32.383+0000] {taskinstance.py:2614} INFO - Dependencies all met for dep_context=requeueable deps ti=<TaskInstance: containers1_dag.php_app2 scheduled__2024-03-14T00:00:00+00:00 [queued]>
[2025-03-24T22:27:32.385+0000] {taskinstance.py:2867} INFO - Starting attempt 1 of 6
[2025-03-24T22:27:32.530+0000] {taskinstance.py:2890} INFO - Executing <Task(BashOperator): php_app2> on 2024-03-14 00:00:00+00:00
[2025-03-24T22:27:32.548+0000] {logging_mixin.py:190} WARNING - /home/***/.local/lib/python3.12/site-packages/***/task/task_runner/standard_task_runner.py:70 DeprecationWarning: This process (pid=5835) is multi-threaded, use of fork() may lead to deadlocks in the child.
[2025-03-24T22:27:32.554+0000] {standard_task_runner.py:72} INFO - Started process 5864 to run task
[2025-03-24T22:27:32.561+0000] {standard_task_runner.py:104} INFO - Running: ['***', 'tasks', 'run', 'containers1_dag', 'php_app2', 'scheduled__2024-03-14T00:00:00+00:00', '--job-id', '201', '--raw', '--subdir', 'DAGS_FOLDER/containers1_dag.py', '--cfg-path', '/tmp/tmpv4to3tay']
[2025-03-24T22:27:32.581+0000] {standard_task_runner.py:105} INFO - Job 201: Subtask php_app2
[2025-03-24T22:27:32.909+0000] {task_command.py:467} INFO - Running <TaskInstance: containers1_dag.php_app2 scheduled__2024-03-14T00:00:00+00:00 [running]> on host b9050090f7f5
[2025-03-24T22:27:33.273+0000] {taskinstance.py:3134} INFO - Exporting env vars: AIRFLOW_CTX_DAG_OWNER='andre' AIRFLOW_CTX_DAG_ID='containers1_dag' AIRFLOW_CTX_TASK_ID='php_app2' AIRFLOW_CTX_EXECUTION_DATE='2024-03-14T00:00:00+00:00' AIRFLOW_CTX_TRY_NUMBER='1' AIRFLOW_CTX_DAG_RUN_ID='scheduled__2024-03-14T00:00:00+00:00'
[2025-03-24T22:27:33.276+0000] {taskinstance.py:732} INFO - ::endgroup::
[2025-03-24T22:27:33.346+0000] {subprocess.py:78} INFO - Tmp dir root location: /tmp
[2025-03-24T22:27:33.357+0000] {subprocess.py:88} INFO - Running command: ['/usr/bin/bash', '-c', 'docker run -v $(pwd)/../in:/usr/src/app/in -v $(pwd):/usr/src/app php-app2']
[2025-03-24T22:27:33.406+0000] {subprocess.py:99} INFO - Output:
[2025-03-24T22:27:33.536+0000] {subprocess.py:106} INFO - docker: Cannot connect to the Docker daemon at unix:///var/run/docker.sock. Is the docker daemon running?.
[2025-03-24T22:27:33.537+0000] {subprocess.py:106} INFO - See 'docker run --help'.
[2025-03-24T22:27:33.541+0000] {subprocess.py:110} INFO - Command exited with return code 125
[2025-03-24T22:27:33.588+0000] {taskinstance.py:3313} ERROR - Task failed with exception
Traceback (most recent call last):
  File "/home/airflow/.local/lib/python3.12/site-packages/airflow/models/taskinstance.py", line 768, in _execute_task
    result = _execute_callable(context=context, **execute_callable_kwargs)
             ^^^^^^^^^^^^^^^^^^^^^^^^^^^^^^^^^^^^^^^^^^^^^^^^^^^^^^^^^^^^^
  File "/home/airflow/.local/lib/python3.12/site-packages/airflow/models/taskinstance.py", line 734, in _execute_callable
    return ExecutionCallableRunner(
           ^^^^^^^^^^^^^^^^^^^^^^^^
  File "/home/airflow/.local/lib/python3.12/site-packages/airflow/utils/operator_helpers.py", line 252, in run
    return self.func(*args, **kwargs)
           ^^^^^^^^^^^^^^^^^^^^^^^^^^
  File "/home/airflow/.local/lib/python3.12/site-packages/airflow/models/baseoperator.py", line 424, in wrapper
    return func(self, *args, **kwargs)
           ^^^^^^^^^^^^^^^^^^^^^^^^^^^
  File "/home/airflow/.local/lib/python3.12/site-packages/airflow/operators/bash.py", line 276, in execute
    raise AirflowException(
airflow.exceptions.AirflowException: Bash command failed. The command returned a non-zero exit code 125.
[2025-03-24T22:27:33.629+0000] {taskinstance.py:1226} INFO - Marking task as UP_FOR_RETRY. dag_id=containers1_dag, task_id=php_app2, run_id=scheduled__2024-03-14T00:00:00+00:00, execution_date=20240314T000000, start_date=20250324T222732, end_date=20250324T222733
[2025-03-24T22:27:33.729+0000] {taskinstance.py:341} INFO - ::group::Post task execution logs
[2025-03-24T22:27:33.731+0000] {standard_task_runner.py:124} ERROR - Failed to execute job 201 for task php_app2 (Bash command failed. The command returned a non-zero exit code 125.; 5864)
Traceback (most recent call last):
  File "/home/airflow/.local/lib/python3.12/site-packages/airflow/task/task_runner/standard_task_runner.py", line 117, in _start_by_fork
    ret = args.func(args, dag=self.dag)
          ^^^^^^^^^^^^^^^^^^^^^^^^^^^^^
  File "/home/airflow/.local/lib/python3.12/site-packages/airflow/cli/cli_config.py", line 49, in command
    return func(*args, **kwargs)
           ^^^^^^^^^^^^^^^^^^^^^
  File "/home/airflow/.local/lib/python3.12/site-packages/airflow/utils/cli.py", line 116, in wrapper
    return f(*args, **kwargs)
           ^^^^^^^^^^^^^^^^^^
  File "/home/airflow/.local/lib/python3.12/site-packages/airflow/cli/commands/task_command.py", line 483, in task_run
    task_return_code = _run_task_by_selected_method(args, _dag, ti)
                       ^^^^^^^^^^^^^^^^^^^^^^^^^^^^^^^^^^^^^^^^^^^^
  File "/home/airflow/.local/lib/python3.12/site-packages/airflow/cli/commands/task_command.py", line 256, in _run_task_by_selected_method
    return _run_raw_task(args, ti)
           ^^^^^^^^^^^^^^^^^^^^^^^
  File "/home/airflow/.local/lib/python3.12/site-packages/airflow/cli/commands/task_command.py", line 341, in _run_raw_task
    return ti._run_raw_task(
           ^^^^^^^^^^^^^^^^^
  File "/home/airflow/.local/lib/python3.12/site-packages/airflow/utils/session.py", line 97, in wrapper
    return func(*args, session=session, **kwargs)
           ^^^^^^^^^^^^^^^^^^^^^^^^^^^^^^^^^^^^^^
  File "/home/airflow/.local/lib/python3.12/site-packages/airflow/models/taskinstance.py", line 3006, in _run_raw_task
    return _run_raw_task(
           ^^^^^^^^^^^^^^
  File "/home/airflow/.local/lib/python3.12/site-packages/airflow/models/taskinstance.py", line 274, in _run_raw_task
    TaskInstance._execute_task_with_callbacks(
  File "/home/airflow/.local/lib/python3.12/site-packages/airflow/models/taskinstance.py", line 3161, in _execute_task_with_callbacks
    result = self._execute_task(context, task_orig)
             ^^^^^^^^^^^^^^^^^^^^^^^^^^^^^^^^^^^^^^
  File "/home/airflow/.local/lib/python3.12/site-packages/airflow/models/taskinstance.py", line 3185, in _execute_task
    return _execute_task(self, context, task_orig)
           ^^^^^^^^^^^^^^^^^^^^^^^^^^^^^^^^^^^^^^^
  File "/home/airflow/.local/lib/python3.12/site-packages/airflow/models/taskinstance.py", line 768, in _execute_task
    result = _execute_callable(context=context, **execute_callable_kwargs)
             ^^^^^^^^^^^^^^^^^^^^^^^^^^^^^^^^^^^^^^^^^^^^^^^^^^^^^^^^^^^^^
  File "/home/airflow/.local/lib/python3.12/site-packages/airflow/models/taskinstance.py", line 734, in _execute_callable
    return ExecutionCallableRunner(
           ^^^^^^^^^^^^^^^^^^^^^^^^
  File "/home/airflow/.local/lib/python3.12/site-packages/airflow/utils/operator_helpers.py", line 252, in run
    return self.func(*args, **kwargs)
           ^^^^^^^^^^^^^^^^^^^^^^^^^^
  File "/home/airflow/.local/lib/python3.12/site-packages/airflow/models/baseoperator.py", line 424, in wrapper
    return func(self, *args, **kwargs)
           ^^^^^^^^^^^^^^^^^^^^^^^^^^^
  File "/home/airflow/.local/lib/python3.12/site-packages/airflow/operators/bash.py", line 276, in execute
    raise AirflowException(
airflow.exceptions.AirflowException: Bash command failed. The command returned a non-zero exit code 125.
[2025-03-24T22:27:33.762+0000] {local_task_job_runner.py:266} INFO - Task exited with return code 1
[2025-03-24T22:27:33.781+0000] {local_task_job_runner.py:245} INFO - ::endgroup::
[2025-03-25T00:18:42.265+0000] {local_task_job_runner.py:123} INFO - ::group::Pre task execution logs
[2025-03-25T00:18:42.510+0000] {taskinstance.py:2614} INFO - Dependencies all met for dep_context=non-requeueable deps ti=<TaskInstance: containers1_dag.php_app2 scheduled__2024-03-14T00:00:00+00:00 [queued]>
[2025-03-25T00:18:42.580+0000] {taskinstance.py:2614} INFO - Dependencies all met for dep_context=requeueable deps ti=<TaskInstance: containers1_dag.php_app2 scheduled__2024-03-14T00:00:00+00:00 [queued]>
[2025-03-25T00:18:42.581+0000] {taskinstance.py:2867} INFO - Starting attempt 1 of 6
[2025-03-25T00:18:43.600+0000] {taskinstance.py:2890} INFO - Executing <Task(DockerOperator): php_app2> on 2024-03-14 00:00:00+00:00
[2025-03-25T00:18:43.699+0000] {standard_task_runner.py:104} INFO - Running: ['***', 'tasks', 'run', 'containers1_dag', 'php_app2', 'scheduled__2024-03-14T00:00:00+00:00', '--job-id', '29', '--raw', '--subdir', 'DAGS_FOLDER/containers1_dag.py', '--cfg-path', '/tmp/tmpp8bobbiv']
[2025-03-25T00:18:43.717+0000] {standard_task_runner.py:105} INFO - Job 29: Subtask php_app2
[2025-03-25T00:18:43.744+0000] {logging_mixin.py:190} WARNING - /home/***/.local/lib/python3.12/site-packages/***/task/task_runner/standard_task_runner.py:70 DeprecationWarning: This process (pid=475) is multi-threaded, use of fork() may lead to deadlocks in the child.
[2025-03-25T00:18:43.745+0000] {standard_task_runner.py:72} INFO - Started process 483 to run task
[2025-03-25T00:18:44.144+0000] {task_command.py:467} INFO - Running <TaskInstance: containers1_dag.php_app2 scheduled__2024-03-14T00:00:00+00:00 [running]> on host 0f77abd8a5ce
[2025-03-25T00:18:44.688+0000] {taskinstance.py:3134} INFO - Exporting env vars: AIRFLOW_CTX_DAG_OWNER='andre' AIRFLOW_CTX_DAG_ID='containers1_dag' AIRFLOW_CTX_TASK_ID='php_app2' AIRFLOW_CTX_EXECUTION_DATE='2024-03-14T00:00:00+00:00' AIRFLOW_CTX_TRY_NUMBER='1' AIRFLOW_CTX_DAG_RUN_ID='scheduled__2024-03-14T00:00:00+00:00'
[2025-03-25T00:18:44.691+0000] {taskinstance.py:732} INFO - ::endgroup::
[2025-03-25T00:18:44.792+0000] {docker.py:157} ERROR - Failed to establish connection to Docker host unix://var/run/docker.sock: Error while fetching server API version: ('Connection aborted.', FileNotFoundError(2, 'No such file or directory'))
[2025-03-25T00:18:44.834+0000] {taskinstance.py:3313} ERROR - Task failed with exception
Traceback (most recent call last):
  File "/home/airflow/.local/lib/python3.12/site-packages/airflow/models/taskinstance.py", line 768, in _execute_task
    result = _execute_callable(context=context, **execute_callable_kwargs)
             ^^^^^^^^^^^^^^^^^^^^^^^^^^^^^^^^^^^^^^^^^^^^^^^^^^^^^^^^^^^^^
  File "/home/airflow/.local/lib/python3.12/site-packages/airflow/models/taskinstance.py", line 734, in _execute_callable
    return ExecutionCallableRunner(
           ^^^^^^^^^^^^^^^^^^^^^^^^
  File "/home/airflow/.local/lib/python3.12/site-packages/airflow/utils/operator_helpers.py", line 252, in run
    return self.func(*args, **kwargs)
           ^^^^^^^^^^^^^^^^^^^^^^^^^^
  File "/home/airflow/.local/lib/python3.12/site-packages/airflow/models/baseoperator.py", line 424, in wrapper
    return func(self, *args, **kwargs)
           ^^^^^^^^^^^^^^^^^^^^^^^^^^^
  File "/home/airflow/.local/lib/python3.12/site-packages/airflow/providers/docker/operators/docker.py", line 467, in execute
    if self.force_pull or not self.cli.images(name=self.image):
                              ^^^^^^^^
  File "/home/airflow/.local/lib/python3.12/site-packages/airflow/providers/docker/operators/docker.py", line 341, in cli
    return self.hook.api_client
           ^^^^^^^^^^^^^^^^^^^^
  File "/usr/local/lib/python3.12/functools.py", line 998, in __get__
    val = self.func(instance)
          ^^^^^^^^^^^^^^^^^^^
  File "/home/airflow/.local/lib/python3.12/site-packages/airflow/providers/docker/hooks/docker.py", line 161, in api_client
    raise AirflowException("Failed to establish connection to any given Docker hosts.")
airflow.exceptions.AirflowException: Failed to establish connection to any given Docker hosts.
[2025-03-25T00:18:44.858+0000] {taskinstance.py:1226} INFO - Marking task as UP_FOR_RETRY. dag_id=containers1_dag, task_id=php_app2, run_id=scheduled__2024-03-14T00:00:00+00:00, execution_date=20240314T000000, start_date=20250325T001842, end_date=20250325T001844
[2025-03-25T00:18:44.969+0000] {taskinstance.py:341} INFO - ::group::Post task execution logs
[2025-03-25T00:18:44.970+0000] {standard_task_runner.py:124} ERROR - Failed to execute job 29 for task php_app2 (Failed to establish connection to any given Docker hosts.; 483)
Traceback (most recent call last):
  File "/home/airflow/.local/lib/python3.12/site-packages/airflow/task/task_runner/standard_task_runner.py", line 117, in _start_by_fork
    ret = args.func(args, dag=self.dag)
          ^^^^^^^^^^^^^^^^^^^^^^^^^^^^^
  File "/home/airflow/.local/lib/python3.12/site-packages/airflow/cli/cli_config.py", line 49, in command
    return func(*args, **kwargs)
           ^^^^^^^^^^^^^^^^^^^^^
  File "/home/airflow/.local/lib/python3.12/site-packages/airflow/utils/cli.py", line 116, in wrapper
    return f(*args, **kwargs)
           ^^^^^^^^^^^^^^^^^^
  File "/home/airflow/.local/lib/python3.12/site-packages/airflow/cli/commands/task_command.py", line 483, in task_run
    task_return_code = _run_task_by_selected_method(args, _dag, ti)
                       ^^^^^^^^^^^^^^^^^^^^^^^^^^^^^^^^^^^^^^^^^^^^
  File "/home/airflow/.local/lib/python3.12/site-packages/airflow/cli/commands/task_command.py", line 256, in _run_task_by_selected_method
    return _run_raw_task(args, ti)
           ^^^^^^^^^^^^^^^^^^^^^^^
  File "/home/airflow/.local/lib/python3.12/site-packages/airflow/cli/commands/task_command.py", line 341, in _run_raw_task
    return ti._run_raw_task(
           ^^^^^^^^^^^^^^^^^
  File "/home/airflow/.local/lib/python3.12/site-packages/airflow/utils/session.py", line 97, in wrapper
    return func(*args, session=session, **kwargs)
           ^^^^^^^^^^^^^^^^^^^^^^^^^^^^^^^^^^^^^^
  File "/home/airflow/.local/lib/python3.12/site-packages/airflow/models/taskinstance.py", line 3006, in _run_raw_task
    return _run_raw_task(
           ^^^^^^^^^^^^^^
  File "/home/airflow/.local/lib/python3.12/site-packages/airflow/models/taskinstance.py", line 274, in _run_raw_task
    TaskInstance._execute_task_with_callbacks(
  File "/home/airflow/.local/lib/python3.12/site-packages/airflow/models/taskinstance.py", line 3161, in _execute_task_with_callbacks
    result = self._execute_task(context, task_orig)
             ^^^^^^^^^^^^^^^^^^^^^^^^^^^^^^^^^^^^^^
  File "/home/airflow/.local/lib/python3.12/site-packages/airflow/models/taskinstance.py", line 3185, in _execute_task
    return _execute_task(self, context, task_orig)
           ^^^^^^^^^^^^^^^^^^^^^^^^^^^^^^^^^^^^^^^
  File "/home/airflow/.local/lib/python3.12/site-packages/airflow/models/taskinstance.py", line 768, in _execute_task
    result = _execute_callable(context=context, **execute_callable_kwargs)
             ^^^^^^^^^^^^^^^^^^^^^^^^^^^^^^^^^^^^^^^^^^^^^^^^^^^^^^^^^^^^^
  File "/home/airflow/.local/lib/python3.12/site-packages/airflow/models/taskinstance.py", line 734, in _execute_callable
    return ExecutionCallableRunner(
           ^^^^^^^^^^^^^^^^^^^^^^^^
  File "/home/airflow/.local/lib/python3.12/site-packages/airflow/utils/operator_helpers.py", line 252, in run
    return self.func(*args, **kwargs)
           ^^^^^^^^^^^^^^^^^^^^^^^^^^
  File "/home/airflow/.local/lib/python3.12/site-packages/airflow/models/baseoperator.py", line 424, in wrapper
    return func(self, *args, **kwargs)
           ^^^^^^^^^^^^^^^^^^^^^^^^^^^
  File "/home/airflow/.local/lib/python3.12/site-packages/airflow/providers/docker/operators/docker.py", line 467, in execute
    if self.force_pull or not self.cli.images(name=self.image):
                              ^^^^^^^^
  File "/home/airflow/.local/lib/python3.12/site-packages/airflow/providers/docker/operators/docker.py", line 341, in cli
    return self.hook.api_client
           ^^^^^^^^^^^^^^^^^^^^
  File "/usr/local/lib/python3.12/functools.py", line 998, in __get__
    val = self.func(instance)
          ^^^^^^^^^^^^^^^^^^^
  File "/home/airflow/.local/lib/python3.12/site-packages/airflow/providers/docker/hooks/docker.py", line 161, in api_client
    raise AirflowException("Failed to establish connection to any given Docker hosts.")
airflow.exceptions.AirflowException: Failed to establish connection to any given Docker hosts.
[2025-03-25T00:18:45.022+0000] {local_task_job_runner.py:266} INFO - Task exited with return code 1
[2025-03-25T00:18:45.080+0000] {taskinstance.py:3901} INFO - 0 downstream tasks scheduled from follow-on schedule check
[2025-03-25T00:18:45.087+0000] {local_task_job_runner.py:245} INFO - ::endgroup::
[2025-03-25T00:25:48.937+0000] {local_task_job_runner.py:123} INFO - ::group::Pre task execution logs
[2025-03-25T00:25:49.018+0000] {taskinstance.py:2614} INFO - Dependencies all met for dep_context=non-requeueable deps ti=<TaskInstance: containers1_dag.php_app2 scheduled__2024-03-14T00:00:00+00:00 [queued]>
[2025-03-25T00:25:49.052+0000] {taskinstance.py:2614} INFO - Dependencies all met for dep_context=requeueable deps ti=<TaskInstance: containers1_dag.php_app2 scheduled__2024-03-14T00:00:00+00:00 [queued]>
[2025-03-25T00:25:49.052+0000] {taskinstance.py:2867} INFO - Starting attempt 1 of 6
[2025-03-25T00:25:49.097+0000] {taskinstance.py:2890} INFO - Executing <Task(DockerOperator): php_app2> on 2024-03-14 00:00:00+00:00
[2025-03-25T00:25:49.120+0000] {logging_mixin.py:190} WARNING - /home/***/.local/lib/python3.12/site-packages/***/task/task_runner/standard_task_runner.py:70 DeprecationWarning: This process (pid=283) is multi-threaded, use of fork() may lead to deadlocks in the child.
[2025-03-25T00:25:49.121+0000] {standard_task_runner.py:72} INFO - Started process 290 to run task
[2025-03-25T00:25:49.118+0000] {standard_task_runner.py:104} INFO - Running: ['***', 'tasks', 'run', 'containers1_dag', 'php_app2', 'scheduled__2024-03-14T00:00:00+00:00', '--job-id', '27', '--raw', '--subdir', 'DAGS_FOLDER/containers1_dag.py', '--cfg-path', '/tmp/tmp5wcmqrp0']
[2025-03-25T00:25:49.130+0000] {standard_task_runner.py:105} INFO - Job 27: Subtask php_app2
[2025-03-25T00:25:49.363+0000] {task_command.py:467} INFO - Running <TaskInstance: containers1_dag.php_app2 scheduled__2024-03-14T00:00:00+00:00 [running]> on host 7e2e363232cf
[2025-03-25T00:25:49.616+0000] {taskinstance.py:3134} INFO - Exporting env vars: AIRFLOW_CTX_DAG_OWNER='andre' AIRFLOW_CTX_DAG_ID='containers1_dag' AIRFLOW_CTX_TASK_ID='php_app2' AIRFLOW_CTX_EXECUTION_DATE='2024-03-14T00:00:00+00:00' AIRFLOW_CTX_TRY_NUMBER='1' AIRFLOW_CTX_DAG_RUN_ID='scheduled__2024-03-14T00:00:00+00:00'
[2025-03-25T00:25:49.621+0000] {taskinstance.py:732} INFO - ::endgroup::
[2025-03-25T00:25:49.665+0000] {docker.py:157} ERROR - Failed to establish connection to Docker host unix://var/run/docker.sock: Error while fetching server API version: ('Connection aborted.', FileNotFoundError(2, 'No such file or directory'))
[2025-03-25T00:25:49.694+0000] {taskinstance.py:3313} ERROR - Task failed with exception
Traceback (most recent call last):
  File "/home/airflow/.local/lib/python3.12/site-packages/airflow/models/taskinstance.py", line 768, in _execute_task
    result = _execute_callable(context=context, **execute_callable_kwargs)
             ^^^^^^^^^^^^^^^^^^^^^^^^^^^^^^^^^^^^^^^^^^^^^^^^^^^^^^^^^^^^^
  File "/home/airflow/.local/lib/python3.12/site-packages/airflow/models/taskinstance.py", line 734, in _execute_callable
    return ExecutionCallableRunner(
           ^^^^^^^^^^^^^^^^^^^^^^^^
  File "/home/airflow/.local/lib/python3.12/site-packages/airflow/utils/operator_helpers.py", line 252, in run
    return self.func(*args, **kwargs)
           ^^^^^^^^^^^^^^^^^^^^^^^^^^
  File "/home/airflow/.local/lib/python3.12/site-packages/airflow/models/baseoperator.py", line 424, in wrapper
    return func(self, *args, **kwargs)
           ^^^^^^^^^^^^^^^^^^^^^^^^^^^
  File "/home/airflow/.local/lib/python3.12/site-packages/airflow/providers/docker/operators/docker.py", line 467, in execute
    if self.force_pull or not self.cli.images(name=self.image):
                              ^^^^^^^^
  File "/home/airflow/.local/lib/python3.12/site-packages/airflow/providers/docker/operators/docker.py", line 341, in cli
    return self.hook.api_client
           ^^^^^^^^^^^^^^^^^^^^
  File "/usr/local/lib/python3.12/functools.py", line 998, in __get__
    val = self.func(instance)
          ^^^^^^^^^^^^^^^^^^^
  File "/home/airflow/.local/lib/python3.12/site-packages/airflow/providers/docker/hooks/docker.py", line 161, in api_client
    raise AirflowException("Failed to establish connection to any given Docker hosts.")
airflow.exceptions.AirflowException: Failed to establish connection to any given Docker hosts.
[2025-03-25T00:25:49.724+0000] {taskinstance.py:1226} INFO - Marking task as UP_FOR_RETRY. dag_id=containers1_dag, task_id=php_app2, run_id=scheduled__2024-03-14T00:00:00+00:00, execution_date=20240314T000000, start_date=20250325T002549, end_date=20250325T002549
[2025-03-25T00:25:49.847+0000] {taskinstance.py:341} INFO - ::group::Post task execution logs
[2025-03-25T00:25:49.848+0000] {standard_task_runner.py:124} ERROR - Failed to execute job 27 for task php_app2 (Failed to establish connection to any given Docker hosts.; 290)
Traceback (most recent call last):
  File "/home/airflow/.local/lib/python3.12/site-packages/airflow/task/task_runner/standard_task_runner.py", line 117, in _start_by_fork
    ret = args.func(args, dag=self.dag)
          ^^^^^^^^^^^^^^^^^^^^^^^^^^^^^
  File "/home/airflow/.local/lib/python3.12/site-packages/airflow/cli/cli_config.py", line 49, in command
    return func(*args, **kwargs)
           ^^^^^^^^^^^^^^^^^^^^^
  File "/home/airflow/.local/lib/python3.12/site-packages/airflow/utils/cli.py", line 116, in wrapper
    return f(*args, **kwargs)
           ^^^^^^^^^^^^^^^^^^
  File "/home/airflow/.local/lib/python3.12/site-packages/airflow/cli/commands/task_command.py", line 483, in task_run
    task_return_code = _run_task_by_selected_method(args, _dag, ti)
                       ^^^^^^^^^^^^^^^^^^^^^^^^^^^^^^^^^^^^^^^^^^^^
  File "/home/airflow/.local/lib/python3.12/site-packages/airflow/cli/commands/task_command.py", line 256, in _run_task_by_selected_method
    return _run_raw_task(args, ti)
           ^^^^^^^^^^^^^^^^^^^^^^^
  File "/home/airflow/.local/lib/python3.12/site-packages/airflow/cli/commands/task_command.py", line 341, in _run_raw_task
    return ti._run_raw_task(
           ^^^^^^^^^^^^^^^^^
  File "/home/airflow/.local/lib/python3.12/site-packages/airflow/utils/session.py", line 97, in wrapper
    return func(*args, session=session, **kwargs)
           ^^^^^^^^^^^^^^^^^^^^^^^^^^^^^^^^^^^^^^
  File "/home/airflow/.local/lib/python3.12/site-packages/airflow/models/taskinstance.py", line 3006, in _run_raw_task
    return _run_raw_task(
           ^^^^^^^^^^^^^^
  File "/home/airflow/.local/lib/python3.12/site-packages/airflow/models/taskinstance.py", line 274, in _run_raw_task
    TaskInstance._execute_task_with_callbacks(
  File "/home/airflow/.local/lib/python3.12/site-packages/airflow/models/taskinstance.py", line 3161, in _execute_task_with_callbacks
    result = self._execute_task(context, task_orig)
             ^^^^^^^^^^^^^^^^^^^^^^^^^^^^^^^^^^^^^^
  File "/home/airflow/.local/lib/python3.12/site-packages/airflow/models/taskinstance.py", line 3185, in _execute_task
    return _execute_task(self, context, task_orig)
           ^^^^^^^^^^^^^^^^^^^^^^^^^^^^^^^^^^^^^^^
  File "/home/airflow/.local/lib/python3.12/site-packages/airflow/models/taskinstance.py", line 768, in _execute_task
    result = _execute_callable(context=context, **execute_callable_kwargs)
             ^^^^^^^^^^^^^^^^^^^^^^^^^^^^^^^^^^^^^^^^^^^^^^^^^^^^^^^^^^^^^
  File "/home/airflow/.local/lib/python3.12/site-packages/airflow/models/taskinstance.py", line 734, in _execute_callable
    return ExecutionCallableRunner(
           ^^^^^^^^^^^^^^^^^^^^^^^^
  File "/home/airflow/.local/lib/python3.12/site-packages/airflow/utils/operator_helpers.py", line 252, in run
    return self.func(*args, **kwargs)
           ^^^^^^^^^^^^^^^^^^^^^^^^^^
  File "/home/airflow/.local/lib/python3.12/site-packages/airflow/models/baseoperator.py", line 424, in wrapper
    return func(self, *args, **kwargs)
           ^^^^^^^^^^^^^^^^^^^^^^^^^^^
  File "/home/airflow/.local/lib/python3.12/site-packages/airflow/providers/docker/operators/docker.py", line 467, in execute
    if self.force_pull or not self.cli.images(name=self.image):
                              ^^^^^^^^
  File "/home/airflow/.local/lib/python3.12/site-packages/airflow/providers/docker/operators/docker.py", line 341, in cli
    return self.hook.api_client
           ^^^^^^^^^^^^^^^^^^^^
  File "/usr/local/lib/python3.12/functools.py", line 998, in __get__
    val = self.func(instance)
          ^^^^^^^^^^^^^^^^^^^
  File "/home/airflow/.local/lib/python3.12/site-packages/airflow/providers/docker/hooks/docker.py", line 161, in api_client
    raise AirflowException("Failed to establish connection to any given Docker hosts.")
airflow.exceptions.AirflowException: Failed to establish connection to any given Docker hosts.
[2025-03-25T00:25:49.874+0000] {local_task_job_runner.py:266} INFO - Task exited with return code 1
[2025-03-25T00:25:49.931+0000] {taskinstance.py:3901} INFO - 0 downstream tasks scheduled from follow-on schedule check
[2025-03-25T00:25:49.938+0000] {local_task_job_runner.py:245} INFO - ::endgroup::
