[2025-03-24T22:27:18.461+0000] {local_task_job_runner.py:123} INFO - ::group::Pre task execution logs
[2025-03-24T22:27:18.560+0000] {taskinstance.py:2614} INFO - Dependencies all met for dep_context=non-requeueable deps ti=<TaskInstance: containers1_dag.php_app1 manual__2025-03-24T22:27:17.435221+00:00 [queued]>
[2025-03-24T22:27:18.593+0000] {taskinstance.py:2614} INFO - Dependencies all met for dep_context=requeueable deps ti=<TaskInstance: containers1_dag.php_app1 manual__2025-03-24T22:27:17.435221+00:00 [queued]>
[2025-03-24T22:27:18.596+0000] {taskinstance.py:2867} INFO - Starting attempt 1 of 6
[2025-03-24T22:27:18.675+0000] {taskinstance.py:2890} INFO - Executing <Task(BashOperator): php_app1> on 2025-03-24 22:27:17.435221+00:00
[2025-03-24T22:27:18.723+0000] {standard_task_runner.py:104} INFO - Running: ['***', 'tasks', 'run', 'containers1_dag', 'php_app1', 'manual__2025-03-24T22:27:17.435221+00:00', '--job-id', '174', '--raw', '--subdir', 'DAGS_FOLDER/containers1_dag.py', '--cfg-path', '/tmp/tmp41oz0nuf']
[2025-03-24T22:27:18.731+0000] {standard_task_runner.py:105} INFO - Job 174: Subtask php_app1
[2025-03-24T22:27:18.722+0000] {logging_mixin.py:190} WARNING - /home/***/.local/lib/python3.12/site-packages/***/task/task_runner/standard_task_runner.py:70 DeprecationWarning: This process (pid=5519) is multi-threaded, use of fork() may lead to deadlocks in the child.
[2025-03-24T22:27:18.732+0000] {standard_task_runner.py:72} INFO - Started process 5524 to run task
[2025-03-24T22:27:19.377+0000] {task_command.py:467} INFO - Running <TaskInstance: containers1_dag.php_app1 manual__2025-03-24T22:27:17.435221+00:00 [running]> on host b9050090f7f5
[2025-03-24T22:27:20.997+0000] {taskinstance.py:3134} INFO - Exporting env vars: AIRFLOW_CTX_DAG_OWNER='andre' AIRFLOW_CTX_DAG_ID='containers1_dag' AIRFLOW_CTX_TASK_ID='php_app1' AIRFLOW_CTX_EXECUTION_DATE='2025-03-24T22:27:17.435221+00:00' AIRFLOW_CTX_TRY_NUMBER='1' AIRFLOW_CTX_DAG_RUN_ID='manual__2025-03-24T22:27:17.435221+00:00'
[2025-03-24T22:27:20.998+0000] {taskinstance.py:732} INFO - ::endgroup::
[2025-03-24T22:27:21.261+0000] {subprocess.py:78} INFO - Tmp dir root location: /tmp
[2025-03-24T22:27:21.267+0000] {subprocess.py:88} INFO - Running command: ['/usr/bin/bash', '-c', 'docker run -v $(pwd)/../in:/usr/src/app/in -v $(pwd):/usr/src/app php-app1']
[2025-03-24T22:27:21.336+0000] {subprocess.py:99} INFO - Output:
[2025-03-24T22:27:21.791+0000] {subprocess.py:106} INFO - docker: Cannot connect to the Docker daemon at unix:///var/run/docker.sock. Is the docker daemon running?.
[2025-03-24T22:27:21.792+0000] {subprocess.py:106} INFO - See 'docker run --help'.
[2025-03-24T22:27:21.808+0000] {subprocess.py:110} INFO - Command exited with return code 125
[2025-03-24T22:27:22.113+0000] {taskinstance.py:3313} ERROR - Task failed with exception
Traceback (most recent call last):
  File "/home/airflow/.local/lib/python3.12/site-packages/airflow/models/taskinstance.py", line 768, in _execute_task
    result = _execute_callable(context=context, **execute_callable_kwargs)
             ^^^^^^^^^^^^^^^^^^^^^^^^^^^^^^^^^^^^^^^^^^^^^^^^^^^^^^^^^^^^^
  File "/home/airflow/.local/lib/python3.12/site-packages/airflow/models/taskinstance.py", line 734, in _execute_callable
    return ExecutionCallableRunner(
           ^^^^^^^^^^^^^^^^^^^^^^^^
  File "/home/airflow/.local/lib/python3.12/site-packages/airflow/utils/operator_helpers.py", line 252, in run
    return self.func(*args, **kwargs)
           ^^^^^^^^^^^^^^^^^^^^^^^^^^
  File "/home/airflow/.local/lib/python3.12/site-packages/airflow/models/baseoperator.py", line 424, in wrapper
    return func(self, *args, **kwargs)
           ^^^^^^^^^^^^^^^^^^^^^^^^^^^
  File "/home/airflow/.local/lib/python3.12/site-packages/airflow/operators/bash.py", line 276, in execute
    raise AirflowException(
airflow.exceptions.AirflowException: Bash command failed. The command returned a non-zero exit code 125.
[2025-03-24T22:27:22.358+0000] {taskinstance.py:1226} INFO - Marking task as UP_FOR_RETRY. dag_id=containers1_dag, task_id=php_app1, run_id=manual__2025-03-24T22:27:17.435221+00:00, execution_date=20250324T222717, start_date=20250324T222718, end_date=20250324T222722
[2025-03-24T22:27:23.391+0000] {taskinstance.py:341} INFO - ::group::Post task execution logs
[2025-03-24T22:27:23.395+0000] {standard_task_runner.py:124} ERROR - Failed to execute job 174 for task php_app1 (Bash command failed. The command returned a non-zero exit code 125.; 5524)
Traceback (most recent call last):
  File "/home/airflow/.local/lib/python3.12/site-packages/airflow/task/task_runner/standard_task_runner.py", line 117, in _start_by_fork
    ret = args.func(args, dag=self.dag)
          ^^^^^^^^^^^^^^^^^^^^^^^^^^^^^
  File "/home/airflow/.local/lib/python3.12/site-packages/airflow/cli/cli_config.py", line 49, in command
    return func(*args, **kwargs)
           ^^^^^^^^^^^^^^^^^^^^^
  File "/home/airflow/.local/lib/python3.12/site-packages/airflow/utils/cli.py", line 116, in wrapper
    return f(*args, **kwargs)
           ^^^^^^^^^^^^^^^^^^
  File "/home/airflow/.local/lib/python3.12/site-packages/airflow/cli/commands/task_command.py", line 483, in task_run
    task_return_code = _run_task_by_selected_method(args, _dag, ti)
                       ^^^^^^^^^^^^^^^^^^^^^^^^^^^^^^^^^^^^^^^^^^^^
  File "/home/airflow/.local/lib/python3.12/site-packages/airflow/cli/commands/task_command.py", line 256, in _run_task_by_selected_method
    return _run_raw_task(args, ti)
           ^^^^^^^^^^^^^^^^^^^^^^^
  File "/home/airflow/.local/lib/python3.12/site-packages/airflow/cli/commands/task_command.py", line 341, in _run_raw_task
    return ti._run_raw_task(
           ^^^^^^^^^^^^^^^^^
  File "/home/airflow/.local/lib/python3.12/site-packages/airflow/utils/session.py", line 97, in wrapper
    return func(*args, session=session, **kwargs)
           ^^^^^^^^^^^^^^^^^^^^^^^^^^^^^^^^^^^^^^
  File "/home/airflow/.local/lib/python3.12/site-packages/airflow/models/taskinstance.py", line 3006, in _run_raw_task
    return _run_raw_task(
           ^^^^^^^^^^^^^^
  File "/home/airflow/.local/lib/python3.12/site-packages/airflow/models/taskinstance.py", line 274, in _run_raw_task
    TaskInstance._execute_task_with_callbacks(
  File "/home/airflow/.local/lib/python3.12/site-packages/airflow/models/taskinstance.py", line 3161, in _execute_task_with_callbacks
    result = self._execute_task(context, task_orig)
             ^^^^^^^^^^^^^^^^^^^^^^^^^^^^^^^^^^^^^^
  File "/home/airflow/.local/lib/python3.12/site-packages/airflow/models/taskinstance.py", line 3185, in _execute_task
    return _execute_task(self, context, task_orig)
           ^^^^^^^^^^^^^^^^^^^^^^^^^^^^^^^^^^^^^^^
  File "/home/airflow/.local/lib/python3.12/site-packages/airflow/models/taskinstance.py", line 768, in _execute_task
    result = _execute_callable(context=context, **execute_callable_kwargs)
             ^^^^^^^^^^^^^^^^^^^^^^^^^^^^^^^^^^^^^^^^^^^^^^^^^^^^^^^^^^^^^
  File "/home/airflow/.local/lib/python3.12/site-packages/airflow/models/taskinstance.py", line 734, in _execute_callable
    return ExecutionCallableRunner(
           ^^^^^^^^^^^^^^^^^^^^^^^^
  File "/home/airflow/.local/lib/python3.12/site-packages/airflow/utils/operator_helpers.py", line 252, in run
    return self.func(*args, **kwargs)
           ^^^^^^^^^^^^^^^^^^^^^^^^^^
  File "/home/airflow/.local/lib/python3.12/site-packages/airflow/models/baseoperator.py", line 424, in wrapper
    return func(self, *args, **kwargs)
           ^^^^^^^^^^^^^^^^^^^^^^^^^^^
  File "/home/airflow/.local/lib/python3.12/site-packages/airflow/operators/bash.py", line 276, in execute
    raise AirflowException(
airflow.exceptions.AirflowException: Bash command failed. The command returned a non-zero exit code 125.
[2025-03-24T22:27:23.440+0000] {local_task_job_runner.py:266} INFO - Task exited with return code 1
[2025-03-24T22:27:23.653+0000] {taskinstance.py:3901} INFO - 0 downstream tasks scheduled from follow-on schedule check
[2025-03-24T22:27:23.673+0000] {local_task_job_runner.py:245} INFO - ::endgroup::
